Workbook
Name _666.lpacal_1: CAL!$A$1:$B$236
Name solver_adj: mtd!$I$4:$N$4
Name solver_cvg: 0.0001
Name solver_drv: 1
Name solver_est: 1
Name solver_itr: 100
Name solver_lin: 2
Name solver_neg: 2
Name solver_num: 0
Name solver_nwt: 1
Name solver_opt: mtd!$H$55
Name solver_pre: 0.000001
Name solver_scl: 2
Name solver_sho: 2
Name solver_tim: 100
Name solver_tol: 0.05
Name solver_typ: 2
Name solver_val: 0

Sheet mtd-10-micron

Sheet mtd-100-micron

Sheet CAL
A1: CALIBRATION RESULTS
A2: verification_count_0_0 | B2: 3502561
A3: verification_count_0_1 | B3: 1384415
A4: verification_count_0_2 | B4: 97621
A5: verification_count_0_3 | B5: 23939
A6: verification_count_0_4 | B6: 11133
A7: verification_count_0_5 | B7: 1551
A8: verification_count_0_6 | B8: 593
A9: verification_count_0_7 | B9: 71
A10: verification_count_1_0 | B10: 3504210
A11: verification_count_1_1 | B11: 1382038
A12: verification_count_1_2 | B12: 99179
A13: verification_count_1_3 | B13: 24541
... A27: led_level | B27: 11559
A34: CALIBRATION DOCUMENT VALUES
A35: date_ | B35: 45999.7
A36: serial_number_ | B36: 204
A37: RIG PARAMETERS
A38: meas_init_level | B38: 12.57
A39: calc_init_volume | B39: 12.57
A40: desired_concentration | B40: 16
A41: calc_qty_add | B41: 201.12
A42: meas_qty_add | B42: 201.06
A43: meas_final_level | B43: 12.57
A44: calc_volume | B44: 12.57
A45: calc_concentration | B45: 15.9952
A46: rig_param_volume_mult | B46: -1
A47: rig_param_volume_constant | B47: 0
A48: rig_param_identifier | B48: 367
A49: rig_cleanliness_count | B49: 0
A57: ICM SETTINGS
A58: time | B58: 1765210805
A59: serial_number | B59: 204
A60: hwRevision | B60: 0
A61: user_lock | B61: 0
A62: user_pass | B62: 0
A63: CycleCount | B63: 0
A64: last_download | B64: 0
A65: FACTORY SET OPTIONS
A66: SET_OPT_LOG | B66: 1
...

Sheet mtd
A1: SRM2806 2.8mg MTD / ml | H1: Interpolation Order
H2: 4 | K2: to 10 micron | M2: to 70 micron
A3: um | B3: n/ml | C3: n/mg/ml | D3: Expanded Uncertainty | F3: ln(n/mg/ml) | H3: um | I3: n/mg/ml | K3: x | L3: y | M3: x | N3: y
A4: 1 | B4: 108400 | C4: =B4/2.8 -> 38714.286 | D4: 0.274 | F4: =LN(C4) -> 10.563964 | H4: 50 | I4: =EXP(interpolate($A$4:$A$93, $F$4:$F$93, $H4,$H$2,0)) -> #NAME? | K4: 1 | L4: =EXP(interpolate($A$4:$A$92, $F$4:$F$92, $K4,$H$2,1)) -> #NAME? | M4: 1 | N4: =EXP(interpolate($A$4:$A$93, $F$4:$F$93, M4,$H$2,1)) -> #NAME?
A5: 2 | B5: 27035 | C5: =B5/2.8 -> 9655.3571 | D5: 0.265 | F5: =LN(C5) -> 9.1752682 | K5: 1.1 | L5: =EXP(interpolate($A$4:$A$92, $F$4:$F$92, $K5,$H$2,1)) -> #NAME? | M5: 2 | N5: =EXP(interpolate($A$4:$A$93, $F$4:$F$93, M5,$H$2,1)) -> #NAME?
A6: 3 | B6: 11209 | C6: =B6/2.8 -> 4003.2143 | D6: 0.272 | F6: =LN(C6) -> 8.2948529 | K6: 1.2 | L6: =EXP(interpolate($A$4:$A$92, $F$4:$F$92, $K6,$H$2,1)) -> #NAME? | M6: 3 | N6: =EXP(interpolate($A$4:$A$93, $F$4:$F$93, M6,$H$2,1)) -> #NAME?
A7: 4 | B7: 6095 | C7: =B7/2.8 -> 2176.7857 | D7: 0.308 | F7: =LN(C7) -> 7.6856046 | K7: 1.3 | L7: =EXP(interpolate($A$4:$A$92, $F$4:$F$92, $K7,$H$2,1)) -> #NAME? | M7: 4 | N7: =EXP(interpolate($A$4:$A$93, $F$4:$F$93, M7,$H$2,1)) -> #NAME?
A8: 5 | B8: 3737 | C8: =B8/2.8 -> 1334.6429 | D8: 0.414 | F8: =LN(C8) -> 7.196419 | H8: n/mg/l | I8: 10000 | K8: 1.4 | L8: =EXP(interpolate($A$4:$A$92, $F$4:$F$92, $K8,$H$2,1)) -> #NAME? | M8: 5 | N8: =EXP(interpolate($A$4:$A$93, $F$4:$F$93, M8,$H$2,1)) -> #NAME?
A9: 6 | B9: 2395 | C9: =B9/2.8 -> 855.35714 | D9: 0.56 | F9: =LN(C9) -> 6.7515191 | H9: ln(n/mg/l) | I9: =LN(I8) -> 9.2103404 | K9: 1.5 | L9: =EXP(interpolate($A$4:$A$92, $F$4:$F$92, $K9,$H$2,1)) -> #NAME? | M9: 6 | N9: =EXP(interpolate($A$4:$A$93, $F$4:$F$93, M9,$H$2,1)) -> #NAME?
A10: 7 | B10: 1573 | C10: =B10/2.8 -> 561.78571 | D10: 0.542 | F10: =LN(C10) -> 6.3311205 | H10: um | I10: =interpolate($F$4:$F$93, $A$4:$A$93, $I9,$H$2,0) -> #NAME? | K10: 1.6 | L10: =EXP(interpolate($A$4:$A$92, $F$4:$F$92, $K10,$H$2,1)) -> #NAME? | M10: 7 | N10: =EXP(interpolate($A$4:$A$93, $F$4:$F$93, M10,$H$2,1)) -> #NAME?
A11: 8 | B11: 1055 | C11: =B11/2.8 -> 376.78571 | D11: 0.499 | F11: =LN(C11) -> 5.9316766 | K11: 1.7 | L11: =EXP(interpolate($A$4:$A$92, $F$4:$F$92, $K11,$H$2,1)) -> #NAME? | M11: 8 | N11: =EXP(interpolate($A$4:$A$93, $F$4:$F$93, M11,$H$2,1)) -> #NAME?
A12: 9 | B12: 725.8 | C12: =B12/2.8 -> 259.21429 | D12: 0.544 | F12: =LN(C12) -> 5.5576551 | K12: 1.8 | L12: =EXP(interpolate($A$4:$A$92, $F$4:$F$92, $K12,$H$2,1)) -> #NAME? | M12: 9 | N12: =EXP(interpolate($A$4:$A$93, $F$4:$F$93, M12,$H$2,1)) -> #NAME?
A13: 10 | B13: 513.7 | C13: =B13/2.8 -> 183.46429 | D13: 0.643 | F13: =LN(C13) -> 5.21202 | K13: 1.9 | L13: =EXP(interpolate($A$4:$A$92, $F$4:$F$92, $K13,$H$2,1)) -> #NAME? | M13: 10 | N13: =EXP(interpolate($A$4:$A$93, $F$4:$F$93, M13,$H$2,1)) -> #NAME?
A14: 11 | B14: 374.6 | C14: =B14/2.8 -> 133.78571 | D14: 0.759 | F14: =LN(C14) -> 4.8962394 | H14: 2 | I14: =mtd($H$14) -> #NAME? | K14: 2 | L14: =EXP(interpolate($A$4:$A$92, $F$4:$F$92, $K14,$H$2,1)) -> #NAME? | M14: 11 | N14: =EXP(interpolate($A$4:$A$93, $F$4:$F$93, M14,$H$2,1)) -> #NAME?
A15: 12 | B15: 281 | C15: =B15/2.8 -> 100.35714 | D15: 0.981 | F15: =LN(C15) -> 4.6087353 | K15: 2.1 | L15: =EXP(interpolate($A$4:$A$92, $F$4:$F$92, $K15,$H$2,1)) -> #NAME? | M15: 12 | N15: =EXP(interpolate($A$4:$A$93, $F$4:$F$93, M15,$H$2,1)) -> #NAME?
A16: 13 | B16: 216.4 | C16: =B16/2.8 -> 77.285714 | D16: 1.273 | F16: =LN(C16) -> 4.3475091 | K16: 2.2 | L16: =EXP(interpolate($A$4:$A$92, $F$4:$F$92, $K16,$H$2,1)) -> #NAME? | M16: 13 | N16: =EXP(interpolate($A$4:$A$93, $F$4:$F$93, M16,$H$2,1)) -> #NAME?
A17: 14 | B17: 170.4 | C17: =B17/2.8 -> 60.857143 | D17: 1.655 | F17: =LN(C17) -> 4.1085292 | H17: =mtd(1.7575) -> #NAME? | K17: 2.3 | L17: =EXP(interpolate($A$4:$A$92, $F$4:$F$92, $K17,$H$2,1)) -> #NAME? | M17: 14 | N17: =EXP(interpolate($A$4:$A$93, $F$4:$F$93, M17,$H$2,1)) -> #NAME?
A18: 15 | B18: 136.8 | C18: =B18/2.8 -> 48.857143 | D18: 2.211 | F18: =LN(C18) -> 3.8889006 | K18: 2.4 | L18: =EXP(interpolate($A$4:$A$92, $F$4:$F$92, $K18,$H$2,1)) -> #NAME? | M18: 15 | N18: =EXP(interpolate($A$4:$A$93, $F$4:$F$93, M18,$H$2,1)) -> #NAME?
A19: 16 | B19: 111.3 | C19: =B19/2.8 -> 39.75 | D19: 2.414 | F19: =LN(C19) -> 3.6826098 | H19: (Testing area only) | K19: 2.5 | L19: =EXP(interpolate($A$4:$A$92, $F$4:$F$92, $K19,$H$2,1)) -> #NAME? | M19: 16 | N19: =EXP(interpolate($A$4:$A$93, $F$4:$F$93, M19,$H$2,1)) -> #NAME?
A20: 17 | B20: 91.33 | C20: =B20/2.8 -> 32.617857 | D20: 2.91 | F20: =LN(C20) -> 3.4848599 | K20: 2.6 | L20: =EXP(interpolate($A$4:$A$92, $F$4:$F$92, $K20,$H$2,1)) -> #NAME? | M20: 17 | N20: =EXP(interpolate($A$4:$A$93, $F$4:$F$93, M20,$H$2,1)) -> #NAME?
A21: 18 | B21: 75.29 | C21: =B21/2.8 -> 26.889286 | D21: 3.444 | F21: =LN(C21) -> 3.2917279 | K21: 2.7 | L21: =EXP(interpolate($A$4:$A$92, $F$4:$F$92, $K21,$H$2,1)) -> #NAME? | M21: 18 | N21: =EXP(interpolate($A$4:$A$93, $F$4:$F$93, M21,$H$2,1)) -> #NAME?
A22: 19 | B22: 62.17 | C22: =B22/2.8 -> 22.203571 | D22: 4.101 | F22: =LN(C22) -> 3.1002532 | I22: = Formulae | K22: 2.8 | L22: =EXP(interpolate($A$4:$A$92, $F$4:$F$92, $K22,$H$2,1)) -> #NAME? | M22: 19 | N22: =EXP(interpolate($A$4:$A$93, $F$4:$F$93, M22,$H$2,1)) -> #NAME?
A23: 20 | B23: 51.35 | C23: =B23/2.8 -> 18.339286 | D23: 5.045 | F23: =LN(C23) -> 2.9090455 | K23: 2.9 | L23: =EXP(interpolate($A$4:$A$92, $F$4:$F$92, $K23,$H$2,1)) -> #NAME? | M23: 20 | N23: =EXP(interpolate($A$4:$A$93, $F$4:$F$93, M23,$H$2,1)) -> #NAME?
A24: 21 | B24: 42.4 | C24: =B24/2.8 -> 15.142857 | D24: 4.976 | F24: =LN(C24) -> 2.7175289 | I24: = Reference Figures | K24: 3 | L24: =EXP(interpolate($A$4:$A$92, $F$4:$F$92, $K24,$H$2,1)) -> #NAME? | M24: 21 | N24: =EXP(interpolate($A$4:$A$93, $F$4:$F$93, M24,$H$2,1)) -> #NAME?
A25: 22 | B25: 35.01 | C25: =B25/2.8 -> 12.503571 | D25: 5.508 | F25: =LN(C25) -> 2.5260143 | K25: 3.1 | L25: =EXP(interpolate($A$4:$A$92, $F$4:$F$92, $K25,$H$2,1)) -> #NAME? | M25: 22 | N25: =EXP(interpolate($A$4:$A$93, $F$4:$F$93, M25,$H$2,1)) -> #NAME?
A26: 23 | B26: 28.95 | C26: =B26/2.8 -> 10.339286 | D26: 5.941 | F26: =LN(C26) -> 2.3359508 | I26: = Manual Input | K26: 3.2 | L26: =EXP(interpolate($A$4:$A$92, $F$4:$F$92, $K26,$H$2,1)) -> #NAME? | M26: 23 | N26: =EXP(interpolate($A$4:$A$93, $F$4:$F$93, M26,$H$2,1)) -> #NAME?
A27: 24 | B27: 23.99 | C27: =B27/2.8 -> 8.5678571 | D27: 6.573 | F27: =LN(C27) -> 2.1480177 | K27: 3.3 | L27: =EXP(interpolate($A$4:$A$92, $F$4:$F$92, $K27,$H$2,1)) -> #NAME? | M27: 24 | N27: =EXP(interpolate($A$4:$A$93, $F$4:$F$93, M27,$H$2,1)) -> #NAME?
A28: 25 | B28: 19.95 | C28: =B28/2.8 -> 7.125 | D28: 6.945 | F28: =LN(C28) -> 1.9636097 | H28: Doc. No: 200.XXX | K28: 3.4 | L28: =EXP(interpolate($A$4:$A$92, $F$4:$F$92, $K28,$H$2,1)) -> #NAME? | M28: 25 | N28: =EXP(interpolate($A$4:$A$93, $F$4:$F$93, M28,$H$2,1)) -> #NAME?
A29: 26 | B29: 16.66 | C29: =B29/2.8 -> 5.95 | D29: 7.261 | F29: =LN(C29) -> 1.7833912 | H29: Sheet 3 | K29: 3.5 | L29: =EXP(interpolate($A$4:$A$92, $F$4:$F$92, $K29,$H$2,1)) -> #NAME? | M29: 26 | N29: =EXP(interpolate($A$4:$A$93, $F$4:$F$93, M29,$H$2,1)) -> #NAME?
A30: 27 | B30: 13.98 | C30: =B30/2.8 -> 4.9928571 | D30: 8.03 | F30: =LN(C30) -> 1.6080083 | H30: DCRXXXX | K30: 3.6 | L30: =EXP(interpolate($A$4:$A$92, $F$4:$F$92, $K30,$H$2,1)) -> #NAME? | M30: 27 | N30: =EXP(interpolate($A$4:$A$93, $F$4:$F$93, M30,$H$2,1)) -> #NAME?
A31: 28 | B31: 11.8 | C31: =B31/2.8 -> 4.2142857 | D31: 8.369 | F31: =LN(C31) -> 1.4384801 | H31: Rev 0 | K31: 3.7 | L31: =EXP(interpolate($A$4:$A$92, $F$4:$F$92, $K31,$H$2,1)) -> #NAME? | M31: 28 | N31: =EXP(interpolate($A$4:$A$93, $F$4:$F$93, M31,$H$2,1)) -> #NAME?
A32: 29 | B32: 10.02 | C32: =B32/2.8 -> 3.5785714 | D32: 8.595 | F32: =LN(C32) -> 1.2749637 | K32: 3.8 | L32: =EXP(interpolate($A$4:$A$92, $F$4:$F$92, $K32,$H$2,1)) -> #NAME? | M32: 29 | N32: =EXP(interpolate($A$4:$A$93, $F$4:$F$93, M32,$H$2,1)) -> #NAME?
A33: 30 | B33: 8.568 | C33: =B33/2.8 -> 3.06 | D33: 9.943 | F33: =LN(C33) -> 1.1184149 | K33: 3.9 | L33: =EXP(interpolate($A$4:$A$92, $F$4:$F$92, $K33,$H$2,1)) -> #NAME? | M33: 30 | N33: =EXP(interpolate($A$4:$A$93, $F$4:$F$93, M33,$H$2,1)) -> #NAME?
A34: 31 | B34: 7.38 | C34: =B34/2.8 -> 2.6357143 | F34: =LN(C34) -> 0.96915422 | K34: 4 | L34: =EXP(interpolate($A$4:$A$92, $F$4:$F$92, $K34,$H$2,1)) -> #NAME? | M34: 31 | N34: =EXP(interpolate($A$4:$A$93, $F$4:$F$93, M34,$H$2,1)) -> #NAME?
A35: 32 | B35: 6.403 | C35: =B35/2.8 -> 2.2867857 | F35: =LN(C35) -> 0.82714721 | K35: 4.1 | L35: =EXP(interpolate($A$4:$A$92, $F$4:$F$92, $K35,$H$2,1)) -> #NAME? | M35: 32 | N35: =EXP(interpolate($A$4:$A$93, $F$4:$F$93, M35,$H$2,1)) -> #NAME?
A36: 33 | B36: 5.594 | C36: =B36/2.8 -> 1.9978571 | F36: =LN(C36) -> 0.69207518 | K36: 4.2 | L36: =EXP(interpolate($A$4:$A$92, $F$4:$F$92, $K36,$H$2,1)) -> #NAME? | M36: 33 | N36: =EXP(interpolate($A$4:$A$93, $F$4:$F$93, M36,$H$2,1)) -> #NAME?
A37: 34 | B37: 4.921 | C37: =B37/2.8 -> 1.7575 | F37: =LN(C37) -> 0.56389234 | K37: 4.3 | L37: =EXP(interpolate($A$4:$A$92, $F$4:$F$92, $K37,$H$2,1)) -> #NAME? | M37: 34 | N37: =EXP(interpolate($A$4:$A$93, $F$4:$F$93, M37,$H$2,1)) -> #NAME?
A38: 35 | B38: 4.356 | C38: =B38/2.8 -> 1.5557143 | F38: =LN(C38) -> 0.44193479 | K38: 4.4 | L38: =EXP(interpolate($A$4:$A$92, $F$4:$F$92, $K38,$H$2,1)) -> #NAME? | M38: 35 | N38: =EXP(interpolate($A$4:$A$93, $F$4:$F$93, M38,$H$2,1)) -> #NAME?
A39: 36 | B39: 3.88 | C39: =B39/2.8 -> 1.3857143 | F39: =LN(C39) -> 0.32621574 | K39: 4.5 | L39: =EXP(interpolate($A$4:$A$92, $F$4:$F$92, $K39,$H$2,1)) -> #NAME? | M39: 36 | N39: =EXP(interpolate($A$4:$A$93, $F$4:$F$93, M39,$H$2,1)) -> #NAME?
A40: 37 | B40: 3.476 | C40: =B40/2.8 -> 1.2414286 | F40: =LN(C40) -> 0.21626279 | K40: 4.6 | L40: =EXP(interpolate($A$4:$A$92, $F$4:$F$92, $K40,$H$2,1)) -> #NAME? | M40: 37 | N40: =EXP(interpolate($A$4:$A$93, $F$4:$F$93, M40,$H$2,1)) -> #NAME?
...

Sheet ICM Job Card 2022
K1: 202.027_02 | R1: - | S1: - | T1: - | U1: -
K2: DCR0678 | M2: =IF(C20="MK II",7000,3900) -> 3900 | R2: C Jones | S2: ISO4406:1999 | T2: N | U2: MK II
A3: Serial Number | E3: Product Code | R3: B Brown | S3: NAS1638 | T3: 0 | U3: MK I
A4: Customer | R4: A Hayward | S4: AS4059E Table 2 | T4: 1 | U4: MK I (OLD)
A5: Booking Date | E5: Service No. | R5: A Wallace | S5: AS4095E Table 1 | T5: 2
A6: Sales Order | E6: Works Order | R6: A Mustoe | S6: ISO11218 | T6: 3
A7: Box Kept? | R7: J Scarrott | S7: AS4059F Table 2 | T7: 4
A8: Checks carried out by | D8: - | R8: S Mosson | S8: AS4095F Table 1 | T8: 5
A9: Calibration Screen | C9: Initial | D9: Rig - (oil flow) | F9: Service carried out by: | H9: - | R9: A Buckley | T9: 6
A10: Photocurrent | B10: (nA) | F10: Calibration carried out by: | H10: - | R10: T Whittle | T10: 7
A11: RH % | F11: Continuous Testing Options | I11: Additional notes
A12: Temp | F12: Test continuously | H12: FALSE
A13: User Settings | F13: Log continuously | H13: FALSE
A14: Format | C14: - | F14: Start testing automatically | H14: FALSE
A15: Simulated Test | C15: FALSE | F15: Stop testing when clean | H15: FALSE
A16: Low Flow Alarm Disabled | C16: FALSE | F16: Confirm target levels | H16: FALSE
A17: Alarm Mode | C17: - | F17: Before stopping (x) times?
F18: Ignore initial tests
A19: System Settings
A20: Sensing Vol. Parameters | C20: - | F20: Firmware Updated
A21: Test Reference | F21: Y/N?
A22: Accumulation Time (s)
A23: Auto-repeat on? | C23: FALSE | F23: Pressure Tests
A24: Interval (s) | F24: 500b Static
A25: W - Water Sensor | C25: FALSE | F25: 500b Pulse
A26: R - Alarm Relays | C26: FALSE
A28: Contamination Code Target/Alarm Levels
B29: 4 | C29: 6 | D29: 14 | F29: RH | G29: Temp
A30: Upper
A31: Lower
A32: Other Sizes
A34: Electronic Changes | C34: PCBR | D34: PCBT | E34: PCBK | G34: Date Returned
A35: Serial numbers

Sheet Service Report
A2: Serial Number | C2: ='ICM Job Card 2022'!C3 -> 0
A3: Service Number | C3: ='ICM Job Card 2022'!G5 -> 0
A4: Customer | C4: ='ICM Job Card 2022'!C4 -> 0
A5: Sales Order | C5: ='ICM Job Card 2022'!C6 -> 0
A6: Product | C6: ='ICM Job Card 2022'!G3 -> 0
A8: Faults Identified
A22: Work Carried Out / Faulty Parts Replaced
A39: Further Recommendations
A48: Service Carried Out By | C48: -

Sheet UK Sterling service quote
A2: Service Quotation: | D2: ="SQ"&#REF! -> #REF!
A4: Serial number of unit(s): | D4: =#REF! -> #REF!
A6: Customer: | C6: =#REF! -> #REF!
A8: Date: | B8: =#REF! -> #REF!
A10: Required work:
A11: Fault Found
A12: ='Service Report'!A10 -> 0
A13: ='Service Report'!A11 -> 0
A14: ='Service Report'!A12 -> 0
A15: ='Service Report'!A13 -> 0
A16: ='Service Report'!A14 -> 0
A17: ='Service Report'!A37 -> 0
A18: Work Done
A19: ='Service Report'!A24 -> 0
A20: ='Service Report'!A25 -> 0
A21: ='Service Report'!A26 -> 0
A22: ='Service Report'!A27 -> 0
A23: ='Service Report'!A35 -> 0
A24: ='Service Report'!A36 -> 0
A27: Cost details: | D27: All figures are in GBP £
A29: Stock Code | C29: Description | G29: Qty | H29: Price | I29: Discount % | J29: Net Price
A30: =IF(G30=1,15.005,0) -> 15.005 | C30: =IF(G30=1,"ICM Recalibration",0) -> ICM Recalibration | G30: =IF(A31=15.012,0,IF(A32=15.013,0,1)) -> 1 | H30: =IF(G30=1,178,0) -> 178 | J30: =(G30*H30)*((100-I30)/100) -> 178
A31: =IF(A20=0,0,15.012) -> 0 | C31: =IF(A31=15.012,"ICM repair of PCB-K - INC Recal",0) -> 0 | G31: =IF(A31=15.012,1,0) -> 0 | H31: =IF(A31=15.012,604.4,0) -> 0 | J31: =(G31*H31)*((100-I31)/100) -> 0
A32: =IF(A19=0,0,15.013) -> 0 | C32: =IF(A32=15.013,"ICM repair of PCB-R - INC Recal",0) -> 0 | G32: =IF(A32=15.013,1,0) -> 0 | H32: =IF(A32=15.013,370.31,0) -> 0 | J32: =(G32*H32)*((100-I32)/100) -> 0
A33: =IF(A22=0,0,11.004) -> 0 | C33: =IF(A33=11.004,"ICM Repair of PCB-T",0) -> 0 | G33: =IF(A33=11.004,1,0) -> 0 | J33: =(G33*H33)*((100-I33)/100) -> 0
A34: =IF(A21=0,0,11.06) -> 0 | C34: =IF(A34=11.06,"Chassis Cable",0) -> 0 | G34: =IF(A34=11.06,1,0) -> 0 | J34: =(G34*H34)*((100-I34)/100) -> 0
J35: =(G35*H35)*((100-I35)/100) -> 0
J36: =(G36*H36)*((100-I36)/100) -> 0
J37: =(G37*H37)*((100-I37)/100) -> 0
J38: =(G38*H38)*((100-I38)/100) -> 0
J39: =(G39*H39)*((100-I39)/100) -> 0
J40: =(G40*H40)*((100-I40)/100) -> 0
J41: =(G41*H41)*((100-I41)/100) -> 0
I42: Total | J42: =SUM(J30:J41) -> 178
I43: VAT | J43: =J42*0.2 -> 35.6
I44: GROSS | J44: =J42+J43 -> 213.6
A52: Customer Authorisation | D52: Please sign and return this authorisation to swillett@mpfiltri.co.uk or sales@mpfiltri.co.uk
A54: We accept the above cost to be added to any current order lines, please advise if this isn't acceptable
A55: We accept the above service quotation and authorise MP Filtri to proceed with the repairs
A58: Signed………………………………………………………………………………………………………………. | H58: Service quote number | J58: =D2 -> #REF!
...

Sheet Non UK Sterling service quote
A2: Service Quotation: | D2: ='UK Sterling service quote'!D2 -> #REF!
A4: Serial number of unit(s): | D4: ='UK Sterling service quote'!D4 -> #REF!
A6: Customer: | C6: ='UK Sterling service quote'!C6 -> #REF!
A8: Date: | B8: ='UK Sterling service quote'!B8 -> #REF!
A10: Required work:
A11: ='UK Sterling service quote'!A12 -> 0
A12: ='UK Sterling service quote'!A13 -> 0
A13: ='UK Sterling service quote'!A14 -> 0
A14: ='UK Sterling service quote'!A15 -> 0
A15: ='UK Sterling service quote'!A16 -> 0
A16: ='UK Sterling service quote'!A11 -> Fault Found
A17: ='UK Sterling service quote'!A18 -> Work Done
A18: ='UK Sterling service quote'!A19 -> 0
A19: ='UK Sterling service quote'!A20 -> 0
A20: ='UK Sterling service quote'!A21 -> 0
A21: ='UK Sterling service quote'!A22 -> 0
A22: ='UK Sterling service quote'!A23 -> 0
A23: ='UK Sterling service quote'!A24 -> 0
A24: ='UK Sterling service quote'!A17 -> 0
A27: Cost details: | D27: All figures are in GBP £
A29: Stock Code | C29: Description | F29: Qty | G29: Price | I29: Discount % | J29: Net Price
A30: ='UK Sterling service quote'!A30 -> 15.005 | C30: ='UK Sterling service quote'!C30 -> ICM Recalibration | F30: ='UK Sterling service quote'!G30 -> 1 | G30: ='UK Sterling service quote'!H30 -> 178 | J30: =(F30*G30)*((100-I30)/100) -> 178
A31: ='UK Sterling service quote'!A31 -> 0 | C31: ='UK Sterling service quote'!C31 -> 0 | F31: ='UK Sterling service quote'!G31 -> 0 | G31: ='UK Sterling service quote'!H31 -> 0 | J31: =(F31*G31)*((100-I31)/100) -> 0
A32: ='UK Sterling service quote'!A32 -> 0 | C32: ='UK Sterling service quote'!C32 -> 0 | F32: ='UK Sterling service quote'!G32 -> 0 | G32: ='UK Sterling service quote'!H32 -> 0 | J32: =(F32*G32)*((100-I32)/100) -> 0
A33: ='UK Sterling service quote'!A33 -> 0 | C33: ='UK Sterling service quote'!C33 -> 0 | F33: ='UK Sterling service quote'!G33 -> 0 | G33: ='UK Sterling service quote'!H33 -> 0 | J33: =(F33*G33)*((100-I33)/100) -> 0
A34: ='UK Sterling service quote'!A34 -> 0 | C34: ='UK Sterling service quote'!C34 -> 0 | F34: ='UK Sterling service quote'!G34 -> 0 | G34: ='UK Sterling service quote'!H34 -> 0 | J34: =(F34*G34)*((100-I34)/100) -> 0
C35: ='UK Sterling service quote'!C35 -> 0 | F35: ='UK Sterling service quote'!G35 -> 0 | G35: ='UK Sterling service quote'!H35 -> 0 | J35: =(F35*G35)*((100-I35)/100) -> 0
J36: =(F36*G36)*((100-I36)/100) -> 0
J37: =(F37*G37)*((100-I37)/100) -> 0
J38: =(F38*G38)*((100-I38)/100) -> 0
J39: =(F39*G39)*((100-I39)/100) -> 0
J40: =(F40*G40)*((100-I40)/100) -> 0
J41: =(F41*G41)*((100-I41)/100) -> 0
I42: Total | J42: =SUM(J30:J41) -> 178
A52: Customer Authorisation | D52: Please sign and return this authorisation to swillett@mpfiltri.co.uk or sales@mpfiltri.co.uk
A55: We accept the above service quotation and authorise MP Filtri to proceed with the repairs
A58: Signed………………………………………………………………………………………………………………. | H58: Service quote number | J58: =D2 -> #REF!
H59: Date of service quote | J59: =B8 -> #REF!

Sheet Euro Service Quote
A2: Service Quotation: | D2: ='UK Sterling service quote'!D2 -> #REF!
A4: Serial number of unit(s): | D4: ='UK Sterling service quote'!D4 -> #REF!
A6: Customer: | C6: ='UK Sterling service quote'!C6 -> #REF!
A8: Date: | B8: ='UK Sterling service quote'!B8 -> #REF!
A10: Required work:
A11: ='UK Sterling service quote'!A12 -> 0
A12: ='UK Sterling service quote'!A13 -> 0
A13: ='UK Sterling service quote'!A14 -> 0
A14: ='UK Sterling service quote'!A15 -> 0
A15: ='UK Sterling service quote'!A16 -> 0
A16: ='UK Sterling service quote'!A11 -> Fault Found
A17: ='UK Sterling service quote'!A18 -> Work Done
A18: ='UK Sterling service quote'!A19 -> 0
A19: ='UK Sterling service quote'!A20 -> 0
A20: ='UK Sterling service quote'!A21 -> 0
A21: ='UK Sterling service quote'!A22 -> 0
A22: ='UK Sterling service quote'!A23 -> 0
A23: ='UK Sterling service quote'!A24 -> 0
A24: ='UK Sterling service quote'!A17 -> 0
A27: Cost details: | D27: All figures are in GBP £
A29: Stock Code | C29: Description | F29: Qty | G29: Price | I29: Discount % | J29: Net Price
A30: ='UK Sterling service quote'!A30 -> 15.005 | C30: ='UK Sterling service quote'!C30 -> ICM Recalibration | F30: ='UK Sterling service quote'!G30 -> 1 | G30: =IF(F30=1,200,0) -> 200 | J30: =(F30*G30)*((100-I30)/100) -> 200
A31: ='UK Sterling service quote'!A31 -> 0 | C31: ='UK Sterling service quote'!C31 -> 0 | F31: ='UK Sterling service quote'!G31 -> 0 | G31: =IF(A31=15.012,755.5,0) -> 0 | J31: =(F31*G31)*((100-I31)/100) -> 0
A32: ='UK Sterling service quote'!A32 -> 0 | C32: ='UK Sterling service quote'!C32 -> 0 | F32: ='UK Sterling service quote'!G32 -> 0 | G32: =IF(A32=15.013,450,0) -> 0 | J32: =(F32*G32)*((100-I32)/100) -> 0
A33: ='UK Sterling service quote'!A33 -> 0 | C33: ='UK Sterling service quote'!C33 -> 0 | F33: ='UK Sterling service quote'!G33 -> 0 | G33: ='UK Sterling service quote'!H33 -> 0 | J33: =(F33*G33)*((100-I33)/100) -> 0
A34: ='UK Sterling service quote'!A34 -> 0 | C34: ='UK Sterling service quote'!C34 -> 0 | F34: ='UK Sterling service quote'!G34 -> 0 | G34: ='UK Sterling service quote'!H34 -> 0 | J34: =(F34*G34)*((100-I34)/100) -> 0
F35: ='UK Sterling service quote'!G35 -> 0 | J35: =(F35*G35)*((100-I35)/100) -> 0
J36: =(F36*G36)*((100-I36)/100) -> 0
J37: =(F37*G37)*((100-I37)/100) -> 0
J38: =(F38*G38)*((100-I38)/100) -> 0
J39: =(F39*G39)*((100-I39)/100) -> 0
J40: =(F40*G40)*((100-I40)/100) -> 0
J41: =(F41*G41)*((100-I41)/100) -> 0
I42: Total | J42: =SUM(J30:J41) -> 200
A52: Customer Authorisation | D52: Please sign and return this authorisation to swillett@mpfiltri.co.uk or sales@mpfiltri.co.uk
A55: We accept the above service quotation and authorise MP Filtri to proceed with the repairs
A58: Signed………………………………………………………………………………………………………………. | H58: Service quote number | J58: =D2 -> #REF!
H59: Date of service quote | J59: =B8 -> #REF!

Sheet Calibration record
H2: = Locked cells | L2: 202.027
L3: Rev 1
H4: = Manual Input
G6: CMP type | H6: 11.111121
G7: Serial Number | H7: 000000204 / 07093-41
C8: Units | G8: Date | H8: 08 12 25
B9: =VLOOKUP("no_noise_threshold",CAL!$A$1:$B$1044,2,FALSE) -> 61 | C9: - | D9: No Noise Threshold | G9: Cert No. | H9: =H7 -> 000000204 / 07093-41 | I9: =H8 -> 08 12 25
B10: =VLOOKUP("calibration_led_level_last",CAL!$A$1:$B$1044,2,FALSE)*VLOOKUP("calibration_led_level_initial",CAL!$A$1:$B$1044,2,FALSE)/100 -> 11558.898 | C10: nA | D10: Photocurrent | G10: MTD Batch No. | H10: 12798M
B11: =VLOOKUP("calc_concentration",CAL!$A$1:$B$1044,2,FALSE) -> 15.9952 | C11: mg/L | D11: Calculated final concentration | G11: Test Rig No. | H11: 367
G12: Calibrated by | H12: J Scarrott
B14: (Light Source, LS1)
B15: 4 | C15: 6 | D15: 14 | E15: 21 | F15: 25 | G15: 38 | H15: 50 | I15: 70 | J15: Particle Size Required (µm)
B16: =VLOOKUP("level[0]",CAL!$A$1:$B$1044,2,FALSE) -> 134 | C16: =VLOOKUP("level[1]",CAL!$A$1:$B$1044,2,FALSE) -> 324 | D16: =VLOOKUP("level[2]",CAL!$A$1:$B$1044,2,FALSE) -> 1886 | E16: =VLOOKUP("level[3]",CAL!$A$1:$B$1044,2,FALSE) -> 4122 | F16: =VLOOKUP("level[4]",CAL!$A$1:$B$1044,2,FALSE) -> 6566 | G16: 15500 | H16: =VLOOKUP("level[6]",CAL!$A$1:$B$1044,2,FALSE) -> 22008 | I16: =VLOOKUP("level[7]",CAL!$A$1:$B$1044,2,FALSE) -> 32390 | J16: Set Thresholds
A18: Add screen shots from LPA View of calibration here, include, LED Power level, and W results (where applicable)
A21: Test result | B21: Target | C21: 1 | D21: % Deviation 1 | E21: 2 | F21: % Deviation 2 | G21: 3 | H21: % Deviation 3 | I21: Average Value | J21: % Deviation Ave.
A22: 4 | B22: =mtd!C7*'Calibration record'!B$11*100 -> 3481812.3 | C22: =VLOOKUP("verification_count_0_0",CAL!$A$1:$B$1044,2,FALSE) -> 3502561 | D22: =(C22-B22)/B22 -> 0.0059591709 | E22: =VLOOKUP("verification_count_1_0",CAL!$A$1:$B$1044,2,FALSE) -> 3504210 | F22: =(E22-B22)/B22 -> 0.0064327748 | G22: 3538386 | H22: =(G22-B22)/B22 -> 0.016248353 | I22: =(C22+E22+G22)/3 -> 3515052.3 | J22: =(I22-B22)/B22 -> 0.0095467661
A23: 6 | B23: =mtd!C9*'Calibration record'!B11*100 -> 1368160.9 | C23: =VLOOKUP("verification_count_0_1",CAL!$A$1:$B$1044,2,FALSE) -> 1384415 | D23: =(C23-B23)/B23 -> 0.011880286 | E23: =VLOOKUP("verification_count_1_1",CAL!$A$1:$B$1044,2,FALSE) -> 1382038 | F23: =(E23-B23)/B23 -> 0.010142918 | G23: 1399993 | H23: =(G23-B23)/B23 -> 0.023266374 | I23: =(C23+E23+G23)/3 -> 1388815.3 | J23: =(I23-B23)/B23 -> 0.015096526
A24: 14 | B24: =mtd!C17*'Calibration record'!B11*100 -> 97342.217 | C24: =VLOOKUP("verification_count_0_2",CAL!$A$1:$B$1044,2,FALSE) -> 97621 | D24: =(C24-B24)/B24 -> 0.002863946 | E24: =VLOOKUP("verification_count_1_2",CAL!$A$1:$B$1044,2,FALSE) -> 99179 | F24: =(E24-B24)/B24 -> 0.018869335 | G24: 99930 | H24: =(G24-B24)/B24 -> 0.026584384 | I24: =(C24+E24+G24)/3 -> 98910 | J24: =(I24-B24)/B24 -> 0.016105888
A25: 21 | B25: =mtd!C24*'Calibration record'!B11*100 -> 24221.303 | C25: =VLOOKUP("verification_count_0_3",CAL!$A$1:$B$1044,2,FALSE) -> 23939 | D25: =(C25-B25)/B25 -> -0.011655147 | E25: =VLOOKUP("verification_count_1_3",CAL!$A$1:$B$1044,2,FALSE) -> 24541 | F25: =(E25-B25)/B25 -> 0.013199007 | G25: 25089 | H25: =(G25-B25)/B25 -> 0.035823719 | I25: =(C25+E25+G25)/3 -> 24523 | J25: =(I25-B25)/B25 -> 0.012455859
A26: 25 | B26: =mtd!C28*'Calibration record'!B11*100 -> 11396.58 | C26: =VLOOKUP("verification_count_0_4",CAL!$A$1:$B$1044,2,FALSE) -> 11133 | D26: =(C26-B26)/B26 -> -0.023127991 | E26: =VLOOKUP("verification_count_1_4",CAL!$A$1:$B$1044,2,FALSE) -> 11031 | F26: =(E26-B26)/B26 -> -0.032078044 | G26: 11724 | H26: =(G26-B26)/B26 -> 0.028729672 | I26: =(C26+E26+G26)/3 -> 11296 | J26: =(I26-B26)/B26 -> -0.0088254547
A27: 38 | B27: =mtd!C41*'Calibration record'!B11*100 -> 1788.6061 | C27: =VLOOKUP("verification_count_0_5",CAL!$A$1:$B$1044,2,FALSE) -> 1551 | D27: =(C27-B27)/B27 -> -0.13284429 | E27: =VLOOKUP("verification_count_1_5",CAL!$A$1:$B$1044,2,FALSE) -> 1458 | F27: =(E27-B27)/B27 -> -0.18484009 | G27: 1947 | H27: =(G27-B27)/B27 -> 0.088557164 | I27: =(C27+E27+G27)/3 -> 1652 | J27: =(I27-B27)/B27 -> -0.076375739
A28: 50 | B28: =mtd!C53*'Calibration record'!B11*100 -> 690.64989 | C28: =VLOOKUP("verification_count_0_6",CAL!$A$1:$B$1044,2,FALSE) -> 593 | D28: =(C28-B28)/B28 -> -0.1413884 | E28: =VLOOKUP("verification_count_1_6",CAL!$A$1:$B$1044,2,FALSE) -> 482 | F28: =(E28-B28)/B28 -> -0.3021066 | G28: 379 | H28: =(G28-B28)/B28 -> -0.45124149 | I28: =(C28+E28+G28)/3 -> 484.66667 | J28: =(I28-B28)/B28 -> -0.2982455
A29: 70 | B29: =mtd!C73*'Calibration record'!B11*100 -> 159.952 | C29: =VLOOKUP("verification_count_0_7",CAL!$A$1:$B$1044,2,FALSE) -> 71 | D29: =(C29-B29)/B29 -> -0.55611684 | E29: =VLOOKUP("verification_count_1_7",CAL!$A$1:$B$1044,2,FALSE) -> 71 | F29: =(E29-B29)/B29 -> -0.55611684 | G29: 35 | H29: =(G29-B29)/B29 -> -0.78118436 | I29: =(C29+E29+G29)/3 -> 59 | J29: =(I29-B29)/B29 -> -0.63113934
A32: Add screen shots from LPA View of verification tests here

Sheet Post calibration
C2: Restoring customer settings
C4: User Settings
C5: Format | E5: ='ICM Job Card 2022'!C14 -> - | F5: FALSE
A6: ='ICM Job Card 2022'!C15 -> FALSE | C6: Simulated Test | E6: =IF(A6=TRUE,1,2) -> 2 | F6: FALSE
A7: ='ICM Job Card 2022'!C16 -> FALSE | C7: Low Flow Alarm Disabled | E7: =IF(A7=TRUE,1,2) -> 2 | F7: FALSE
C8: Alarm Mode | E8: ='ICM Job Card 2022'!C17 -> - | F8: FALSE
C9: Contamination codes restored? | F9: FALSE
C11: Continuous Testing Options
A12: ='ICM Job Card 2022'!H12 -> FALSE | C12: Test continuously | E12: =IF(A12=TRUE,1,2) -> 2 | F12: FALSE
A13: ='ICM Job Card 2022'!H13 -> FALSE | C13: Log continuously | E13: =IF(A13=TRUE,1,2) -> 2 | F13: FALSE
A14: ='ICM Job Card 2022'!H14 -> FALSE | C14: Start testing automatically | E14: =IF(A14=TRUE,1,2) -> 2 | F14: FALSE
A15: ='ICM Job Card 2022'!H15 -> FALSE | C15: Stop testing when clean | E15: =IF(A15=TRUE,1,2) -> 2 | F15: FALSE
A16: ='ICM Job Card 2022'!H16 -> FALSE | C16: Confirm target levels | E16: =IF(A16=TRUE,1,2) -> 2 | F16: FALSE
C17: Before stopping (x) times? | E17: ='ICM Job Card 2022'!H17 -> 0 | F17: FALSE
C18: Ignore initial tests | E18: ='ICM Job Card 2022'!H18 -> 0 | F18: FALSE
C20: System Settings
C21: Sensing Vol. Parameters | E21: ='ICM Job Card 2022'!C20 -> - | F21: FALSE
C22: Test Reference | E22: ='ICM Job Card 2022'!C21 -> 0 | F22: FALSE
C23: Accumulation Time (s) | E23: ='ICM Job Card 2022'!C22 -> 0 | F23: FALSE
A24: ='ICM Job Card 2022'!C23 -> FALSE | C24: Auto-repeat on? | E24: =IF(A24=TRUE,1,2) -> 2 | F24: FALSE
C25: Interval (s) | E25: ='ICM Job Card 2022'!C24 -> 0 | F25: FALSE
A26: ='ICM Job Card 2022'!C25 -> FALSE | C26: W - Water Sensor | E26: =IF(A26=TRUE,1,2) -> 2 | F26: FALSE
A27: ='ICM Job Card 2022'!C26 -> FALSE | C27: R - Alarm Relays | E27: =IF(A27=TRUE,1,2) -> 2 | F27: FALSE
C30: Admin and record-keeping
C32: Complete calibration record | F32: FALSE
C33: Select appropriate cal cert | F33: FALSE
C34: Print to pdf | F34: FALSE
C35: Print 2 physical copies in colour | F35: FALSE
C36: Update simplybook.me | F36: FALSE
C37: Fill in Job Card | F37: FALSE
C38: Update whiteboard on window | F38: FALSE
C41: Packing
C43: Turn off rig, switch to clean-up | F43: FALSE
C44: Close oil taps and turn rig back on | F44: FALSE
C45: Attach bottle sampler to lines | F45: FALSE
C46: Blow air through the ICMs to clear | F46: FALSE
C47: Add calibration sticker under label | F47: FALSE
C48: Remove and take to logistics | F48: FALSE
C49: Post-calibration completed by: | F49: -
A127: FALSE

Sheet MP Calibration Certificate
B2: MP Filtri UK Ltd
B3: Keep House, Conference Way, Vale Park South,
B4: Evesham
B5: England
B6: WR11 1 LB
B7: Tel: +44 (0) 1386 258500
B8: www.mpfiltri.co.uk
B10: CERTIFICATE OF CALIBRATION
B13: WE HEREBY CERTIFY THAT THE CONTAMINATION MONITORING PRODUCT DETAILED BELOW HAS BEEN FULLY CALIBRATED WITH ISO MEDIUM TEST DUST (MTD) BASED ON ISO 11171 ON TEST EQUIPMENT CERTIFIED TO ISO 11943 BY I.F.T.S {Institut de la Filtration et des Techniques Séparatives}.
B14: We hereby confirm that the above mentioned measuring system was calibrated according to DIN ISO 9001, under the observation of a certified quality assurance system. The measuring installation used for calibration are regularly calibrated to national standards by I.F.T.S. Should no national standards exist, the measuring procedure corresponds with the technical regulations and norms valid at the time of the measurement
B17: PRODUCT TYPE | D17: ICMWMKRG12.0AZ2 | K17: MEDIUM TEST DUST BATCH NUMBER | O17: ='Calibration record'!H10 -> 12798M
B18: SERIAL NUMBER | D18: ='Calibration record'!H7 -> 000000204 / 07093-41 | K18: DATE OF CALIBRATION | O18: ='Calibration record'!H8 -> 08 12 25
B19: CERTIFICATE NUMBER | D19: ='Calibration record'!H9 -> 000000204 / 07093-41 | E19: ='Calibration record'!I9 -> 08 12 25 | K19: CALIBRATION RIG NUMBER | O19: ='Calibration record'!H11 -> 367
B21: PARTICLE COUNT LIMITS AT 16mg/L CONCENTRATION
B22: (Suspension of ISO MTD in MIL-H-5606)
B23: No. particles reported per 100ml volume
D26: Particle Size | F26: Calibration Pulse Height | H26: Target Particle Count | J26: Actual Particle Count | K26: Deviation | L26: % Deviation (+/- 10%)
D27: [microns (c)] | F27: [mV] | H27: [n] | J27: [n] | K27: [n] | L27: [%]
D28: >4 | F28: ='Calibration record'!B16 -> 134 | H28: ='Calibration record'!B22 -> 3481812.3 | J28: ='Calibration record'!I22 -> 3515052.3 | K28: =J28-H28 -> 33240.048 | L28: ='Calibration record'!J22 -> 0.0095467661
D29: >6 | F29: ='Calibration record'!C16 -> 324 | H29: ='Calibration record'!B23 -> 1368160.9 | J29: ='Calibration record'!I23 -> 1388815.3 | K29: =J29-H29 -> 20654.476 | L29: ='Calibration record'!J23 -> 0.015096526
D30: >14 | F30: ='Calibration record'!D16 -> 1886 | H30: ='Calibration record'!B24 -> 97342.217 | J30: ='Calibration record'!I24 -> 98910 | K30: =J30-H30 -> 1567.7829 | L30: ='Calibration record'!J24 -> 0.016105888
D31: >21 | F31: ='Calibration record'!E16 -> 4122 | H31: ='Calibration record'!B25 -> 24221.303 | J31: ='Calibration record'!I25 -> 24523 | K31: =J31-H31 -> 301.69714 | L31: ='Calibration record'!J25 -> 0.012455859
D32: >25 | F32: ='Calibration record'!F16 -> 6566 | H32: ='Calibration record'!B26 -> 11396.58 | J32: ='Calibration record'!I26 -> 11296 | K32: =J32-H32 -> -100.58 | L32: ='Calibration record'!J26 -> -0.0088254547
D33: >38 | F33: ='Calibration record'!G16 -> 15500 | H33: ='Calibration record'!B27 -> 1788.6061 | J33: ='Calibration record'!I27 -> 1652 | K33: =J33-H33 -> -136.60611 | L33: ='Calibration record'!J27 -> -0.076375739
D34: >**50 | F34: ='Calibration record'!H16 -> 22008 | H34: ='Calibration record'!B28 -> 690.64989 | J34: ='Calibration record'!I28 -> 484.66667 | K34: - | L34: -
D35: >**70 | F35: ='Calibration record'!I16 -> 32390 | H35: ='Calibration record'!B29 -> 159.952 | J35: ='Calibration record'!I29 -> 59 | K35: - | L35: -
D36: **These particle sizes are not yet certified by NIST
D38: LS1 No Noise Threshold | E38: LS1 Threshold Sensitivity | G38: Sensitivity Threshold Ratio
D39: [mV] | E39: [mV] | G39: [-]
D40: ='Calibration record'!B9 -> 61 | E40: =F28-D40 -> 73 | G40: =F28/D40 -> 2.1967213
B72: CALIBRATION RESULT | D72: PASS | K72: PASS - VERIFIED
B74: RE-CALIBRATION DUE | D74: 1 YEAR FROM FIRST USE (refer to ICM diagnostics)
B76: CALIBRATED BY | K76: Position | L76: Calibration Lab Technician
D77: ='Calibration record'!H12 -> J Scarrott
B78: Newly purchased products are covered under warranty for 12 months from first use | K78: We hereby certify that this instrument meets standard performance criteria, providing calibration results within +/-10% of target concentration values from >4um to >38um, and exhibits a sensitivity threshold ratio of greater than 1.19 for each light source
B79: Products being returned for re-calibration are verified for accuracy for a further 12 months. This does not extend the warranty.
B80: Customers are responsible for managing the intervals between calibration's as defined within IS0 9001:2000
O83: Doc No. 202.027-02
O84: Sheet 1
O85: DCRXXXX
...

Sheet DESCASE CERT
B10: CERTIFICATE OF CALIBRATION
B13: WE HEREBY CERTIFY THAT THE CONTAMINATION MONITORING PRODUCT DETAILED BELOW HAS BEEN FULLY CALIBRATED WITH ISO MEDIUM TEST DUST (MTD) BASED ON ISO 11171 ON TEST EQUIPMENT CERTIFIED TO ISO 11943 BY I.F.T.S {Institut de la Filtration et des Techniques Séparatives}.
B14: We hereby confirm that the above mentioned measuring system was calibrated according to DIN ISO 9001, under the observation of a certified quality assurance system. The measuring installation used for calibration are regularly calibrated to national standards by I.F.T.S. Should no national standards exist, the measuring procedure corresponds with the technical regulations and norms valid at the time of the measurement
B17: PRODUCT TYPE | D17: ='Calibration record'!H6 -> 11.111121 | K17: MEDIUM TEST DUST BATCH NUMBER | O17: ='[1]Calibration record'!H10 -> 12798M
B18: SERIAL NUMBER | D18: ='Calibration record'!H7 -> 000000204 / 07093-41 | K18: DATE OF CALIBRATION | O18: ='Calibration record'!H8 -> 08 12 25
B19: CERTIFICATE NUMBER | D19: =D18 -> 000000204 / 07093-41 | E19: ='Calibration record'!H8 -> 08 12 25 | K19: CALIBRATION RIG NUMBER | O19: ='Calibration record'!H11 -> 367
B21: PARTICLE COUNT LIMITS AT 16mg/L CONCENTRATION
B22: (Suspension of ISO MTD in MIL-H-5606)
B23: No. particles reported per 100ml volume
D26: Particle Size | F26: Calibration Pulse Height | H26: Target Particle Count | J26: Actual Particle Count | K26: Deviation | L26: % Deviation (+/- 10%)
D27: [microns (c)] | F27: [mV] | H27: [n] | J27: [n] | K27: [n] | L27: [%]
D28: >4 | F28: ='Calibration record'!B16 -> 134 | H28: ='Calibration record'!B22 -> 3481812.3 | J28: ='Calibration record'!I22 -> 3515052.3 | K28: =J28-H28 -> 33240.048 | L28: ='Calibration record'!J22 -> 0.0095467661
D29: >6 | F29: ='Calibration record'!C16 -> 324 | H29: ='Calibration record'!B23 -> 1368160.9 | J29: ='Calibration record'!I23 -> 1388815.3 | K29: =J29-H29 -> 20654.476 | L29: ='Calibration record'!J23 -> 0.015096526
D30: >14 | F30: ='Calibration record'!D16 -> 1886 | H30: ='Calibration record'!B24 -> 97342.217 | J30: ='Calibration record'!I24 -> 98910 | K30: =J30-H30 -> 1567.7829 | L30: ='Calibration record'!J24 -> 0.016105888
D31: >21 | F31: ='Calibration record'!E16 -> 4122 | H31: ='Calibration record'!B25 -> 24221.303 | J31: ='Calibration record'!I25 -> 24523 | K31: =J31-H31 -> 301.69714 | L31: ='Calibration record'!J25 -> 0.012455859
D32: >25 | F32: ='Calibration record'!F16 -> 6566 | H32: ='Calibration record'!B26 -> 11396.58 | J32: ='Calibration record'!I26 -> 11296 | K32: =J32-H32 -> -100.58 | L32: ='Calibration record'!J26 -> -0.0088254547
D33: >38 | F33: ='Calibration record'!G16 -> 15500 | H33: ='Calibration record'!B27 -> 1788.6061 | J33: ='Calibration record'!I27 -> 1652 | K33: =J33-H33 -> -136.60611 | L33: ='Calibration record'!J27 -> -0.076375739
D34: >**50 | F34: ='Calibration record'!H16 -> 22008 | H34: ='Calibration record'!B28 -> 690.64989 | J34: ='Calibration record'!I28 -> 484.66667 | K34: - | L34: -
D35: >**70 | F35: ='Calibration record'!I16 -> 32390 | H35: ='Calibration record'!B29 -> 159.952 | J35: ='Calibration record'!I29 -> 59 | K35: - | L35: -
D36: **These particle sizes are not yet certified by NIST
D38: LS1 No Noise Threshold | E38: LS1 Threshold Sensitivity | G38: Sensitivity Threshold Ratio
D39: [mV] | E39: [mV] | G39: [-]
D40: ='Calibration record'!B9 -> 61 | E40: =F28-D40 -> 73 | G40: =F28/D40 -> 2.1967213
B72: CALIBRATION RESULT | D72: PASS | K72: PASS - VERIFIED
B74: RE-CALIBRATION DUE | D74: 1 YEAR FROM FIRST USE (refer to CMS diagnostics)
B76: CALIBRATED BY | D76: ='[1]Calibration record'!H12 -> J Scarrott | K76: Position | L76: Calibration Lab Technician
B78: Newly purchased products are covered under warranty for 12 months from first use | K78: We hereby certify that this instrument meets standard performance criteria, providing calibration results within +/-10% of target concentration values from >4um to >38um, and exhibits a sensitivity threshold ratio of greater than 1.19 for each light source
B79: Products being returned for re-calibration are verified for accuracy for a further 12 months. This does not extend the warranty.
B80: Customers are responsible for managing the intervals between calibration's as defined within IS0 9001:2000
O83: Doc No. 202.027
B86: Page 1 of 1

Sheet LPM Certificate
B10: CERTIFICATE OF CALIBRATION
B13: WE HEREBY CERTIFY THAT THE CONTAMINATION MONITORING PRODUCT DETAILED BELOW HAS BEEN FULLY CALIBRATED WITH ISO MEDIUM TEST DUST (MTD) BASED ON ISO 11171 ON TEST EQUIPMENT CERTIFIED TO ISO 11943 BY I.F.T.S {Institut de la Filtration et des Techniques Séparatives}.
B14: We hereby confirm that the above mentioned measuring system was calibrated according to DIN ISO 9001, under the observation of a certified quality assurance system. The measuring installation used for calibration are regularly calibrated to national standards by I.F.T.S. Should no national standards exist, the measuring procedure corresponds with the technical regulations and norms valid at the time of the measurement
B17: PRODUCT TYPE | D17: ='Calibration record'!H6 -> 11.111121 | K17: MEDIUM TEST DUST BATCH NUMBER | O17: ='Calibration record'!H10 -> 12798M
B18: SERIAL NUMBER | D18: ='Calibration record'!H7 -> 000000204 / 07093-41 | K18: DATE OF CALIBRATION | O18: ='Calibration record'!H8 -> 08 12 25
B19: CERTIFICATE NUMBER | D19: ='Calibration record'!H9 -> 000000204 / 07093-41 | K19: CALIBRATION RIG NUMBER | O19: ='Calibration record'!H11 -> 367
B21: PARTICLE COUNT LIMITS AT 16mg/L CONCENTRATION
B22: (Suspension of ISO MTD in MIL-H-5606)
B23: No. particles reported per 100ml volume
D26: Particle Size | F26: Calibration Pulse Height | H26: Target Particle Count | J26: Actual Particle Count | K26: Deviation | L26: % Deviation (+/- 10%)
D27: [microns (c)] | F27: [mV] | H27: [n] | J27: [n] | K27: [n] | L27: [%]
D28: >4 | F28: ='Calibration record'!B16 -> 134 | H28: ='Calibration record'!B22 -> 3481812.3 | J28: ='Calibration record'!I22 -> 3515052.3 | K28: =J28-H28 -> 33240.048 | L28: ='Calibration record'!J22 -> 0.0095467661
D29: >6 | F29: ='Calibration record'!C16 -> 324 | H29: ='Calibration record'!B23 -> 1368160.9 | J29: ='Calibration record'!I23 -> 1388815.3 | K29: =J29-H29 -> 20654.476 | L29: ='Calibration record'!J23 -> 0.015096526
D30: >14 | F30: ='Calibration record'!D16 -> 1886 | H30: ='Calibration record'!B24 -> 97342.217 | J30: ='Calibration record'!I24 -> 98910 | K30: =J30-H30 -> 1567.7829 | L30: ='Calibration record'!J24 -> 0.016105888
D31: >21 | F31: ='Calibration record'!E16 -> 4122 | H31: ='Calibration record'!B25 -> 24221.303 | J31: ='Calibration record'!I25 -> 24523 | K31: =J31-H31 -> 301.69714 | L31: ='Calibration record'!J25 -> 0.012455859
D32: >25 | F32: ='Calibration record'!F16 -> 6566 | H32: ='Calibration record'!B26 -> 11396.58 | J32: ='Calibration record'!I26 -> 11296 | K32: =J32-H32 -> -100.58 | L32: ='Calibration record'!J26 -> -0.0088254547
D33: >38 | F33: ='Calibration record'!G16 -> 15500 | H33: ='Calibration record'!B27 -> 1788.6061 | J33: ='Calibration record'!I27 -> 1652 | K33: =J33-H33 -> -136.60611 | L33: ='Calibration record'!J27 -> -0.076375739
D34: >**50 | F34: ='Calibration record'!H16 -> 22008 | H34: ='Calibration record'!B28 -> 690.64989 | J34: ='Calibration record'!I28 -> 484.66667 | K34: - | L34: -
D35: >**70 | F35: ='Calibration record'!I16 -> 32390 | H35: ='Calibration record'!B29 -> 159.952 | J35: ='Calibration record'!I29 -> 59 | K35: - | L35: -
D36: **These particle sizes are not yet certified by NIST
D38: LS1 No Noise Threshold | E38: LS1 Threshold Sensitivity | G38: Sensitivity Threshold Ratio
D39: [mV] | E39: [mV] | G39: [-]
D40: ='Calibration record'!B9 -> 61 | E40: =F28-D40 -> 73 | G40: =F28/D40 -> 2.1967213
B72: CALIBRATION RESULT | D72: PASS | K72: PASS - VERIFIED
B74: RE-CALIBRATION DUE | D74: 1 YEAR FROM FIRST USE (refer to ICM diagnostics)
B76: CALIBRATED BY | D76: ='Calibration record'!H12 -> J Scarrott | K76: Position | L76: Calibration Lab Technician
B78: Newly purchased products are covered under warranty for 12 months from first use | K78: We hereby certify that this instrument meets standard performance criteria, providing calibration results within +/-10% of target concentration values from >4um to >38um, and exhibits a sensitivity threshold ratio of greater than 1.19 for each light source
B79: Products being returned for re-calibration are verified for accuracy for a further 12 months. This does not extend the warranty.
B80: Customers are responsible for managing the intervals between calibration's as defined within IS0 9001:2000
O83: Doc No. 202.027
B86: Page 1 of 1

Sheet Solge Certificate
B10: CERTIFICATE OF CALIBRATION
B13: WE HEREBY CERTIFY THAT THE CONTAMINATION MONITORING PRODUCT DETAILED BELOW HAS BEEN FULLY CALIBRATED WITH ISO MEDIUM TEST DUST (MTD) BASED ON ISO 11171 ON TEST EQUIPMENT CERTIFIED TO ISO 11943 BY I.F.T.S {Institut de la Filtration et des Techniques Séparatives}.
B14: We hereby confirm that the above mentioned measuring system was calibrated according to DIN ISO 9001, under the observation of a certified quality assurance system. The measuring installation used for calibration are regularly calibrated to national standards by I.F.T.S. Should no national standards exist, the measuring procedure corresponds with the technical regulations and norms valid at the time of the measurement
B17: PRODUCT TYPE | D17: ='Calibration record'!H6 -> 11.111121 | K17: MEDIUM TEST DUST BATCH NUMBER | O17: ='Calibration record'!H10 -> 12798M
B18: SERIAL NUMBER | D18: ='Calibration record'!H7 -> 000000204 / 07093-41 | K18: DATE OF CALIBRATION | O18: ='Calibration record'!H8 -> 08 12 25
B19: CERTIFICATE NUMBER | D19: ='Calibration record'!H9 -> 000000204 / 07093-41 | K19: CALIBRATION RIG NUMBER | O19: ='Calibration record'!H11 -> 367
B21: PARTICLE COUNT LIMITS AT 16mg/L CONCENTRATION
B22: (Suspension of ISO MTD in MIL-H-5606)
B23: No. particles reported per 100ml volume
D26: Particle Size | F26: Calibration Pulse Height | H26: Target Particle Count | J26: Actual Particle Count | K26: Deviation | L26: % Deviation (+/- 10%)
D27: [microns (c)] | F27: [mV] | H27: [n] | J27: [n] | K27: [n] | L27: [%]
D28: >4 | F28: ='Calibration record'!B16 -> 134 | H28: ='Calibration record'!B22 -> 3481812.3 | J28: ='Calibration record'!I22 -> 3515052.3 | K28: =J28-H28 -> 33240.048 | L28: ='Calibration record'!J22 -> 0.0095467661
D29: >6 | F29: ='Calibration record'!C16 -> 324 | H29: ='Calibration record'!B23 -> 1368160.9 | J29: ='Calibration record'!I23 -> 1388815.3 | K29: =J29-H29 -> 20654.476 | L29: ='Calibration record'!J23 -> 0.015096526
D30: >14 | F30: ='Calibration record'!D16 -> 1886 | H30: ='Calibration record'!B24 -> 97342.217 | J30: ='Calibration record'!I24 -> 98910 | K30: =J30-H30 -> 1567.7829 | L30: ='Calibration record'!J24 -> 0.016105888
D31: >21 | F31: ='Calibration record'!E16 -> 4122 | H31: ='Calibration record'!B25 -> 24221.303 | J31: ='Calibration record'!I25 -> 24523 | K31: =J31-H31 -> 301.69714 | L31: ='Calibration record'!J25 -> 0.012455859
D32: >25 | F32: ='Calibration record'!F16 -> 6566 | H32: ='Calibration record'!B26 -> 11396.58 | J32: ='Calibration record'!I26 -> 11296 | K32: =J32-H32 -> -100.58 | L32: ='Calibration record'!J26 -> -0.0088254547
D33: >38 | F33: ='Calibration record'!G16 -> 15500 | H33: ='Calibration record'!B27 -> 1788.6061 | J33: ='Calibration record'!I27 -> 1652 | K33: =J33-H33 -> -136.60611 | L33: ='Calibration record'!J27 -> -0.076375739
D34: >**50 | F34: ='Calibration record'!H16 -> 22008 | H34: ='Calibration record'!B28 -> 690.64989 | J34: ='Calibration record'!I28 -> 484.66667 | K34: - | L34: -
D35: >**70 | F35: ='Calibration record'!I16 -> 32390 | H35: ='Calibration record'!B29 -> 159.952 | J35: ='Calibration record'!I29 -> 59 | K35: - | L35: -
D36: **These particle sizes are not yet certified by NIST
D38: LS1 No Noise Threshold | E38: LS1 Threshold Sensitivity | G38: Sensitivity Threshold Ratio
D39: [mV] | E39: [mV] | G39: [-]
D40: ='Calibration record'!B9 -> 61 | E40: =F28-D40 -> 73 | G40: =F28/D40 -> 2.1967213
B72: CALIBRATION RESULT | D72: PASS | K72: PASS - VERIFIED
B74: RE-CALIBRATION DUE | D74: 1 YEAR FROM FIRST USE (refer to ICM diagnostics)
B76: CALIBRATED BY | D76: ='Calibration record'!H12 -> J Scarrott | K76: Position | L76: Calibration Lab Technician
B78: Newly purchased products are covered under warranty for 12 months from first use | K78: We hereby certify that this instrument meets standard performance criteria, providing calibration results within +/-10% of target concentration values from >4um to >38um, and exhibits a sensitivity threshold ratio of greater than 1.19 for each light source
B79: Products being returned for re-calibration are verified for accuracy for a further 12 months. This does not extend the warranty.
B80: Customers are responsible for managing the intervals between calibration's as defined within IS0 9001:2000
O83: Doc No. 202.027
B86: Page 1 of 1

Sheet RMF Certificate
B10: CERTIFICATE OF CALIBRATION
B13: WE HEREBY CERTIFY THAT THE CONTAMINATION MONITORING PRODUCT DETAILED BELOW HAS BEEN FULLY CALIBRATED WITH ISO MEDIUM TEST DUST (MTD) BASED ON ISO 11171 ON TEST EQUIPMENT CERTIFIED TO ISO 11943 BY I.F.T.S {Institut de la Filtration et des Techniques Séparatives}.
B14: We hereby confirm that the above mentioned measuring system was calibrated according to DIN ISO 9001, under the observation of a certified quality assurance system. The measuring installation used for calibration are regularly calibrated to national standards by I.F.T.S. Should no national standards exist, the measuring procedure corresponds with the technical regulations and norms valid at the time of the measurement
B17: PRODUCT TYPE | D17: ='Calibration record'!H6 -> 11.111121 | K17: MEDIUM TEST DUST BATCH NUMBER | O17: ='Calibration record'!H10 -> 12798M
B18: SERIAL NUMBER | D18: ='Calibration record'!H7 -> 000000204 / 07093-41 | K18: DATE OF CALIBRATION | O18: ='Calibration record'!H8 -> 08 12 25
B19: CERTIFICATE NUMBER | D19: ='Calibration record'!H9 -> 000000204 / 07093-41 | K19: CALIBRATION RIG NUMBER | O19: ='Calibration record'!H11 -> 367
B21: PARTICLE COUNT LIMITS AT 16mg/L CONCENTRATION
B22: (Suspension of ISO MTD in MIL-H-5606)
B23: No. particles reported per 100ml volume
D26: Particle Size | F26: Calibration Pulse Height | H26: Target Particle Count | J26: Actual Particle Count | K26: Deviation | L26: % Deviation (+/- 10%)
D27: [microns (c)] | F27: [mV] | H27: [n] | J27: [n] | K27: [n] | L27: [%]
D28: >4 | F28: ='Calibration record'!B16 -> 134 | H28: ='Calibration record'!B22 -> 3481812.3 | J28: ='Calibration record'!I22 -> 3515052.3 | K28: =J28-H28 -> 33240.048 | L28: ='Calibration record'!J22 -> 0.0095467661
D29: >6 | F29: ='Calibration record'!C16 -> 324 | H29: ='Calibration record'!B23 -> 1368160.9 | J29: ='Calibration record'!I23 -> 1388815.3 | K29: =J29-H29 -> 20654.476 | L29: ='Calibration record'!J23 -> 0.015096526
D30: >14 | F30: ='Calibration record'!D16 -> 1886 | H30: ='Calibration record'!B24 -> 97342.217 | J30: ='Calibration record'!I24 -> 98910 | K30: =J30-H30 -> 1567.7829 | L30: ='Calibration record'!J24 -> 0.016105888
D31: >21 | F31: ='Calibration record'!E16 -> 4122 | H31: ='Calibration record'!B25 -> 24221.303 | J31: ='Calibration record'!I25 -> 24523 | K31: =J31-H31 -> 301.69714 | L31: ='Calibration record'!J25 -> 0.012455859
D32: >25 | F32: ='Calibration record'!F16 -> 6566 | H32: ='Calibration record'!B26 -> 11396.58 | J32: ='Calibration record'!I26 -> 11296 | K32: =J32-H32 -> -100.58 | L32: ='Calibration record'!J26 -> -0.0088254547
D33: >38 | F33: ='Calibration record'!G16 -> 15500 | H33: ='Calibration record'!B27 -> 1788.6061 | J33: ='Calibration record'!I27 -> 1652 | K33: =J33-H33 -> -136.60611 | L33: ='Calibration record'!J27 -> -0.076375739
D34: >**50 | F34: ='Calibration record'!H16 -> 22008 | H34: ='Calibration record'!B28 -> 690.64989 | J34: ='Calibration record'!I28 -> 484.66667 | K34: - | L34: -
D35: >**70 | F35: ='Calibration record'!I16 -> 32390 | H35: ='Calibration record'!B29 -> 159.952 | J35: ='Calibration record'!I29 -> 59 | K35: - | L35: -
D36: **These particle sizes are not yet certified by NIST
D38: LS1 No Noise Threshold | E38: LS1 Threshold Sensitivity | G38: Sensitivity Threshold Ratio
D39: [mV] | E39: [mV] | G39: [-]
D40: ='Calibration record'!B9 -> 61 | E40: =F28-D40 -> 73 | G40: =F28/D40 -> 2.1967213
B72: CALIBRATION RESULT | D72: PASS | K72: PASS - VERIFIED
B74: RE-CALIBRATION DUE | D74: 1 YEAR FROM FIRST USE (refer to ICM diagnostics)
B76: CALIBRATED BY | D76: ='Calibration record'!H12 -> J Scarrott | K76: Position | L76: Calibration Lab Technician
B78: Newly purchased products are covered under warranty for 12 months from first use | K78: We hereby certify that this instrument meets standard performance criteria, providing calibration results within +/-10% of target concentration values from >4um to >38um, and exhibits a sensitivity threshold ratio of greater than 1.19 for each light source
B79: Products being returned for re-calibration are verified for accuracy for a further 12 months. This does not extend the warranty.
B80: Customers are responsible for managing the intervals between calibration's as defined within IS0 9001:2000
O83: Doc No. 202.027
B86: Page 1 of 1

Sheet CCJ Certificate
B10: CERTIFICATE OF CALIBRATION
B13: WE HEREBY CERTIFY THAT THE CONTAMINATION MONITORING PRODUCT DETAILED BELOW HAS BEEN FULLY CALIBRATED WITH ISO MEDIUM TEST DUST (MTD) BASED ON ISO 11171 ON TEST EQUIPMENT CERTIFIED TO ISO 11943 BY I.F.T.S {Institut de la Filtration et des Techniques Séparatives}.
B14: We hereby confirm that the above mentioned measuring system was calibrated according to DIN ISO 9001, under the observation of a certified quality assurance system. The measuring installation used for calibration are regularly calibrated to national standards by I.F.T.S. Should no national standards exist, the measuring procedure corresponds with the technical regulations and norms valid at the time of the measurement
B17: PRODUCT TYPE | D17: ='Calibration record'!H6 -> 11.111121 | K17: MEDIUM TEST DUST BATCH NUMBER | O17: ='Calibration record'!H10 -> 12798M
B18: SERIAL NUMBER | D18: ='Calibration record'!H7 -> 000000204 / 07093-41 | K18: DATE OF CALIBRATION | O18: ='Calibration record'!H8 -> 08 12 25
B19: CERTIFICATE NUMBER | D19: ='Calibration record'!H9 -> 000000204 / 07093-41 | K19: CALIBRATION RIG NUMBER | O19: ='Calibration record'!H11 -> 367
B21: PARTICLE COUNT LIMITS AT 16mg/L CONCENTRATION
B22: (Suspension of ISO MTD in MIL-H-5606)
B23: No. particles reported per 100ml volume
D26: Particle Size | F26: Calibration Pulse Height | H26: Target Particle Count | J26: Actual Particle Count | K26: Deviation | L26: % Deviation (+/- 10%)
D27: [microns (c)] | F27: [mV] | H27: [n] | J27: [n] | K27: [n] | L27: [%]
D28: >4 | F28: ='Calibration record'!B16 -> 134 | H28: ='Calibration record'!B22 -> 3481812.3 | J28: ='Calibration record'!I22 -> 3515052.3 | K28: =J28-H28 -> 33240.048 | L28: ='Calibration record'!J22 -> 0.0095467661
D29: >6 | F29: ='Calibration record'!C16 -> 324 | H29: ='Calibration record'!B23 -> 1368160.9 | J29: ='Calibration record'!I23 -> 1388815.3 | K29: =J29-H29 -> 20654.476 | L29: ='Calibration record'!J23 -> 0.015096526
D30: >14 | F30: ='Calibration record'!D16 -> 1886 | H30: ='Calibration record'!B24 -> 97342.217 | J30: ='Calibration record'!I24 -> 98910 | K30: =J30-H30 -> 1567.7829 | L30: ='Calibration record'!J24 -> 0.016105888
D31: >21 | F31: ='Calibration record'!E16 -> 4122 | H31: ='Calibration record'!B25 -> 24221.303 | J31: ='Calibration record'!I25 -> 24523 | K31: =J31-H31 -> 301.69714 | L31: ='Calibration record'!J25 -> 0.012455859
D32: >25 | F32: ='Calibration record'!F16 -> 6566 | H32: ='Calibration record'!B26 -> 11396.58 | J32: ='Calibration record'!I26 -> 11296 | K32: =J32-H32 -> -100.58 | L32: ='Calibration record'!J26 -> -0.0088254547
D33: >38 | F33: ='Calibration record'!G16 -> 15500 | H33: ='Calibration record'!B27 -> 1788.6061 | J33: ='Calibration record'!I27 -> 1652 | K33: =J33-H33 -> -136.60611 | L33: ='Calibration record'!J27 -> -0.076375739
D34: >**50 | F34: ='Calibration record'!H16 -> 22008 | H34: ='Calibration record'!B28 -> 690.64989 | J34: ='Calibration record'!I28 -> 484.66667 | K34: - | L34: -
D35: >**70 | F35: ='Calibration record'!I16 -> 32390 | H35: ='Calibration record'!B29 -> 159.952 | J35: ='Calibration record'!I29 -> 59 | K35: - | L35: -
D36: **These particle sizes are not yet certified by NIST
D38: LS1 No Noise Threshold | E38: LS1 Threshold Sensitivity | G38: Sensitivity Threshold Ratio
D39: [mV] | E39: [mV] | G39: [-]
D40: ='Calibration record'!B9 -> 61 | E40: =F28-D40 -> 73 | G40: =F28/D40 -> 2.1967213
B72: CALIBRATION RESULT | D72: PASS | K72: PASS - VERIFIED
B74: RE-CALIBRATION DUE | D74: 2 YEARS FROM FIRST USE (refer to OCM diagnostics)
B76: CALIBRATED BY | D76: ='Calibration record'!H12 -> J Scarrott | K76: Position | L76: Calibration Lab Technician
B78: Newly purchased products are covered under warranty for 12 months from first use | K78: We hereby certify that this instrument meets standard performance criteria, providing calibration results within +/-10% of target concentration values from >4um to >38um, and exhibits a sensitivity threshold ratio of greater than 1.19 for each light source
B79: Products being returned for re-calibration are verified for accuracy for a further 12 months. This does not extend the warranty.
B80: Customers are responsible for managing the intervals between calibration's as defined within IS0 9001:2000
O83: Doc No. 202.027
B86: Page 1 of 1

Sheet Hanzaflex Certificate
B10: CERTIFICATE OF CALIBRATION
B13: WE HEREBY CERTIFY THAT THE CONTAMINATION MONITORING PRODUCT DETAILED BELOW HAS BEEN FULLY CALIBRATED WITH ISO MEDIUM TEST DUST (MTD) BASED ON ISO 11171 ON TEST EQUIPMENT CERTIFIED TO ISO 11943 BY I.F.T.S {Institut de la Filtration et des Techniques Séparatives}.
B14: We hereby confirm that the above mentioned measuring system was calibrated according to DIN ISO 9001, under the observation of a certified quality assurance system. The measuring installation used for calibration are regularly calibrated to national standards by I.F.T.S. Should no national standards exist, the measuring procedure corresponds with the technical regulations and norms valid at the time of the measurement
B17: PRODUCT TYPE | D17: ='Calibration record'!H6 -> 11.111121 | K17: MEDIUM TEST DUST BATCH NUMBER | O17: ='Calibration record'!H10 -> 12798M
B18: SERIAL NUMBER | D18: ='Calibration record'!H7 -> 000000204 / 07093-41 | K18: DATE OF CALIBRATION | O18: ='Calibration record'!H8 -> 08 12 25
B19: CERTIFICATE NUMBER | D19: ='Calibration record'!H9 -> 000000204 / 07093-41 | K19: CALIBRATION RIG NUMBER | O19: ='Calibration record'!H11 -> 367
B21: PARTICLE COUNT LIMITS AT 16mg/L CONCENTRATION
B22: (Suspension of ISO MTD in MIL-H-5606)
B23: No. particles reported per 100ml volume
D26: Particle Size | F26: Calibration Pulse Height | H26: Target Particle Count | J26: Actual Particle Count | K26: Deviation | L26: % Deviation (+/- 10%)
D27: [microns (c)] | F27: [mV] | H27: [n] | J27: [n] | K27: [n] | L27: [%]
D28: >4 | F28: ='Calibration record'!B16 -> 134 | H28: ='Calibration record'!B22 -> 3481812.3 | J28: ='Calibration record'!I22 -> 3515052.3 | K28: =J28-H28 -> 33240.048 | L28: ='Calibration record'!J22 -> 0.0095467661
D29: >6 | F29: ='Calibration record'!C16 -> 324 | H29: ='Calibration record'!B23 -> 1368160.9 | J29: ='Calibration record'!I23 -> 1388815.3 | K29: =J29-H29 -> 20654.476 | L29: ='Calibration record'!J23 -> 0.015096526
D30: >14 | F30: ='Calibration record'!D16 -> 1886 | H30: ='Calibration record'!B24 -> 97342.217 | J30: ='Calibration record'!I24 -> 98910 | K30: =J30-H30 -> 1567.7829 | L30: ='Calibration record'!J24 -> 0.016105888
D31: >21 | F31: ='Calibration record'!E16 -> 4122 | H31: ='Calibration record'!B25 -> 24221.303 | J31: ='Calibration record'!I25 -> 24523 | K31: =J31-H31 -> 301.69714 | L31: ='Calibration record'!J25 -> 0.012455859
D32: >25 | F32: ='Calibration record'!F16 -> 6566 | H32: ='Calibration record'!B26 -> 11396.58 | J32: ='Calibration record'!I26 -> 11296 | K32: =J32-H32 -> -100.58 | L32: ='Calibration record'!J26 -> -0.0088254547
D33: >38 | F33: ='Calibration record'!G16 -> 15500 | H33: ='Calibration record'!B27 -> 1788.6061 | J33: ='Calibration record'!I27 -> 1652 | K33: =J33-H33 -> -136.60611 | L33: ='Calibration record'!J27 -> -0.076375739
D34: >**50 | F34: ='Calibration record'!H16 -> 22008 | H34: ='Calibration record'!B28 -> 690.64989 | J34: ='Calibration record'!I28 -> 484.66667 | K34: - | L34: -
D35: >**70 | F35: ='Calibration record'!I16 -> 32390 | H35: ='Calibration record'!B29 -> 159.952 | J35: ='Calibration record'!I29 -> 59 | K35: - | L35: -
D36: **These particle sizes are not yet certified by NIST
D38: LS1 No Noise Threshold | E38: LS1 Threshold Sensitivity | G38: Sensitivity Threshold Ratio
D39: [mV] | E39: [mV] | G39: [-]
D40: ='Calibration record'!B9 -> 61 | E40: =F28-D40 -> 73 | G40: =F28/D40 -> 2.1967213
B72: CALIBRATION RESULT | D72: PASS | K72: PASS - VERIFIED
B74: RE-CALIBRATION DUE | D74: 1 YEAR FROM FIRST USE (refer to ICM diagnostics)
B76: CALIBRATED BY | D76: ='Calibration record'!H12 -> J Scarrott | K76: Position | L76: Calibration Lab Technician
