Workbook

Sheet Clause 6
A1: Clause 6 - Sizing Calibration - Initial Threshold Setting
D2: Reference Fluid Dilution Calculator | P2: Diluted | Q2: 0.89 | R2: Captured
A3: RM | B3: Partistan 34D Lot 34D | E3: Target Concentration | F3: =P3 -> 0.3 | P3: 0.3 | Q3: 50 | R3: ml
A4: Date | B4: 45988 | E4: Fluid Density | F4: 0.868 | L4: um(c) | M4: SRM2806D | N4: 34D | O4: RM USED | P4: Diluted | Q4: Counted
A5: Operator | B5: JMD | L5: 1.5 | M5: 67392.07 | O5: 67392.07 | P5: =O5*P$3 -> 20217.621 | Q5: =P5*Q$2*Q$3 -> 899684.13
A6: APC Model | B6: REF | E6: Bottle Number | F6: B0 | G6: B1 | H6: B2 | I6: B3 | L6: 2 | M6: 41165 | O6: 41165 | P6: =O6*P$3 -> 12349.5 | Q6: =P6*Q$2*Q$3 -> 549552.75
A7: APC S/N | B7: 11171-00001 | E7: Ref Fluid to Add / g | F7: =$F3*$F4*100 -> 26.04 | G7: =$F3*$F4*100 -> 26.04 | H7: =$F3*$F4*100 -> 26.04 | I7: =$F3*$F4*100 -> 26.04 | L7: 3 | M7: 17975.47 | N7: 17634.1 | O7: 17975.47 | P7: =O7*P$3 -> 5392.641 | Q7: =P7*Q$2*Q$3 -> 239972.52
A8: Sensor Model | B8: REF | E8: Ref Fluid Added / g | F8: 26.08 | G8: 26.08 | H8: 26.11 | I8: 26.16 | L8: 4 | M8: 10898.56 | N8: 10750.3 | O8: 10898.56 | P8: =O8*P$3 -> 3269.568 | Q8: =P8*Q$2*Q$3 -> 145495.78
A9: Sensor S/N | B9: 11171-00001 | E9: Diluent to add / g | F9: =(1/$F$3-1)*F8 -> 60.853333 | G9: =(1/$F$3-1)*G8 -> 60.853333 | H9: =(1/$F$3-1)*H8 -> 60.923333 | I9: =(1/$F$3-1)*I8 -> 61.04 | L9: 5 | M9: 6986.32 | N9: 7121.1 | O9: 6986.32 | P9: =O9*P$3 -> 2095.896 | Q9: =P9*Q$2*Q$3 -> 93267.372
A10: Bottle Sampler | B10: BS110-HP D2 BS2044 | E10: Diluent Added / g | F10: 61 | G10: 61.18 | H10: 61.2 | I10: 61.09 | L10: 6 | M10: 4679.65 | N10: 4729.1 | O10: 4679.65 | P10: =O10*P$3 -> 1403.895 | Q10: =P10*Q$2*Q$3 -> 62473.327
E11: Final Concentration | F11: =F8/(F8+F10) -> 0.29949472 | G11: =G8/(G8+G10) -> 0.29887692 | H11: =H8/(H8+H10) -> 0.29904936 | I11: =I8/(I8+I10) -> 0.29982808 | L11: 7 | M11: 3163.23 | N11: 3199.3 | O11: 3163.23 | P11: =O11*P$3 -> 948.969 | Q11: =P11*Q$2*Q$3 -> 42229.12
A12: Threshold Noise | B12: 110 | L12: 8 | M12: 2175.47 | N12: 2280.6 | O12: 2175.47 | P12: =O12*P$3 -> 652.641 | Q12: =P12*Q$2*Q$3 -> 29042.524
L13: 9 | M13: 1512.11 | N13: 1615 | O13: 1512.11 | P13: =O13*P$3 -> 453.633 | Q13: =P13*Q$2*Q$3 -> 20186.668
A14: Lowest threshold J | B14: =B12*1.5 -> 165 | L14: 10 | M14: 1079.78 | N14: 1130.5 | O14: 1079.78 | P14: =O14*P$3 -> 323.934 | Q14: =P14*Q$2*Q$3 -> 14415.063
A15: Highest threshold H | B15: 14000 | L15: 11 | M15: 786.62 | N15: 816.2 | O15: 786.62 | P15: =O15*P$3 -> 235.986 | Q15: =P15*Q$2*Q$3 -> 10501.377
A16: Threshold Factor K | B16: =10^((LOG(B15)-LOG(B14))/(30-1)) -> 1.1654804 | L16: 12 | M16: 586.06 | N16: 618.6 | O16: 586.06 | P16: =O16*P$3 -> 175.818 | Q16: =P16*Q$2*Q$3 -> 7823.901
L17: 13 | M17: 449.93 | N17: 481.9 | O17: 449.93 | P17: =O17*P$3 -> 134.979 | Q17: =P17*Q$2*Q$3 -> 6006.5655
A18: Threshold# | B18: Initial Value | C18: INT | D18: Reversed | L18: 14 | M18: 352.62 | N18: 384.7 | O18: 352.62 | P18: =O18*P$3 -> 105.786 | Q18: =P18*Q$2*Q$3 -> 4707.477
A19: 4 | B19: =B12*1.5 -> 165 | C19: =INT($B19+0.5) -> 165 | D19: =D20*B$16 -> 14000 | E19: 1.5x noise | L19: 15 | M19: 282.04 | N19: 314.6 | O19: 282.04 | P19: =O19*P$3 -> 84.612 | Q19: =P19*Q$2*Q$3 -> 3765.234
A20: 5 | B20: =B19*B$16 -> 192.30426 | C20: =INT($B20+0.5) -> 192 | D20: =D21*B$16 -> 12012.214 | L20: 16 | M20: 229.42 | N20: 261.8 | O20: 229.42 | P20: =O20*P$3 -> 68.826 | Q20: =P20*Q$2*Q$3 -> 3062.757
A21: 6 | B21: =B20*B$16 -> 224.12685 | C21: =INT($B21+0.5) -> 224 | D21: =D22*B$16 -> 10306.664 | L21: 17 | M21: 186.1 | N21: 221.2 | O21: 186.1 | P21: =O21*P$3 -> 55.83 | Q21: =P21*Q$2*Q$3 -> 2484.435
A22: 7 | B22: =B21*B$16 -> 261.21544 | C22: =INT($B22+0.5) -> 261 | D22: =D23*B$16 -> 8843.275 | L22: 18 | M22: 153.87 | N22: 188.7 | O22: 153.87 | P22: =O22*P$3 -> 46.161 | Q22: =P22*Q$2*Q$3 -> 2054.1645
A23: 8 | B23: =B22*B$16 -> 304.44148 | C23: =INT($B23+0.5) -> 304 | D23: =D24*B$16 -> 7587.6652 | L23: 19 | M23: 128.62 | N23: 161 | O23: 128.62 | P23: =O23*P$3 -> 38.586 | Q23: =P23*Q$2*Q$3 -> 1717.077
A24: 9 | B24: =B23*B$16 -> 354.82057 | C24: =INT($B24+0.5) -> 355 | D24: =D25*B$16 -> 6510.3328 | L24: 20 | M24: 107.35 | N24: 136.4 | O24: 107.35 | P24: =O24*P$3 -> 32.205 | Q24: =P24*Q$2*Q$3 -> 1433.1225
A25: 10 | B25: =B24*B$16 -> 413.53641 | C25: =INT($B25+0.5) -> 414 | D25: =D26*B$16 -> 5585.9652 | L25: 21 | M25: 88.64 | N25: 114.4 | O25: 88.64 | P25: =O25*P$3 -> 26.592 | Q25: =P25*Q$2*Q$3 -> 1183.344
A26: 11 | B26: =B25*B$16 -> 481.96858 | C26: =INT($B26+0.5) -> 482 | D26: =D27*B$16 -> 4792.8436 | L26: 22 | M26: 75.56 | N26: 95.3 | O26: 75.56 | P26: =O26*P$3 -> 22.668 | Q26: =P26*Q$2*Q$3 -> 1008.726
A27: 12 | B27: =B26*B$16 -> 561.72492 | C27: =INT($B27+0.5) -> 562 | D27: =D28*B$16 -> 4112.3331 | L27: 23 | M27: 61.94 | N27: 79 | O27: 61.94 | P27: =O27*P$3 -> 18.582 | Q27: =P27*Q$2*Q$3 -> 826.899
A28: 13 | B28: =B27*B$16 -> 654.67938 | C28: =INT($B28+0.5) -> 655 | D28: =D29*B$16 -> 3528.4447 | L28: 24 | M28: 50.86 | N28: 65.3 | O28: 50.86 | P28: =O28*P$3 -> 15.258 | Q28: =P28*Q$2*Q$3 -> 678.981
A29: 14 | B29: =B28*B$16 -> 763.01598 | C29: =INT($B29+0.5) -> 763 | D29: =D30*B$16 -> 3027.4595 | L29: 25 | M29: 41.61 | N29: 53.8 | O29: 41.61 | P29: =O29*P$3 -> 12.483 | Q29: =P29*Q$2*Q$3 -> 555.4935
A30: 15 | B30: =B29*B$16 -> 889.28015 | C30: =INT($B30+0.5) -> 889 | D30: =D31*B$16 -> 2597.6066 | L30: 26 | M30: 33.44 | N30: 44.6 | O30: 33.44 | P30: =O30*P$3 -> 10.032 | Q30: =P30*Q$2*Q$3 -> 446.424
A31: 16 | B31: =B30*B$16 -> 1036.4386 | C31: =INT($B31+0.5) -> 1036 | D31: =D32*B$16 -> 2228.7862 | L31: 27 | M31: 26.08 | N31: 37 | O31: 26.08 | P31: =O31*P$3 -> 7.824 | Q31: =P31*Q$2*Q$3 -> 348.168
... A34: 19 | B34: =B33*B$16 -> 1640.8107 | C34: =INT($B34+0.5) -> 1641 | D34: =D35*B$16 -> 1407.8407 | L34: 30 | M34: 13.94 | N34: 20.1 | O34: 13.94 | P34: =O34*P$3 -> 4.182 | Q34: =P34*Q$2*Q$3 -> 186.099
A35: 20 | B35: =B34*B$16 -> 1912.3327 | C35: =INT($B35+0.5) -> 1912 | D35: =D36*B$16 -> 1207.9488
A36: 21 | B36: =B35*B$16 -> 2228.7862 | C36: =INT($B36+0.5) -> 2229 | D36: =D37*B$16 -> 1036.4386
A37: 22 | B37: =B36*B$16 -> 2597.6066 | C37: =INT($B37+0.5) -> 2598 | D37: =D38*B$16 -> 889.28015
A38: 23 | B38: =B37*B$16 -> 3027.4595 | C38: =INT($B38+0.5) -> 3027 | D38: =D39*B$16 -> 763.01598
A39: 24 | B39: =B38*B$16 -> 3528.4447 | C39: =INT($B39+0.5) -> 3528 | D39: =D40*B$16 -> 654.67938
A40: 25 | B40: =B39*B$16 -> 4112.3331 | C40: =INT($B40+0.5) -> 4112 | D40: =D41*B$16 -> 561.72492
A41: 26 | B41: =B40*B$16 -> 4792.8436 | C41: =INT($B41+0.5) -> 4793 | D41: =D42*B$16 -> 481.96858
A42: 27 | B42: =B41*B$16 -> 5585.9652 | C42: =INT($B42+0.5) -> 5586 | D42: =D43*B$16 -> 413.53641
...

Sheet 6 - B1
A1: Data Preprocessing and Quality Assessment per ISO 11171 Clause 6.6
A2: BOTTLE 1 | H2: CHECK CALIBRATION THRESHOLDS ENTERED ON PARTICLE COUNTER
A3: Serial # | B3: 11171-00009 | D3: Dilution Ratio | E3: ='Clause 6'!$G$11 -> 0.29887692
A4: Date | B4: 45989
A5: RM | B5: 34D
A6: BOTTLE | B6: =RIGHT(CELL("filename"),1) -> 1
B7: Portion 1 | C7: Portion 2 | D7: Portion 3 | E7: Portion 4 | F7: Portion 5 | G7: X / ml | H7: NTOTAL | I7: CV | J7: DQMAX | K7: DQ | L7: X̅N | M7: NC
A8: Scanned ml | B8: =B52 -> 8.282699 | C8: =C52 -> 8.727867 | D8: =D52 -> 8.668422 | E8: =E52 -> 8.722132 | F8: =F52 -> 8.721622 | G8: =AVERAGE(B$8:F$8)*5 -> 43.122742
A9: count_4 | B9: =B53/B$8 -> 4082.3649 | C9: =C53/C$8 -> 4059.984 | D9: =D53/D$8 -> 4137.4312 | E9: =E53/E$8 -> 4038.5768 | F9: =F53/F$8 -> 4238.2025 | G9: =AVERAGE(B9:F9) -> 4111.3119 | H9: =G9*G$8 -> 177291.04 | I9: =STDEVP(B9:F9)/AVERAGE(B9:F9) -> 0.017385962 | J9: =IF(H9>$A$43, $C$43, IF(H9>$A$44, $C$44, IF(H9>$A$45,$C$45,IF(H9>$A$46,$C$46, IF(H9>$A$47,$C$47,IF(H9>$A$48,$C$48,$C$49))))))/100 -> 0.11 | K9: =(MAX(B9:F9)-MIN(B9:F9))/G9 -> 0.048555225 | L9: =G9/'Clause 6'!$G$11 -> 13755.869 | M9: =COUNTA(B9:F9) -> 5
A10: count_5 | B10: =B54/B$8 -> 3566.3496 | C10: =C54/C$8 -> 3548.7479 | D10: =D54/D$8 -> 3605.0391 | E10: =E54/E$8 -> 3518.5205 | F10: =F54/F$8 -> 3680.9667 | G10: =AVERAGE(B10:F10) -> 3583.9247 | H10: =G10*G$8 -> 154548.66 | I10: =STDEVP(B10:F10)/AVERAGE(B10:F10) -> 0.015628799 | J10: =IF(H10>$A$43, $C$43, IF(H10>$A$44, $C$44, IF(H10>$A$45,$C$45,IF(H10>$A$46,$C$46, IF(H10>$A$47,$C$47,IF(H10>$A$48,$C$48,$C$49))))))/100 -> 0.11 | K10: =(MAX(B10:F10)-MIN(B10:F10))/G10 -> 0.045326345 | L10: =G10/'Clause 6'!$G$11 -> 11991.306 | M10: =COUNTA(B10:F10) -> 5
A11: count_6 | B11: =B55/B$8 -> 3102.3704 | C11: =C55/C$8 -> 3091.5916 | D11: =D55/D$8 -> 3126.1745 | E11: =E55/E$8 -> 3046.8468 | F11: =F55/F$8 -> 3206.2843 | G11: =AVERAGE(B11:F11) -> 3114.6535 | H11: =G11*G$8 -> 134312.4 | I11: =STDEVP(B11:F11)/AVERAGE(B11:F11) -> 0.016873026 | J11: =IF(H11>$A$43, $C$43, IF(H11>$A$44, $C$44, IF(H11>$A$45,$C$45,IF(H11>$A$46,$C$46, IF(H11>$A$47,$C$47,IF(H11>$A$48,$C$48,$C$49))))))/100 -> 0.11 | K11: =(MAX(B11:F11)-MIN(B11:F11))/G11 -> 0.051189492 | L11: =G11/'Clause 6'!$G$11 -> 10421.191 | M11: =COUNTA(B11:F11) -> 5
A12: count_7 | B12: =B56/B$8 -> 2692.9628 | C12: =C56/C$8 -> 2685.4213 | D12: =D56/D$8 -> 2694.0313 | E12: =E56/E$8 -> 2648.6643 | F12: =F56/F$8 -> 2779.2995 | G12: =AVERAGE(B12:F12) -> 2700.0758 | H12: =G12*G$8 -> 116434.67 | I12: =STDEVP(B12:F12)/AVERAGE(B12:F12) -> 0.01590516 | J12: =IF(H12>$A$43, $C$43, IF(H12>$A$44, $C$44, IF(H12>$A$45,$C$45,IF(H12>$A$46,$C$46, IF(H12>$A$47,$C$47,IF(H12>$A$48,$C$48,$C$49))))))/100 -> 0.11 | K12: =(MAX(B12:F12)-MIN(B12:F12))/G12 -> 0.048382048 | L12: =G12/'Clause 6'!$G$11 -> 9034.0728 | M12: =COUNTA(B12:F12) -> 5
A13: count_8 | B13: =B57/B$8 -> 2317.602 | C13: =C57/C$8 -> 2304.6868 | D13: =D57/D$8 -> 2314.262 | E13: =E57/E$8 -> 2272.6095 | F13: =F57/F$8 -> 2402.5348 | G13: =AVERAGE(B13:F13) -> 2322.339 | H13: =G13*G$8 -> 100145.63 | I13: =STDEVP(B13:F13)/AVERAGE(B13:F13) -> 0.018574463 | J13: =IF(H13>$A$43, $C$43, IF(H13>$A$44, $C$44, IF(H13>$A$45,$C$45,IF(H13>$A$46,$C$46, IF(H13>$A$47,$C$47,IF(H13>$A$48,$C$48,$C$49))))))/100 -> 0.11 | K13: =(MAX(B13:F13)-MIN(B13:F13))/G13 -> 0.055945864 | L13: =G13/'Clause 6'!$G$11 -> 7770.2187 | M13: =COUNTA(B13:F13) -> 5
A14: count_9 | B14: =B58/B$8 -> 1977.737 | C14: =C58/C$8 -> 1973.5635 | D14: =D58/D$8 -> 1988.4819 | E14: =E58/E$8 -> 1947.1157 | F14: =F58/F$8 -> 2045.0324 | G14: =AVERAGE(B14:F14) -> 1986.3861 | H14: =G14*G$8 -> 85658.415 | I14: =STDEVP(B14:F14)/AVERAGE(B14:F14) -> 0.016274284 | J14: =IF(H14>$A$43, $C$43, IF(H14>$A$44, $C$44, IF(H14>$A$45,$C$45,IF(H14>$A$46,$C$46, IF(H14>$A$47,$C$47,IF(H14>$A$48,$C$48,$C$49))))))/100 -> 0.11 | K14: =(MAX(B14:F14)-MIN(B14:F14))/G14 -> 0.049293925 | L14: =G14/'Clause 6'!$G$11 -> 6646.1676 | M14: =COUNTA(B14:F14) -> 5
A15: count_10 | B15: =B59/B$8 -> 1676.2652 | C15: =C59/C$8 -> 1677.6149 | D15: =D59/D$8 -> 1685.3125 | E15: =E59/E$8 -> 1653.6095 | F15: =F59/F$8 -> 1737.6355 | G15: =AVERAGE(B15:F15) -> 1686.0875 | H15: =G15*G$8 -> 72708.717 | I15: =STDEVP(B15:F15)/AVERAGE(B15:F15) -> 0.016523426 | J15: =IF(H15>$A$43, $C$43, IF(H15>$A$44, $C$44, IF(H15>$A$45,$C$45,IF(H15>$A$46,$C$46, IF(H15>$A$47,$C$47,IF(H15>$A$48,$C$48,$C$49))))))/100 -> 0.11 | K15: =(MAX(B15:F15)-MIN(B15:F15))/G15 -> 0.049834921 | L15: =G15/'Clause 6'!$G$11 -> 5641.4109 | M15: =COUNTA(B15:F15) -> 5
A16: count_11 | B16: =B60/B$8 -> 1410.2891 | C16: =C60/C$8 -> 1415.5807 | D16: =D60/D$8 -> 1409.0223 | E16: =E60/E$8 -> 1387.6194 | F16: =F60/F$8 -> 1458.3297 | G16: =AVERAGE(B16:F16) -> 1416.1682 | H16: =G16*G$8 -> 61069.058 | I16: =STDEVP(B16:F16)/AVERAGE(B16:F16) -> 0.016343816 | J16: =IF(H16>$A$43, $C$43, IF(H16>$A$44, $C$44, IF(H16>$A$45,$C$45,IF(H16>$A$46,$C$46, IF(H16>$A$47,$C$47,IF(H16>$A$48,$C$48,$C$49))))))/100 -> 0.11 | K16: =(MAX(B16:F16)-MIN(B16:F16))/G16 -> 0.049930654 | L16: =G16/'Clause 6'!$G$11 -> 4738.2991 | M16: =COUNTA(B16:F16) -> 5
A17: count_12 | B17: =B61/B$8 -> 1168.339 | C17: =C61/C$8 -> 1165.3477 | D17: =D61/D$8 -> 1164.5718 | E17: =E61/E$8 -> 1151.4387 | F17: =F61/F$8 -> 1208.3761 | G17: =AVERAGE(B17:F17) -> 1171.6147 | H17: =G17*G$8 -> 50523.237 | I17: =STDEVP(B17:F17)/AVERAGE(B17:F17) -> 0.016453674 | J17: =IF(H17>$A$43, $C$43, IF(H17>$A$44, $C$44, IF(H17>$A$45,$C$45,IF(H17>$A$46,$C$46, IF(H17>$A$47,$C$47,IF(H17>$A$48,$C$48,$C$49))))))/100 -> 0.11 | K17: =(MAX(B17:F17)-MIN(B17:F17))/G17 -> 0.048597451 | L17: =G17/'Clause 6'!$G$11 -> 3920.0574 | M17: =COUNTA(B17:F17) -> 5
A18: count_13 | B18: =B62/B$8 -> 952.46731 | C18: =C62/C$8 -> 953.95587 | D18: =D62/D$8 -> 956.92157 | E18: =E62/E$8 -> 948.62128 | F18: =F62/F$8 -> 982.50073 | G18: =AVERAGE(B18:F18) -> 958.89335 | H18: =G18*G$8 -> 41350.111 | I18: =STDEVP(B18:F18)/AVERAGE(B18:F18) -> 0.012621596 | J18: =IF(H18>$A$43, $C$43, IF(H18>$A$44, $C$44, IF(H18>$A$45,$C$45,IF(H18>$A$46,$C$46, IF(H18>$A$47,$C$47,IF(H18>$A$48,$C$48,$C$49))))))/100 -> 0.11 | K18: =(MAX(B18:F18)-MIN(B18:F18))/G18 -> 0.035331828 | L18: =G18/'Clause 6'!$G$11 -> 3208.3219 | M18: =COUNTA(B18:F18) -> 5
A19: count_14 | B19: =B63/B$8 -> 767.98638 | C19: =C63/C$8 -> 766.39573 | D19: =D63/D$8 -> 774.30471 | E19: =E63/E$8 -> 767.70221 | F19: =F63/F$8 -> 788.04149 | G19: =AVERAGE(B19:F19) -> 772.8861 | H19: =G19*G$8 -> 33328.968 | I19: =STDEVP(B19:F19)/AVERAGE(B19:F19) -> 0.010426602 | J19: =IF(H19>$A$43, $C$43, IF(H19>$A$44, $C$44, IF(H19>$A$45,$C$45,IF(H19>$A$46,$C$46, IF(H19>$A$47,$C$47,IF(H19>$A$48,$C$48,$C$49))))))/100 -> 0.11 | K19: =(MAX(B19:F19)-MIN(B19:F19))/G19 -> 0.028006404 | L19: =G19/'Clause 6'!$G$11 -> 2585.9678 | M19: =COUNTA(B19:F19) -> 5
A20: count_15 | B20: =B64/B$8 -> 618.75966 | C20: =C64/C$8 -> 611.71876 | D20: =D64/D$8 -> 616.02908 | E20: =E64/E$8 -> 613.26749 | F20: =F64/F$8 -> 615.25253 | G20: =AVERAGE(B20:F20) -> 615.0055 | H20: =G20*G$8 -> 26520.724 | I20: =STDEVP(B20:F20)/AVERAGE(B20:F20) -> 0.0039176693 | J20: =IF(H20>$A$43, $C$43, IF(H20>$A$44, $C$44, IF(H20>$A$45,$C$45,IF(H20>$A$46,$C$46, IF(H20>$A$47,$C$47,IF(H20>$A$48,$C$48,$C$49))))))/100 -> 0.11 | K20: =(MAX(B20:F20)-MIN(B20:F20))/G20 -> 0.011448508 | L20: =G20/'Clause 6'!$G$11 -> 2057.7216 | M20: =COUNTA(B20:F20) -> 5
... A38: count_70 | B38: =B82/B$8 -> 4.2256757 | C38: =C82/C$8 -> 5.38505 | D38: =D82/D$8 -> 4.7298113 | E38: =E82/E$8 -> 4.356733 | F38: =F82/F$8 -> 3.0957544 | G38: =AVERAGE(B38:F38) -> 4.3586049 | H38: =G38*G$8 -> 187.95499 | I38: =STDEVP(B38:F38)/AVERAGE(B38:F38) -> 0.17180855 | J38: =IF(H38>$A$43, $C$43, IF(H38>$A$44, $C$44, IF(H38>$A$45,$C$45,IF(H38>$A$46,$C$46, IF(H38>$A$47,$C$47,IF(H38>$A$48,$C$48,$C$49))))))/100 -> 0.275 | K38: =(MAX(B38:F38)-MIN(B38:F38))/G38 -> 0.52523585 | L38: =G38/'Clause 6'!$G$11 -> 14.583277 | M38: =COUNTA(B38:F38) -> 5
A40: Table C.2
B41: Mean counted X | D41: CV_MAX
A42: X >= | B42: X < | C42: DQMAX / SAMPLE | D42: N=3 | E42: N=6 | F42: N=10 | G42: N=20 | H42: N=40
A43: 10000 | C43: 11 | D43: 7.8 | E43: 5.3 | F43: 4 | G43: 2.7 | H43: 1.8
A44: 5000 | B44: 10000 | C44: 11.3 | D44: 7.8 | E44: 5.3 | F44: 4 | G44: 2.7 | H44: 1.9
A45: 2000 | B45: 5000 | C45: 11.9 | D45: 7.9 | E45: 5.4 | F45: 4.1 | G45: 2.9 | H45: 2.1
A46: 1000 | B46: 2000 | C46: 13.4 | D46: 8 | E46: 5.6 | F46: 4.3 | G46: 3.1 | H46: 2.4
A47: 500 | B47: 1000 | C47: 15.6 | D47: 8.2 | E47: 5.9 | F47: 4.7 | G47: 3.6 | H47: 2.9
A48: 200 | B48: 500 | C48: 19.3 | D48: 8.9 | E48: 6.8 | F48: 5.7 | G48: 4.7 | H48: 4.1
A49: 100 | B49: 200 | C49: 27.5 | D49: 10 | E49: 8 | F49: 7 | G49: 6.1 | H49: 5.5
B51: Portion 1 | C51: Portion 2 | D51: Portion 3 | E51: Portion 4 | F51: Portion 5 | G51: Portion 1 | H51: Portion 2 | I51: Portion 3 | J51: Portion 4 | K51: Portion 5 | L51: Portion 1 | M51: Portion 2 | N51: Portion 3 | O51: Portion 4 | P51: Portion 5
A52: NAME\mL | B52: 8.282699 | C52: 8.727867 | D52: 8.668422 | E52: 8.722132 | F52: 8.721622 | G52: 8.282699 | H52: 8.727867 | I52: 8.668422 | J52: 8.722132 | K52: 8.721622 | L52: 8.282699 | M52: 8.727867 | N52: 8.668422 | O52: 8.722132 | P52: 8.721622
A53: 4 | B53: 33813 | C53: 35435 | D53: 35865 | E53: 35225 | F53: 36964 | G53: 33813 | H53: 35435 | I53: 35865 | J53: 35225 | K53: 36964 | L53: 33813 | M53: 35435 | N53: 35865 | O53: 35225 | P53: 36964
A54: 5 | B54: 29539 | C54: 30973 | D54: 31250 | E54: 30689 | F54: 32104 | G54: 29539 | H54: 30973 | I54: 31250 | J54: 30689 | K54: 32104 | L54: 29539 | M54: 30973 | N54: 31250 | O54: 30689 | P54: 32104
A55: 6 | B55: 25696 | C55: 26983 | D55: 27099 | E55: 26575 | F55: 27964 | G55: 25696 | H55: 26983 | I55: 27099 | J55: 26575 | K55: 27964 | L55: 25696 | M55: 26983 | N55: 27099 | O55: 26575 | P55: 27964
A56: 7 | B56: 22305 | C56: 23438 | D56: 23353 | E56: 23102 | F56: 24240 | G56: 22305 | H56: 23438 | I56: 23353 | J56: 23102 | K56: 24240 | L56: 22305 | M56: 23438 | N56: 23353 | O56: 23102 | P56: 24240
A57: 8 | B57: 19196 | C57: 20115 | D57: 20061 | E57: 19822 | F57: 20954 | G57: 19196 | H57: 20115 | I57: 20061 | J57: 19822 | K57: 20954 | L57: 19196 | M57: 20115 | N57: 20061 | O57: 19822 | P57: 20954
A58: 9 | B58: 16381 | C58: 17225 | D58: 17237 | E58: 16983 | F58: 17836 | G58: 16381 | H58: 17225 | I58: 17237 | J58: 16983 | K58: 17836 | L58: 16381 | M58: 17225 | N58: 17237 | O58: 16983 | P58: 17836
A59: 10 | B59: 13884 | C59: 14642 | D59: 14609 | E59: 14423 | F59: 15155 | G59: 13884 | H59: 14642 | I59: 14609 | J59: 14423 | K59: 15155 | L59: 13884 | M59: 14642 | N59: 14609 | O59: 14423 | P59: 15155
...

Sheet 6 - B2
A1: ='6 - B1'!$A$1 -> Data Preprocessing and Quality Assessment per ISO 11171 Clause 6.6
A2: BOTTLE 2
A3: ='6 - B1'!$A$3 -> Serial # | B3: ='6 - B1'!$B$3 -> 11171-00009
A4: ='6 - B1'!$A$4 -> Date | B4: ='6 - B1'!$B$4 -> 45989
A5: ='6 - B1'!$A$5 -> RM | B5: ='6 - B1'!$B$5 -> 34D
B7: Portion 1 | C7: Portion 2 | D7: Portion 3 | E7: Portion 4 | F7: Portion 5 | G7: X / ml | H7: NTOTAL | I7: CV | J7: DQMAX | K7: DQ | L7: X̅N | M7: NC
A8: Scanned ml | B8: =G52 -> 8.282699 | C8: =H52 -> 8.727867 | D8: =I52 -> 8.668422 | E8: =J52 -> 8.722132 | F8: =K52 -> 8.721622 | G8: =AVERAGE(B$8:F$8)*5 -> 43.122742
A9: count_4 | B9: =G53/B$8 -> 4082.3649 | C9: =H53/C$8 -> 4059.984 | D9: =I53/D$8 -> 4137.4312 | E9: =J53/E$8 -> 4038.5768 | F9: =K53/F$8 -> 4238.2025 | G9: =AVERAGE(B9:F9) -> 4111.3119 | H9: =G9*G$8 -> 177291.04 | I9: =STDEVP(B9:F9)/AVERAGE(B9:F9) -> 0.017385962 | J9: =IF(H9>$A$43, $C$43, IF(H9>$A$44, $C$44, IF(H9>$A$45,$C$45,IF(H9>$A$46,$C$46, IF(H9>$A$47,$C$47,IF(H9>$A$48,$C$48,$C$49))))))/100 -> 0.11 | K9: =(MAX(B9:F9)-MIN(B9:F9))/G9 -> 0.048555225 | L9: =G9/'Clause 6'!$H$11 -> 13747.937 | M9: =COUNTA(B9:F9) -> 5
A10: count_5 | B10: =G54/B$8 -> 3566.3496 | C10: =H54/C$8 -> 3548.7479 | D10: =I54/D$8 -> 3605.0391 | E10: =J54/E$8 -> 3518.5205 | F10: =K54/F$8 -> 3680.9667 | G10: =AVERAGE(B10:F10) -> 3583.9247 | H10: =G10*G$8 -> 154548.66 | I10: =STDEVP(B10:F10)/AVERAGE(B10:F10) -> 0.015628799 | J10: =IF(H10>$A$43, $C$43, IF(H10>$A$44, $C$44, IF(H10>$A$45,$C$45,IF(H10>$A$46,$C$46, IF(H10>$A$47,$C$47,IF(H10>$A$48,$C$48,$C$49))))))/100 -> 0.11 | K10: =(MAX(B10:F10)-MIN(B10:F10))/G10 -> 0.045326345 | L10: =G10/'Clause 6'!$H$11 -> 11984.392 | M10: =COUNTA(B10:F10) -> 5
A11: count_6 | B11: =G55/B$8 -> 3102.3704 | C11: =H55/C$8 -> 3091.5916 | D11: =I55/D$8 -> 3126.1745 | E11: =J55/E$8 -> 3046.8468 | F11: =K55/F$8 -> 3206.2843 | G11: =AVERAGE(B11:F11) -> 3114.6535 | H11: =G11*G$8 -> 134312.4 | I11: =STDEVP(B11:F11)/AVERAGE(B11:F11) -> 0.016873026 | J11: =IF(H11>$A$43, $C$43, IF(H11>$A$44, $C$44, IF(H11>$A$45,$C$45,IF(H11>$A$46,$C$46, IF(H11>$A$47,$C$47,IF(H11>$A$48,$C$48,$C$49))))))/100 -> 0.11 | K11: =(MAX(B11:F11)-MIN(B11:F11))/G11 -> 0.051189492 | L11: =G11/'Clause 6'!$H$11 -> 10415.182 | M11: =COUNTA(B11:F11) -> 5
A12: count_7 | B12: =G56/B$8 -> 2692.9628 | C12: =H56/C$8 -> 2685.4213 | D12: =I56/D$8 -> 2694.0313 | E12: =J56/E$8 -> 2648.6643 | F12: =K56/F$8 -> 2779.2995 | G12: =AVERAGE(B12:F12) -> 2700.0758 | H12: =G12*G$8 -> 116434.67 | I12: =STDEVP(B12:F12)/AVERAGE(B12:F12) -> 0.01590516 | J12: =IF(H12>$A$43, $C$43, IF(H12>$A$44, $C$44, IF(H12>$A$45,$C$45,IF(H12>$A$46,$C$46, IF(H12>$A$47,$C$47,IF(H12>$A$48,$C$48,$C$49))))))/100 -> 0.11 | K12: =(MAX(B12:F12)-MIN(B12:F12))/G12 -> 0.048382048 | L12: =G12/'Clause 6'!$H$11 -> 9028.8634 | M12: =COUNTA(B12:F12) -> 5
A13: count_8 | B13: =G57/B$8 -> 2317.602 | C13: =H57/C$8 -> 2304.6868 | D13: =I57/D$8 -> 2314.262 | E13: =J57/E$8 -> 2272.6095 | F13: =K57/F$8 -> 2402.5348 | G13: =AVERAGE(B13:F13) -> 2322.339 | H13: =G13*G$8 -> 100145.63 | I13: =STDEVP(B13:F13)/AVERAGE(B13:F13) -> 0.018574463 | J13: =IF(H13>$A$43, $C$43, IF(H13>$A$44, $C$44, IF(H13>$A$45,$C$45,IF(H13>$A$46,$C$46, IF(H13>$A$47,$C$47,IF(H13>$A$48,$C$48,$C$49))))))/100 -> 0.11 | K13: =(MAX(B13:F13)-MIN(B13:F13))/G13 -> 0.055945864 | L13: =G13/'Clause 6'!$H$11 -> 7765.7381 | M13: =COUNTA(B13:F13) -> 5
A14: count_9 | B14: =G58/B$8 -> 1977.737 | C14: =H58/C$8 -> 1973.5635 | D14: =I58/D$8 -> 1988.4819 | E14: =J58/E$8 -> 1947.1157 | F14: =K58/F$8 -> 2045.0324 | G14: =AVERAGE(B14:F14) -> 1986.3861 | H14: =G14*G$8 -> 85658.415 | I14: =STDEVP(B14:F14)/AVERAGE(B14:F14) -> 0.016274284 | J14: =IF(H14>$A$43, $C$43, IF(H14>$A$44, $C$44, IF(H14>$A$45,$C$45,IF(H14>$A$46,$C$46, IF(H14>$A$47,$C$47,IF(H14>$A$48,$C$48,$C$49))))))/100 -> 0.11 | K14: =(MAX(B14:F14)-MIN(B14:F14))/G14 -> 0.049293925 | L14: =G14/'Clause 6'!$H$11 -> 6642.3351 | M14: =COUNTA(B14:F14) -> 5
A15: count_10 | B15: =G59/B$8 -> 1676.2652 | C15: =H59/C$8 -> 1677.6149 | D15: =I59/D$8 -> 1685.3125 | E15: =J59/E$8 -> 1653.6095 | F15: =K59/F$8 -> 1737.6355 | G15: =AVERAGE(B15:F15) -> 1686.0875 | H15: =G15*G$8 -> 72708.717 | I15: =STDEVP(B15:F15)/AVERAGE(B15:F15) -> 0.016523426 | J15: =IF(H15>$A$43, $C$43, IF(H15>$A$44, $C$44, IF(H15>$A$45,$C$45,IF(H15>$A$46,$C$46, IF(H15>$A$47,$C$47,IF(H15>$A$48,$C$48,$C$49))))))/100 -> 0.11 | K15: =(MAX(B15:F15)-MIN(B15:F15))/G15 -> 0.049834921 | L15: =G15/'Clause 6'!$H$11 -> 5638.1578 | M15: =COUNTA(B15:F15) -> 5
A16: count_11 | B16: =G60/B$8 -> 1410.2891 | C16: =H60/C$8 -> 1415.5807 | D16: =I60/D$8 -> 1409.0223 | E16: =J60/E$8 -> 1387.6194 | F16: =K60/F$8 -> 1458.3297 | G16: =AVERAGE(B16:F16) -> 1416.1682 | H16: =G16*G$8 -> 61069.058 | I16: =STDEVP(B16:F16)/AVERAGE(B16:F16) -> 0.016343816 | J16: =IF(H16>$A$43, $C$43, IF(H16>$A$44, $C$44, IF(H16>$A$45,$C$45,IF(H16>$A$46,$C$46, IF(H16>$A$47,$C$47,IF(H16>$A$48,$C$48,$C$49))))))/100 -> 0.11 | K16: =(MAX(B16:F16)-MIN(B16:F16))/G16 -> 0.049930654 | L16: =G16/'Clause 6'!$H$11 -> 4735.5668 | M16: =COUNTA(B16:F16) -> 5
A17: count_12 | B17: =G61/B$8 -> 1168.339 | C17: =H61/C$8 -> 1165.3477 | D17: =I61/D$8 -> 1164.5718 | E17: =J61/E$8 -> 1151.4387 | F17: =K61/F$8 -> 1208.3761 | G17: =AVERAGE(B17:F17) -> 1171.6147 | H17: =G17*G$8 -> 50523.237 | I17: =STDEVP(B17:F17)/AVERAGE(B17:F17) -> 0.016453674 | J17: =IF(H17>$A$43, $C$43, IF(H17>$A$44, $C$44, IF(H17>$A$45,$C$45,IF(H17>$A$46,$C$46, IF(H17>$A$47,$C$47,IF(H17>$A$48,$C$48,$C$49))))))/100 -> 0.11 | K17: =(MAX(B17:F17)-MIN(B17:F17))/G17 -> 0.048597451 | L17: =G17/'Clause 6'!$H$11 -> 3917.7969 | M17: =COUNTA(B17:F17) -> 5
A18: count_13 | B18: =G62/B$8 -> 952.46731 | C18: =H62/C$8 -> 953.95587 | D18: =I62/D$8 -> 956.92157 | E18: =J62/E$8 -> 948.62128 | F18: =K62/F$8 -> 982.50073 | G18: =AVERAGE(B18:F18) -> 958.89335 | H18: =G18*G$8 -> 41350.111 | I18: =STDEVP(B18:F18)/AVERAGE(B18:F18) -> 0.012621596 | J18: =IF(H18>$A$43, $C$43, IF(H18>$A$44, $C$44, IF(H18>$A$45,$C$45,IF(H18>$A$46,$C$46, IF(H18>$A$47,$C$47,IF(H18>$A$48,$C$48,$C$49))))))/100 -> 0.11 | K18: =(MAX(B18:F18)-MIN(B18:F18))/G18 -> 0.035331828 | L18: =G18/'Clause 6'!$H$11 -> 3206.4718 | M18: =COUNTA(B18:F18) -> 5
A19: count_14 | B19: =G63/B$8 -> 767.98638 | C19: =H63/C$8 -> 766.39573 | D19: =I63/D$8 -> 774.30471 | E19: =J63/E$8 -> 767.70221 | F19: =K63/F$8 -> 788.04149 | G19: =AVERAGE(B19:F19) -> 772.8861 | H19: =G19*G$8 -> 33328.968 | I19: =STDEVP(B19:F19)/AVERAGE(B19:F19) -> 0.010426602 | J19: =IF(H19>$A$43, $C$43, IF(H19>$A$44, $C$44, IF(H19>$A$45,$C$45,IF(H19>$A$46,$C$46, IF(H19>$A$47,$C$47,IF(H19>$A$48,$C$48,$C$49))))))/100 -> 0.11 | K19: =(MAX(B19:F19)-MIN(B19:F19))/G19 -> 0.028006404 | L19: =G19/'Clause 6'!$H$11 -> 2584.4767 | M19: =COUNTA(B19:F19) -> 5
A20: count_15 | B20: =G64/B$8 -> 618.75966 | C20: =H64/C$8 -> 611.71876 | D20: =I64/D$8 -> 616.02908 | E20: =J64/E$8 -> 613.26749 | F20: =K64/F$8 -> 615.25253 | G20: =AVERAGE(B20:F20) -> 615.0055 | H20: =G20*G$8 -> 26520.724 | I20: =STDEVP(B20:F20)/AVERAGE(B20:F20) -> 0.0039176693 | J20: =IF(H20>$A$43, $C$43, IF(H20>$A$44, $C$44, IF(H20>$A$45,$C$45,IF(H20>$A$46,$C$46, IF(H20>$A$47,$C$47,IF(H20>$A$48,$C$48,$C$49))))))/100 -> 0.11 | K20: =(MAX(B20:F20)-MIN(B20:F20))/G20 -> 0.011448508 | L20: =G20/'Clause 6'!$H$11 -> 2056.5351 | M20: =COUNTA(B20:F20) -> 5
... A38: count_70 | B38: =G82/B$8 -> 4.2256757 | C38: =H82/C$8 -> 5.38505 | D38: =I82/D$8 -> 4.7298113 | E38: =J82/E$8 -> 4.356733 | F38: =K82/F$8 -> 3.0957544 | G38: =AVERAGE(B38:F38) -> 4.3586049 | H38: =G38*G$8 -> 187.95499 | I38: =STDEVP(B38:F38)/AVERAGE(B38:F38) -> 0.17180855 | J38: =IF(H38>$A$43, $C$43, IF(H38>$A$44, $C$44, IF(H38>$A$45,$C$45,IF(H38>$A$46,$C$46, IF(H38>$A$47,$C$47,IF(H38>$A$48,$C$48,$C$49))))))/100 -> 0.275 | K38: =(MAX(B38:F38)-MIN(B38:F38))/G38 -> 0.52523585 | L38: =G38/'Clause 6'!$H$11 -> 14.574868 | M38: =COUNTA(B38:F38) -> 5
A40: Table C.2
B41: Mean counted X | D41: CV_MAX
A42: X >= | B42: X < | C42: DQMAX / SAMPLE | D42: N=3 | E42: N=6 | F42: N=10 | G42: N=20 | H42: N=40
A43: 10000 | C43: 11 | D43: 7.8 | E43: 5.3 | F43: 4 | G43: 2.7 | H43: 1.8
A44: 5000 | B44: 10000 | C44: 11.3 | D44: 7.8 | E44: 5.3 | F44: 4 | G44: 2.7 | H44: 1.9
A45: 2000 | B45: 5000 | C45: 11.9 | D45: 7.9 | E45: 5.4 | F45: 4.1 | G45: 2.9 | H45: 2.1
A46: 1000 | B46: 2000 | C46: 13.4 | D46: 8 | E46: 5.6 | F46: 4.3 | G46: 3.1 | H46: 2.4
A47: 500 | B47: 1000 | C47: 15.6 | D47: 8.2 | E47: 5.9 | F47: 4.7 | G47: 3.6 | H47: 2.9
A48: 200 | B48: 500 | C48: 19.3 | D48: 8.9 | E48: 6.8 | F48: 5.7 | G48: 4.7 | H48: 4.1
A49: 100 | B49: 200 | C49: 27.5 | D49: 10 | E49: 8 | F49: 7 | G49: 6.1 | H49: 5.5
A51: ='6 - B1'!A51 -> 0 | B51: ='6 - B1'!B51 -> Portion 1 | C51: ='6 - B1'!C51 -> Portion 2 | D51: ='6 - B1'!D51 -> Portion 3 | E51: ='6 - B1'!E51 -> Portion 4 | F51: ='6 - B1'!F51 -> Portion 5 | G51: ='6 - B1'!G51 -> Portion 1 | H51: ='6 - B1'!H51 -> Portion 2 | ... P51: ='6 - B1'!P51 -> Portion 5
A52: ='6 - B1'!A52 -> NAME\mL | B52: ='6 - B1'!B52 -> 8.282699 | C52: ='6 - B1'!C52 -> 8.727867 | D52: ='6 - B1'!D52 -> 8.668422 | E52: ='6 - B1'!E52 -> 8.722132 | F52: ='6 - B1'!F52 -> 8.721622 | G52: ='6 - B1'!G52 -> 8.282699 | H52: ='6 - B1'!H52 -> 8.727867 | ... P52: ='6 - B1'!P52 -> 8.721622
A53: ='6 - B1'!A53 -> 4 | B53: ='6 - B1'!B53 -> 33813 | C53: ='6 - B1'!C53 -> 35435 | D53: ='6 - B1'!D53 -> 35865 | E53: ='6 - B1'!E53 -> 35225 | F53: ='6 - B1'!F53 -> 36964 | G53: ='6 - B1'!G53 -> 33813 | H53: ='6 - B1'!H53 -> 35435 | ... P53: ='6 - B1'!P53 -> 36964
A54: ='6 - B1'!A54 -> 5 | B54: ='6 - B1'!B54 -> 29539 | C54: ='6 - B1'!C54 -> 30973 | D54: ='6 - B1'!D54 -> 31250 | E54: ='6 - B1'!E54 -> 30689 | F54: ='6 - B1'!F54 -> 32104 | G54: ='6 - B1'!G54 -> 29539 | H54: ='6 - B1'!H54 -> 30973 | ... P54: ='6 - B1'!P54 -> 32104
A55: ='6 - B1'!A55 -> 6 | B55: ='6 - B1'!B55 -> 25696 | C55: ='6 - B1'!C55 -> 26983 | D55: ='6 - B1'!D55 -> 27099 | E55: ='6 - B1'!E55 -> 26575 | F55: ='6 - B1'!F55 -> 27964 | G55: ='6 - B1'!G55 -> 25696 | H55: ='6 - B1'!H55 -> 26983 | ... P55: ='6 - B1'!P55 -> 27964
A56: ='6 - B1'!A56 -> 7 | B56: ='6 - B1'!B56 -> 22305 | C56: ='6 - B1'!C56 -> 23438 | D56: ='6 - B1'!D56 -> 23353 | E56: ='6 - B1'!E56 -> 23102 | F56: ='6 - B1'!F56 -> 24240 | G56: ='6 - B1'!G56 -> 22305 | H56: ='6 - B1'!H56 -> 23438 | ... P56: ='6 - B1'!P56 -> 24240
A57: ='6 - B1'!A57 -> 8 | B57: ='6 - B1'!B57 -> 19196 | C57: ='6 - B1'!C57 -> 20115 | D57: ='6 - B1'!D57 -> 20061 | E57: ='6 - B1'!E57 -> 19822 | F57: ='6 - B1'!F57 -> 20954 | G57: ='6 - B1'!G57 -> 19196 | H57: ='6 - B1'!H57 -> 20115 | ... P57: ='6 - B1'!P57 -> 20954
A58: ='6 - B1'!A58 -> 9 | B58: ='6 - B1'!B58 -> 16381 | C58: ='6 - B1'!C58 -> 17225 | D58: ='6 - B1'!D58 -> 17237 | E58: ='6 - B1'!E58 -> 16983 | F58: ='6 - B1'!F58 -> 17836 | G58: ='6 - B1'!G58 -> 16381 | H58: ='6 - B1'!H58 -> 17225 | ... P58: ='6 - B1'!P58 -> 17836
A59: ='6 - B1'!A59 -> 10 | B59: ='6 - B1'!B59 -> 13884 | C59: ='6 - B1'!C59 -> 14642 | D59: ='6 - B1'!D59 -> 14609 | E59: ='6 - B1'!E59 -> 14423 | F59: ='6 - B1'!F59 -> 15155 | G59: ='6 - B1'!G59 -> 13884 | H59: ='6 - B1'!H59 -> 14642 | ... P59: ='6 - B1'!P59 -> 15155
A60: ='6 - B1'!A60 -> 11 | B60: ='6 - B1'!B60 -> 11681 | C60: ='6 - B1'!C60 -> 12355 | D60: ='6 - B1'!D60 -> 12214 | E60: ='6 - B1'!E60 -> 12103 | F60: ='6 - B1'!F60 -> 12719 | G60: ='6 - B1'!G60 -> 11681 | H60: ='6 - B1'!H60 -> 12355 | ... P60: ='6 - B1'!P60 -> 12719
...

Sheet 6 - B3
A1: ='6 - B1'!$A$1 -> Data Preprocessing and Quality Assessment per ISO 11171 Clause 6.6
A2: BOTTLE 3
A3: ='6 - B1'!$A$3 -> Serial # | B3: ='6 - B1'!$B$3 -> 11171-00009
A4: ='6 - B1'!$A$4 -> Date | B4: ='6 - B1'!$B$4 -> 45989
A5: ='6 - B1'!$A$5 -> RM | B5: ='6 - B1'!$B$5 -> 34D
B7: Portion 1 | C7: Portion 2 | D7: Portion 3 | E7: Portion 4 | F7: Portion 5 | G7: X / ml | H7: NTOTAL | I7: CV | J7: DQMAX | K7: DQ | L7: X̅N | M7: NC
A8: Scanned ml | B8: =L52 -> 8.282699 | C8: =M52 -> 8.727867 | D8: =N52 -> 8.668422 | E8: =O52 -> 8.722132 | F8: =P52 -> 8.721622 | G8: =AVERAGE(B$8:F$8)*5 -> 43.122742
A9: count_4 | B9: =L53/B$8 -> 4082.3649 | C9: =M53/C$8 -> 4059.984 | D9: =N53/D$8 -> 4137.4312 | E9: =O53/E$8 -> 4038.5768 | F9: =P53/F$8 -> 4238.2025 | G9: =AVERAGE(B9:F9) -> 4111.3119 | H9: =G9*G$8 -> 177291.04 | I9: =STDEVP(B9:F9)/G9 -> 0.017385962 | J9: =IF(H9>$A$43, $C$43, IF(H9>$A$44, $C$44, IF(H9>$A$45,$C$45,IF(H9>$A$46,$C$46, IF(H9>$A$47,$C$47,IF(H9>$A$48,$C$48,$C$49))))))/100 -> 0.11 | K9: =(MAX(B9:F9)-MIN(B9:F9))/G9 -> 0.048555225 | L9: =G9/'Clause 6'!$I$11 -> 13712.231 | M9: =COUNTA(B9:F9) -> 5
A10: count_5 | B10: =L54/B$8 -> 3566.3496 | C10: =M54/C$8 -> 3548.7479 | D10: =N54/D$8 -> 3605.0391 | E10: =O54/E$8 -> 3518.5205 | F10: =P54/F$8 -> 3680.9667 | G10: =AVERAGE(B10:F10) -> 3583.9247 | H10: =G10*G$8 -> 154548.66 | I10: =STDEVP(B10:F10)/G10 -> 0.015628799 | J10: =IF(H10>$A$43, $C$43, IF(H10>$A$44, $C$44, IF(H10>$A$45,$C$45,IF(H10>$A$46,$C$46, IF(H10>$A$47,$C$47,IF(H10>$A$48,$C$48,$C$49))))))/100 -> 0.11 | K10: =(MAX(B10:F10)-MIN(B10:F10))/G10 -> 0.045326345 | L10: =G10/'Clause 6'!$I$11 -> 11953.266 | M10: =COUNTA(B10:F10) -> 5
A11: count_6 | B11: =L55/B$8 -> 3102.3704 | C11: =M55/C$8 -> 3091.5916 | D11: =N55/D$8 -> 3126.1745 | E11: =O55/E$8 -> 3046.8468 | F11: =P55/F$8 -> 3206.2843 | G11: =AVERAGE(B11:F11) -> 3114.6535 | H11: =G11*G$8 -> 134312.4 | I11: =STDEVP(B11:F11)/G11 -> 0.016873026 | J11: =IF(H11>$A$43, $C$43, IF(H11>$A$44, $C$44, IF(H11>$A$45,$C$45,IF(H11>$A$46,$C$46, IF(H11>$A$47,$C$47,IF(H11>$A$48,$C$48,$C$49))))))/100 -> 0.11 | K11: =(MAX(B11:F11)-MIN(B11:F11))/G11 -> 0.051189492 | L11: =G11/'Clause 6'!$I$11 -> 10388.131 | M11: =COUNTA(B11:F11) -> 5
A12: count_7 | B12: =L56/B$8 -> 2692.9628 | C12: =M56/C$8 -> 2685.4213 | D12: =N56/D$8 -> 2694.0313 | E12: =O56/E$8 -> 2648.6643 | F12: =P56/F$8 -> 2779.2995 | G12: =AVERAGE(B12:F12) -> 2700.0758 | H12: =G12*G$8 -> 116434.67 | I12: =STDEVP(B12:F12)/G12 -> 0.01590516 | J12: =IF(H12>$A$43, $C$43, IF(H12>$A$44, $C$44, IF(H12>$A$45,$C$45,IF(H12>$A$46,$C$46, IF(H12>$A$47,$C$47,IF(H12>$A$48,$C$48,$C$49))))))/100 -> 0.11 | K12: =(MAX(B12:F12)-MIN(B12:F12))/G12 -> 0.048382048 | L12: =G12/'Clause 6'!$I$11 -> 9005.4135 | M12: =COUNTA(B12:F12) -> 5
A13: count_8 | B13: =L57/B$8 -> 2317.602 | C13: =M57/C$8 -> 2304.6868 | D13: =N57/D$8 -> 2314.262 | E13: =O57/E$8 -> 2272.6095 | F13: =P57/F$8 -> 2402.5348 | G13: =AVERAGE(B13:F13) -> 2322.339 | H13: =G13*G$8 -> 100145.63 | I13: =STDEVP(B13:F13)/G13 -> 0.018574463 | J13: =IF(H13>$A$43, $C$43, IF(H13>$A$44, $C$44, IF(H13>$A$45,$C$45,IF(H13>$A$46,$C$46, IF(H13>$A$47,$C$47,IF(H13>$A$48,$C$48,$C$49))))))/100 -> 0.11 | K13: =(MAX(B13:F13)-MIN(B13:F13))/G13 -> 0.055945864 | L13: =G13/'Clause 6'!$I$11 -> 7745.5688 | M13: =COUNTA(B13:F13) -> 5
A14: count_9 | B14: =L58/B$8 -> 1977.737 | C14: =M58/C$8 -> 1973.5635 | D14: =N58/D$8 -> 1988.4819 | E14: =O58/E$8 -> 1947.1157 | F14: =P58/F$8 -> 2045.0324 | G14: =AVERAGE(B14:F14) -> 1986.3861 | H14: =G14*G$8 -> 85658.415 | I14: =STDEVP(B14:F14)/G14 -> 0.016274284 | J14: =IF(H14>$A$43, $C$43, IF(H14>$A$44, $C$44, IF(H14>$A$45,$C$45,IF(H14>$A$46,$C$46, IF(H14>$A$47,$C$47,IF(H14>$A$48,$C$48,$C$49))))))/100 -> 0.11 | K14: =(MAX(B14:F14)-MIN(B14:F14))/G14 -> 0.049293925 | L14: =G14/'Clause 6'!$I$11 -> 6625.0836 | M14: =COUNTA(B14:F14) -> 5
A15: count_10 | B15: =L59/B$8 -> 1676.2652 | C15: =M59/C$8 -> 1677.6149 | D15: =N59/D$8 -> 1685.3125 | E15: =O59/E$8 -> 1653.6095 | F15: =P59/F$8 -> 1737.6355 | G15: =AVERAGE(B15:F15) -> 1686.0875 | H15: =G15*G$8 -> 72708.717 | I15: =STDEVP(B15:F15)/G15 -> 0.016523426 | J15: =IF(H15>$A$43, $C$43, IF(H15>$A$44, $C$44, IF(H15>$A$45,$C$45,IF(H15>$A$46,$C$46, IF(H15>$A$47,$C$47,IF(H15>$A$48,$C$48,$C$49))))))/100 -> 0.11 | K15: =(MAX(B15:F15)-MIN(B15:F15))/G15 -> 0.049834921 | L15: =G15/'Clause 6'!$I$11 -> 5623.5144 | M15: =COUNTA(B15:F15) -> 5
A16: count_11 | B16: =L60/B$8 -> 1410.2891 | C16: =M60/C$8 -> 1415.5807 | D16: =N60/D$8 -> 1409.0223 | E16: =O60/E$8 -> 1387.6194 | F16: =P60/F$8 -> 1458.3297 | G16: =AVERAGE(B16:F16) -> 1416.1682 | H16: =G16*G$8 -> 61069.058 | I16: =STDEVP(B16:F16)/G16 -> 0.016343816 | J16: =IF(H16>$A$43, $C$43, IF(H16>$A$44, $C$44, IF(H16>$A$45,$C$45,IF(H16>$A$46,$C$46, IF(H16>$A$47,$C$47,IF(H16>$A$48,$C$48,$C$49))))))/100 -> 0.11 | K16: =(MAX(B16:F16)-MIN(B16:F16))/G16 -> 0.049930654 | L16: =G16/'Clause 6'!$I$11 -> 4723.2675 | M16: =COUNTA(B16:F16) -> 5
A17: count_12 | B17: =L61/B$8 -> 1168.339 | C17: =M61/C$8 -> 1165.3477 | D17: =N61/D$8 -> 1164.5718 | E17: =O61/E$8 -> 1151.4387 | F17: =P61/F$8 -> 1208.3761 | G17: =AVERAGE(B17:F17) -> 1171.6147 | H17: =G17*G$8 -> 50523.237 | I17: =STDEVP(B17:F17)/G17 -> 0.016453674 | J17: =IF(H17>$A$43, $C$43, IF(H17>$A$44, $C$44, IF(H17>$A$45,$C$45,IF(H17>$A$46,$C$46, IF(H17>$A$47,$C$47,IF(H17>$A$48,$C$48,$C$49))))))/100 -> 0.11 | K17: =(MAX(B17:F17)-MIN(B17:F17))/G17 -> 0.048597451 | L17: =G17/'Clause 6'!$I$11 -> 3907.6215 | M17: =COUNTA(B17:F17) -> 5
A18: count_13 | B18: =L62/B$8 -> 952.46731 | C18: =M62/C$8 -> 953.95587 | D18: =N62/D$8 -> 956.92157 | E18: =O62/E$8 -> 948.62128 | F18: =P62/F$8 -> 982.50073 | G18: =AVERAGE(B18:F18) -> 958.89335 | H18: =G18*G$8 -> 41350.111 | I18: =STDEVP(B18:F18)/G18 -> 0.012621596 | J18: =IF(H18>$A$43, $C$43, IF(H18>$A$44, $C$44, IF(H18>$A$45,$C$45,IF(H18>$A$46,$C$46, IF(H18>$A$47,$C$47,IF(H18>$A$48,$C$48,$C$49))))))/100 -> 0.11 | K18: =(MAX(B18:F18)-MIN(B18:F18))/G18 -> 0.035331828 | L18: =G18/'Clause 6'!$I$11 -> 3198.1439 | M18: =COUNTA(B18:F18) -> 5
A19: count_14 | B19: =L63/B$8 -> 767.98638 | C19: =M63/C$8 -> 766.39573 | D19: =N63/D$8 -> 774.30471 | E19: =O63/E$8 -> 767.70221 | F19: =P63/F$8 -> 788.04149 | G19: =AVERAGE(B19:F19) -> 772.8861 | H19: =G19*G$8 -> 33328.968 | I19: =STDEVP(B19:F19)/G19 -> 0.010426602 | J19: =IF(H19>$A$43, $C$43, IF(H19>$A$44, $C$44, IF(H19>$A$45,$C$45,IF(H19>$A$46,$C$46, IF(H19>$A$47,$C$47,IF(H19>$A$48,$C$48,$C$49))))))/100 -> 0.11 | K19: =(MAX(B19:F19)-MIN(B19:F19))/G19 -> 0.028006404 | L19: =G19/'Clause 6'!$I$11 -> 2577.7642 | M19: =COUNTA(B19:F19) -> 5
A20: count_15 | B20: =L64/B$8 -> 618.75966 | C20: =M64/C$8 -> 611.71876 | D20: =N64/D$8 -> 616.02908 | E20: =O64/E$8 -> 613.26749 | F20: =P64/F$8 -> 615.25253 | G20: =AVERAGE(B20:F20) -> 615.0055 | H20: =G20*G$8 -> 26520.724 | I20: =STDEVP(B20:F20)/G20 -> 0.0039176693 | J20: =IF(H20>$A$43, $C$43, IF(H20>$A$44, $C$44, IF(H20>$A$45,$C$45,IF(H20>$A$46,$C$46, IF(H20>$A$47,$C$47,IF(H20>$A$48,$C$48,$C$49))))))/100 -> 0.11 | K20: =(MAX(B20:F20)-MIN(B20:F20))/G20 -> 0.011448508 | L20: =G20/'Clause 6'!$I$11 -> 2051.1938 | M20: =COUNTA(B20:F20) -> 5
... A38: count_70 | B38: =L82/B$8 -> 4.2256757 | C38: =M82/C$8 -> 5.38505 | D38: =N82/D$8 -> 4.7298113 | E38: =O82/E$8 -> 4.356733 | F38: =P82/F$8 -> 3.0957544 | G38: =AVERAGE(B38:F38) -> 4.3586049 | H38: =G38*G$8 -> 187.95499 | I38: =STDEVP(B38:F38)/G38 -> 0.17180855 | J38: =IF(H38>$A$43, $C$43, IF(H38>$A$44, $C$44, IF(H38>$A$45,$C$45,IF(H38>$A$46,$C$46, IF(H38>$A$47,$C$47,IF(H38>$A$48,$C$48,$C$49))))))/100 -> 0.275 | K38: =(MAX(B38:F38)-MIN(B38:F38))/G38 -> 0.52523585 | L38: =G38/'Clause 6'!$I$11 -> 14.537014 | M38: =COUNTA(B38:F38) -> 5
A40: Table C.2
B41: Mean counted X | D41: CV_MAX
A42: X >= | B42: X < | C42: DQMAX / SAMPLE | D42: N=3 | E42: N=6 | F42: N=10 | G42: N=20 | H42: N=40
A43: 10000 | C43: 11 | D43: 7.8 | E43: 5.3 | F43: 4 | G43: 2.7 | H43: 1.8
A44: 5000 | B44: 10000 | C44: 11.3 | D44: 7.8 | E44: 5.3 | F44: 4 | G44: 2.7 | H44: 1.9
A45: 2000 | B45: 5000 | C45: 11.9 | D45: 7.9 | E45: 5.4 | F45: 4.1 | G45: 2.9 | H45: 2.1
A46: 1000 | B46: 2000 | C46: 13.4 | D46: 8 | E46: 5.6 | F46: 4.3 | G46: 3.1 | H46: 2.4
A47: 500 | B47: 1000 | C47: 15.6 | D47: 8.2 | E47: 5.9 | F47: 4.7 | G47: 3.6 | H47: 2.9
A48: 200 | B48: 500 | C48: 19.3 | D48: 8.9 | E48: 6.8 | F48: 5.7 | G48: 4.7 | H48: 4.1
A49: 100 | B49: 200 | C49: 27.5 | D49: 10 | E49: 8 | F49: 7 | G49: 6.1 | H49: 5.5
A51: ='6 - B1'!A51 -> 0 | B51: ='6 - B1'!B51 -> Portion 1 | C51: ='6 - B1'!C51 -> Portion 2 | D51: ='6 - B1'!D51 -> Portion 3 | E51: ='6 - B1'!E51 -> Portion 4 | F51: ='6 - B1'!F51 -> Portion 5 | G51: ='6 - B1'!G51 -> Portion 1 | H51: ='6 - B1'!H51 -> Portion 2 | ... P51: ='6 - B1'!P51 -> Portion 5
A52: ='6 - B1'!A52 -> NAME\mL | B52: ='6 - B1'!B52 -> 8.282699 | C52: ='6 - B1'!C52 -> 8.727867 | D52: ='6 - B1'!D52 -> 8.668422 | E52: ='6 - B1'!E52 -> 8.722132 | F52: ='6 - B1'!F52 -> 8.721622 | G52: ='6 - B1'!G52 -> 8.282699 | H52: ='6 - B1'!H52 -> 8.727867 | ... P52: ='6 - B1'!P52 -> 8.721622
A53: ='6 - B1'!A53 -> 4 | B53: ='6 - B1'!B53 -> 33813 | C53: ='6 - B1'!C53 -> 35435 | D53: ='6 - B1'!D53 -> 35865 | E53: ='6 - B1'!E53 -> 35225 | F53: ='6 - B1'!F53 -> 36964 | G53: ='6 - B1'!G53 -> 33813 | H53: ='6 - B1'!H53 -> 35435 | ... P53: ='6 - B1'!P53 -> 36964
A54: ='6 - B1'!A54 -> 5 | B54: ='6 - B1'!B54 -> 29539 | C54: ='6 - B1'!C54 -> 30973 | D54: ='6 - B1'!D54 -> 31250 | E54: ='6 - B1'!E54 -> 30689 | F54: ='6 - B1'!F54 -> 32104 | G54: ='6 - B1'!G54 -> 29539 | H54: ='6 - B1'!H54 -> 30973 | ... P54: ='6 - B1'!P54 -> 32104
A55: ='6 - B1'!A55 -> 6 | B55: ='6 - B1'!B55 -> 25696 | C55: ='6 - B1'!C55 -> 26983 | D55: ='6 - B1'!D55 -> 27099 | E55: ='6 - B1'!E55 -> 26575 | F55: ='6 - B1'!F55 -> 27964 | G55: ='6 - B1'!G55 -> 25696 | H55: ='6 - B1'!H55 -> 26983 | ... P55: ='6 - B1'!P55 -> 27964
A56: ='6 - B1'!A56 -> 7 | B56: ='6 - B1'!B56 -> 22305 | C56: ='6 - B1'!C56 -> 23438 | D56: ='6 - B1'!D56 -> 23353 | E56: ='6 - B1'!E56 -> 23102 | F56: ='6 - B1'!F56 -> 24240 | G56: ='6 - B1'!G56 -> 22305 | H56: ='6 - B1'!H56 -> 23438 | ... P56: ='6 - B1'!P56 -> 24240
A57: ='6 - B1'!A57 -> 8 | B57: ='6 - B1'!B57 -> 19196 | C57: ='6 - B1'!C57 -> 20115 | D57: ='6 - B1'!D57 -> 20061 | E57: ='6 - B1'!E57 -> 19822 | F57: ='6 - B1'!F57 -> 20954 | G57: ='6 - B1'!G57 -> 19196 | H57: ='6 - B1'!H57 -> 20115 | ... P57: ='6 - B1'!P57 -> 20954
A58: ='6 - B1'!A58 -> 9 | B58: ='6 - B1'!B58 -> 16381 | C58: ='6 - B1'!C58 -> 17225 | D58: ='6 - B1'!D58 -> 17237 | E58: ='6 - B1'!E58 -> 16983 | F58: ='6 - B1'!F58 -> 17836 | G58: ='6 - B1'!G58 -> 16381 | H58: ='6 - B1'!H58 -> 17225 | ... P58: ='6 - B1'!P58 -> 17836
A59: ='6 - B1'!A59 -> 10 | B59: ='6 - B1'!B59 -> 13884 | C59: ='6 - B1'!C59 -> 14642 | D59: ='6 - B1'!D59 -> 14609 | E59: ='6 - B1'!E59 -> 14423 | F59: ='6 - B1'!F59 -> 15155 | G59: ='6 - B1'!G59 -> 13884 | H59: ='6 - B1'!H59 -> 14642 | ... P59: ='6 - B1'!P59 -> 15155
A60: ='6 - B1'!A60 -> 11 | B60: ='6 - B1'!B60 -> 11681 | C60: ='6 - B1'!C60 -> 12355 | D60: ='6 - B1'!D60 -> 12214 | E60: ='6 - B1'!E60 -> 12103 | F60: ='6 - B1'!F60 -> 12719 | G60: ='6 - B1'!G60 -> 11681 | H60: ='6 - B1'!H60 -> 12355 | ... P60: ='6 - B1'!P60 -> 12719
...

Sheet 6 - Thresholds
B2: X̅N for First Sample | C2: X̅N for Second Sample | D2: X̅N for Third Sample | E2: Mean X̅N | F2: Threshold Voltage Setting | G2: NC | H2: Uncertainty S | K2: Particle Size | L2: Undiluted Particle Concentration | M2: Interpolated Threshold Voltage Setting
B3: particles per millilitre | C3: particles per millilitre | D3: particles per millilitre | E3: particles per millilitre | G3: samples | H3: /ml | K3: µm(c) | L3: ="/ml" -> /ml
A4: 30 | B4: ='6 - B1'!$L38 -> 14.583277 | C4: ='6 - B2'!$L38 -> 14.574868 | D4: ='6 - B3'!$L38 -> 14.537014 | E4: =AVERAGE(B4:D4) -> 14.565053 | F4: ='Clause 6'!D19 -> 14000 | G4: ='6 - B1'!$M38+'6 - B2'!$M38+'6 - B3'!$M38 -> 15 | H4: =STDEVP('6 - B1'!$B38:F38,'6 - B2'!B38:F38,'6 - B3'!B38:F38)/SQRT(G4) -> 0.1933511 | K4: 4 | L4: 10750.3 | M4: =CubicSpline(L4,$E$4:$E$33,$F$4:$F$33) -> #NAME?
A5: 29 | B5: ='6 - B1'!$L37 -> 20.476954 | C5: ='6 - B2'!$L37 -> 20.465146 | D5: ='6 - B3'!$L37 -> 20.411994 | E5: =AVERAGE(B5:D5) -> 20.451365 | F5: ='Clause 6'!D20 -> 12012.214 | G5: ='6 - B1'!$M37+'6 - B2'!$M37+'6 - B3'!$M37 -> 15 | H5: =STDEVP('6 - B1'!$B37:F37,'6 - B2'!B37:F37,'6 - B3'!B37:F37)/SQRT(G5) -> 0.34897868 | K5: 5 | L5: 7121.1 | M5: =CubicSpline(L5,$E$4:$E$33,$F$4:$F$33) -> #NAME?
A6: 28 | B6: ='6 - B1'!$L36 -> 28.768244 | C6: ='6 - B2'!$L36 -> 28.751655 | D6: ='6 - B3'!$L36 -> 28.676981 | E6: =AVERAGE(B6:D6) -> 28.732293 | F6: ='Clause 6'!D21 -> 10306.664 | G6: ='6 - B1'!$M36+'6 - B2'!$M36+'6 - B3'!$M36 -> 15 | H6: =STDEVP('6 - B1'!$B36:F36,'6 - B2'!B36:F36,'6 - B3'!B36:F36)/SQRT(G6) -> 0.38278067 | K6: 6 | L6: 4729.1 | M6: =CubicSpline(L6,$E$4:$E$33,$F$4:$F$33) -> #NAME?
A7: 27 | B7: ='6 - B1'!$L35 -> 38.996946 | C7: ='6 - B2'!$L35 -> 38.974459 | D7: ='6 - B3'!$L35 -> 38.873234 | E7: =AVERAGE(B7:D7) -> 38.948213 | F7: ='Clause 6'!D22 -> 8843.275 | G7: ='6 - B1'!$M35+'6 - B2'!$M35+'6 - B3'!$M35 -> 15 | H7: =STDEVP('6 - B1'!$B35:F35,'6 - B2'!B35:F35,'6 - B3'!B35:F35)/SQRT(G7) -> 0.42453767 | K7: 7 | L7: 3199.3 | M7: =CubicSpline(L7,$E$4:$E$33,$F$4:$F$33) -> #NAME?
A8: 26 | B8: ='6 - B1'!$L34 -> 54.224197 | C8: ='6 - B2'!$L34 -> 54.192929 | D8: ='6 - B3'!$L34 -> 54.052178 | E8: =AVERAGE(B8:D8) -> 54.156435 | F8: ='Clause 6'!D23 -> 7587.6652 | G8: ='6 - B1'!$M34+'6 - B2'!$M34+'6 - B3'!$M34 -> 15 | H8: =STDEVP('6 - B1'!$B34:F34,'6 - B2'!B34:F34,'6 - B3'!B34:F34)/SQRT(G8) -> 0.42000335 | K8: 8 | L8: 2280.6 | M8: =CubicSpline(L8,$E$4:$E$33,$F$4:$F$33) -> #NAME?
A9: 25 | B9: ='6 - B1'!$L33 -> 73.363272 | C9: ='6 - B2'!$L33 -> 73.320968 | D9: ='6 - B3'!$L33 -> 73.130538 | E9: =AVERAGE(B9:D9) -> 73.271592 | F9: ='Clause 6'!D24 -> 6510.3328 | G9: ='6 - B1'!$M33+'6 - B2'!$M33+'6 - B3'!$M33 -> 15 | H9: =STDEVP('6 - B1'!$B33:F33,'6 - B2'!B33:F33,'6 - B3'!B33:F33)/SQRT(G9) -> 0.6023295 | K9: 9 | L9: 1615 | M9: =CubicSpline(L9,$E$4:$E$33,$F$4:$F$33) -> #NAME?
A10: 24 | B10: ='6 - B1'!$L32 -> 96.592672 | C10: ='6 - B2'!$L32 -> 96.536972 | D10: ='6 - B3'!$L32 -> 96.286246 | E10: =AVERAGE(B10:D10) -> 96.471963 | F10: ='Clause 6'!D25 -> 5585.9652 | G10: ='6 - B1'!$M32+'6 - B2'!$M32+'6 - B3'!$M32 -> 15 | H10: =STDEVP('6 - B1'!$B32:F32,'6 - B2'!B32:F32,'6 - B3'!B32:F32)/SQRT(G10) -> 0.7933298 | K10: 10 | L10: 1130.5 | M10: =CubicSpline(L10,$E$4:$E$33,$F$4:$F$33) -> #NAME?
A11: 23 | B11: ='6 - B1'!$L31 -> 124.82758 | C11: ='6 - B2'!$L31 -> 124.75559 | D11: ='6 - B3'!$L31 -> 124.43158 | E11: =AVERAGE(B11:D11) -> 124.67158 | F11: ='Clause 6'!D26 -> 4792.8436 | G11: ='6 - B1'!$M31+'6 - B2'!$M31+'6 - B3'!$M31 -> 15 | H11: =STDEVP('6 - B1'!$B31:F31,'6 - B2'!B31:F31,'6 - B3'!B31:F31)/SQRT(G11) -> 0.70342103 | K11: 11 | L11: 816.2 | M11: =CubicSpline(L11,$E$4:$E$33,$F$4:$F$33) -> #NAME?
A12: 22 | B12: ='6 - B1'!$L30 -> 165.09075 | C12: ='6 - B2'!$L30 -> 164.99555 | D12: ='6 - B3'!$L30 -> 164.56702 | E12: =AVERAGE(B12:D12) -> 164.88444 | F12: ='Clause 6'!D27 -> 4112.3331 | G12: ='6 - B1'!$M30+'6 - B2'!$M30+'6 - B3'!$M30 -> 15 | H12: =STDEVP('6 - B1'!$B30:F30,'6 - B2'!B30:F30,'6 - B3'!B30:F30)/SQRT(G12) -> 0.63857966 | K12: 12 | L12: 618.6 | M12: =CubicSpline(L12,$E$4:$E$33,$F$4:$F$33) -> #NAME?
A13: 21 | B13: ='6 - B1'!$L29 -> 219.97392 | C13: ='6 - B2'!$L29 -> 219.84707 | D13: ='6 - B3'!$L29 -> 219.27608 | E13: =AVERAGE(B13:D13) -> 219.69902 | F13: ='Clause 6'!D28 -> 3528.4447 | G13: ='6 - B1'!$M29+'6 - B2'!$M29+'6 - B3'!$M29 -> 15 | H13: =STDEVP('6 - B1'!$B29:F29,'6 - B2'!B29:F29,'6 - B3'!B29:F29)/SQRT(G13) -> 0.67218754 | K13: 13 | L13: 481.9 | M13: =CubicSpline(L13,$E$4:$E$33,$F$4:$F$33) -> #NAME?
A14: 20 | B14: ='6 - B1'!$L28 -> 276.41264 | C14: ='6 - B2'!$L28 -> 276.25325 | D14: ='6 - B3'!$L28 -> 275.53576 | E14: =AVERAGE(B14:D14) -> 276.06722 | F14: ='Clause 6'!D29 -> 3027.4595 | G14: ='6 - B1'!$M28+'6 - B2'!$M28+'6 - B3'!$M28 -> 15 | H14: =STDEVP('6 - B1'!$B28:F28,'6 - B2'!B28:F28,'6 - B3'!B28:F28)/SQRT(G14) -> 0.65053196 | K14: 14 | L14: 384.7 | M14: =CubicSpline(L14,$E$4:$E$33,$F$4:$F$33) -> #NAME?
A15: 19 | B15: ='6 - B1'!$L27 -> 358.75007 | C15: ='6 - B2'!$L27 -> 358.5432 | D15: ='6 - B3'!$L27 -> 357.61199 | E15: =AVERAGE(B15:D15) -> 358.30175 | F15: ='Clause 6'!D30 -> 2597.6066 | G15: ='6 - B1'!$M27+'6 - B2'!$M27+'6 - B3'!$M27 -> 15 | H15: =STDEVP('6 - B1'!$B27:F27,'6 - B2'!B27:F27,'6 - B3'!B27:F27)/SQRT(G15) -> 0.5402549 | K15: 15 | L15: 314.6 | M15: =CubicSpline(L15,$E$4:$E$33,$F$4:$F$33) -> #NAME?
A16: 18 | B16: ='6 - B1'!$L26 -> 462.48684 | C16: ='6 - B2'!$L26 -> 462.22015 | D16: ='6 - B3'!$L26 -> 461.01967 | E16: =AVERAGE(B16:D16) -> 461.90889 | F16: ='Clause 6'!D31 -> 2228.7862 | G16: ='6 - B1'!$M26+'6 - B2'!$M26+'6 - B3'!$M26 -> 15 | H16: =STDEVP('6 - B1'!$B26:F26,'6 - B2'!B26:F26,'6 - B3'!B26:F26)/SQRT(G16) -> 0.3922967 | K16: 16 | L16: 261.8 | M16: =CubicSpline(L16,$E$4:$E$33,$F$4:$F$33) -> #NAME?
A17: 17 | B17: ='6 - B1'!$L25 -> 583.22532 | C17: ='6 - B2'!$L25 -> 582.889 | D17: ='6 - B3'!$L25 -> 581.37512 | E17: =AVERAGE(B17:D17) -> 582.49648 | F17: ='Clause 6'!D32 -> 1912.3327 | G17: ='6 - B1'!$M25+'6 - B2'!$M25+'6 - B3'!$M25 -> 15 | H17: =STDEVP('6 - B1'!$B25:F25,'6 - B2'!B25:F25,'6 - B3'!B25:F25)/SQRT(G17) -> 0.62198721 | K17: 17 | L17: 221.2 | M17: =CubicSpline(L17,$E$4:$E$33,$F$4:$F$33) -> #NAME?
A18: 16 | B18: ='6 - B1'!$L24 -> 751.27455 | C18: ='6 - B2'!$L24 -> 750.84134 | D18: ='6 - B3'!$L24 -> 748.89125 | E18: =AVERAGE(B18:D18) -> 750.33571 | F18: ='Clause 6'!D33 -> 1640.8107 | G18: ='6 - B1'!$M24+'6 - B2'!$M24+'6 - B3'!$M24 -> 15 | H18: =STDEVP('6 - B1'!$B24:F24,'6 - B2'!B24:F24,'6 - B3'!B24:F24)/SQRT(G18) -> 0.82823079 | K18: 18 | L18: 188.7 | M18: =CubicSpline(L18,$E$4:$E$33,$F$4:$F$33) -> #NAME?
A19: 15 | B19: ='6 - B1'!$L23 -> 969.09775 | C19: ='6 - B2'!$L23 -> 968.53893 | D19: ='6 - B3'!$L23 -> 966.02343 | E19: =AVERAGE(B19:D19) -> 967.8867 | F19: ='Clause 6'!D34 -> 1407.8407 | G19: ='6 - B1'!$M23+'6 - B2'!$M23+'6 - B3'!$M23 -> 15 | H19: =STDEVP('6 - B1'!$B23:F23,'6 - B2'!B23:F23,'6 - B3'!B23:F23)/SQRT(G19) -> 0.54560261 | K19: 19 | L19: 161 | M19: =CubicSpline(L19,$E$4:$E$33,$F$4:$F$33) -> #NAME?
A20: 14 | B20: ='6 - B1'!$L22 -> 1246.8133 | C20: ='6 - B2'!$L22 -> 1246.0943 | D20: ='6 - B3'!$L22 -> 1242.8579 | E20: =AVERAGE(B20:D20) -> 1245.2552 | F20: ='Clause 6'!D35 -> 1207.9488 | G20: ='6 - B1'!$M22+'6 - B2'!$M22+'6 - B3'!$M22 -> 15 | H20: =STDEVP('6 - B1'!$B22:F22,'6 - B2'!B22:F22,'6 - B3'!B22:F22)/SQRT(G20) -> 0.78362597 | K20: 20 | L20: 136.4 | M20: =CubicSpline(L20,$E$4:$E$33,$F$4:$F$33) -> #NAME?
A21: 13 | B21: ='6 - B1'!$L21 -> 1609.4769 | C21: ='6 - B2'!$L21 -> 1608.5488 | D21: ='6 - B3'!$L21 -> 1604.371 | E21: =AVERAGE(B21:D21) -> 1607.4656 | F21: ='Clause 6'!D36 -> 1036.4386 | G21: ='6 - B1'!$M21+'6 - B2'!$M21+'6 - B3'!$M21 -> 15 | H21: =STDEVP('6 - B1'!$B21:F21,'6 - B2'!B21:F21,'6 - B3'!B21:F21)/SQRT(G21) -> 1.0250859 | K21: 21 | L21: 114.4 | M21: =CubicSpline(L21,$E$4:$E$33,$F$4:$F$33) -> #NAME?
A22: 12 | B22: ='6 - B1'!$L20 -> 2057.7216 | C22: ='6 - B2'!$L20 -> 2056.5351 | D22: ='6 - B3'!$L20 -> 2051.1938 | E22: =AVERAGE(B22:D22) -> 2055.1502 | F22: ='Clause 6'!D37 -> 889.28015 | G22: ='6 - B1'!$M20+'6 - B2'!$M20+'6 - B3'!$M20 -> 15 | H22: =STDEVP('6 - B1'!$B20:F20,'6 - B2'!B20:F20,'6 - B3'!B20:F20)/SQRT(G22) -> 0.62210135 | K22: 22 | L22: 95.3 | M22: =CubicSpline(L22,$E$4:$E$33,$F$4:$F$33) -> #NAME?
A23: 11 | B23: ='6 - B1'!$L19 -> 2585.9678 | C23: ='6 - B2'!$L19 -> 2584.4767 | D23: ='6 - B3'!$L19 -> 2577.7642 | E23: =AVERAGE(B23:D23) -> 2582.7363 | F23: ='Clause 6'!D38 -> 763.01598 | G23: ='6 - B1'!$M19+'6 - B2'!$M19+'6 - B3'!$M19 -> 15 | H23: =STDEVP('6 - B1'!$B19:F19,'6 - B2'!B19:F19,'6 - B3'!B19:F19)/SQRT(G23) -> 2.0807154 | K23: 23 | L23: 79 | M23: =CubicSpline(L23,$E$4:$E$33,$F$4:$F$33) -> #NAME?
A24: 10 | B24: ='6 - B1'!$L18 -> 3208.3219 | C24: ='6 - B2'!$L18 -> 3206.4718 | D24: ='6 - B3'!$L18 -> 3198.1439 | E24: =AVERAGE(B24:D24) -> 3204.3125 | F24: ='Clause 6'!D39 -> 654.67938 | G24: ='6 - B1'!$M18+'6 - B2'!$M18+'6 - B3'!$M18 -> 15 | H24: =STDEVP('6 - B1'!$B18:F18,'6 - B2'!B18:F18,'6 - B3'!B18:F18)/SQRT(G24) -> 3.1249204 | K24: 24 | L24: 65.3 | M24: =CubicSpline(L24,$E$4:$E$33,$F$4:$F$33) -> #NAME?
A25: 9 | B25: ='6 - B1'!$L17 -> 3920.0574 | C25: ='6 - B2'!$L17 -> 3917.7969 | D25: ='6 - B3'!$L17 -> 3907.6215 | E25: =AVERAGE(B25:D25) -> 3915.1586 | F25: ='Clause 6'!D40 -> 561.72492 | G25: ='6 - B1'!$M17+'6 - B2'!$M17+'6 - B3'!$M17 -> 15 | H25: =STDEVP('6 - B1'!$B17:F17,'6 - B2'!B17:F17,'6 - B3'!B17:F17)/SQRT(G25) -> 4.9773943 | K25: 25 | L25: 53.8 | M25: =CubicSpline(L25,$E$4:$E$33,$F$4:$F$33) -> #NAME?
A26: 8 | B26: ='6 - B1'!$L16 -> 4738.2991 | C26: ='6 - B2'!$L16 -> 4735.5668 | D26: ='6 - B3'!$L16 -> 4723.2675 | E26: =AVERAGE(B26:D26) -> 4732.3778 | F26: ='Clause 6'!D41 -> 481.96858 | G26: ='6 - B1'!$M16+'6 - B2'!$M16+'6 - B3'!$M16 -> 15 | H26: =STDEVP('6 - B1'!$B16:F16,'6 - B2'!B16:F16,'6 - B3'!B16:F16)/SQRT(G26) -> 5.9761664 | K26: 26 | L26: 44.6 | M26: =CubicSpline(L26,$E$4:$E$33,$F$4:$F$33) -> #NAME?
A27: 7 | B27: ='6 - B1'!$L15 -> 5641.4109 | C27: ='6 - B2'!$L15 -> 5638.1578 | D27: ='6 - B3'!$L15 -> 5623.5144 | E27: =AVERAGE(B27:D27) -> 5634.361 | F27: ='Clause 6'!D42 -> 413.53641 | G27: ='6 - B1'!$M15+'6 - B2'!$M15+'6 - B3'!$M15 -> 15 | H27: =STDEVP('6 - B1'!$B15:F15,'6 - B2'!B15:F15,'6 - B3'!B15:F15)/SQRT(G27) -> 7.1934063 | K27: 27 | L27: 37 | M27: =CubicSpline(L27,$E$4:$E$33,$F$4:$F$33) -> #NAME?
A28: 6 | B28: ='6 - B1'!$L14 -> 6646.1676 | C28: ='6 - B2'!$L14 -> 6642.3351 | D28: ='6 - B3'!$L14 -> 6625.0836 | E28: =AVERAGE(B28:D28) -> 6637.8621 | F28: ='Clause 6'!D43 -> 354.82057 | G28: ='6 - B1'!$M14+'6 - B2'!$M14+'6 - B3'!$M14 -> 15 | H28: =STDEVP('6 - B1'!$B14:F14,'6 - B2'!B14:F14,'6 - B3'!B14:F14)/SQRT(G28) -> 8.3467982 | K28: 28 | L28: 30.7 | M28: =CubicSpline(L28,$E$4:$E$33,$F$4:$F$33) -> #NAME?
A29: 5 | B29: ='6 - B1'!$L13 -> 7770.2187 | C29: ='6 - B2'!$L13 -> 7765.7381 | D29: ='6 - B3'!$L13 -> 7745.5688 | E29: =AVERAGE(B29:D29) -> 7760.5085 | F29: ='Clause 6'!D44 -> 304.44148 | G29: ='6 - B1'!$M13+'6 - B2'!$M13+'6 - B3'!$M13 -> 15 | H29: =STDEVP('6 - B1'!$B13:F13,'6 - B2'!B13:F13,'6 - B3'!B13:F13)/SQRT(G29) -> 11.137719 | K29: 29 | L29: 25.2 | M29: =CubicSpline(L29,$E$4:$E$33,$F$4:$F$33) -> #NAME?
A30: 4 | B30: ='6 - B1'!$L12 -> 9034.0728 | C30: ='6 - B2'!$L12 -> 9028.8634 | D30: ='6 - B3'!$L12 -> 9005.4135 | E30: =AVERAGE(B30:D30) -> 9022.7832 | F30: ='Clause 6'!D45 -> 261.21544 | G30: ='6 - B1'!$M12+'6 - B2'!$M12+'6 - B3'!$M12 -> 15 | H30: =STDEVP('6 - B1'!$B12:F12,'6 - B2'!B12:F12,'6 - B3'!B12:F12)/SQRT(G30) -> 11.088387 | K30: 30 | L30: 20.1 | M30: =CubicSpline(L30,$E$4:$E$33,$F$4:$F$33) -> #NAME?
A31: 3 | B31: ='6 - B1'!$L11 -> 10421.191 | C31: ='6 - B2'!$L11 -> 10415.182 | D31: ='6 - B3'!$L11 -> 10388.131 | E31: =AVERAGE(B31:D31) -> 10408.168 | F31: ='Clause 6'!D46 -> 224.12685 | G31: ='6 - B1'!$M11+'6 - B2'!$M11+'6 - B3'!$M11 -> 15 | H31: =STDEVP('6 - B1'!$B11:F11,'6 - B2'!B11:F11,'6 - B3'!B11:F11)/SQRT(G31) -> 13.569289
A32: 2 | B32: ='6 - B1'!$L10 -> 11991.306 | C32: ='6 - B2'!$L10 -> 11984.392 | D32: ='6 - B3'!$L10 -> 11953.266 | E32: =AVERAGE(B32:D32) -> 11976.321 | F32: ='Clause 6'!D47 -> 192.30426 | G32: ='6 - B1'!$M10+'6 - B2'!$M10+'6 - B3'!$M10 -> 15 | H32: =STDEVP('6 - B1'!$B10:F10,'6 - B2'!B10:F10,'6 - B3'!B10:F10)/SQRT(G32) -> 14.462349
A33: 1 | B33: ='6 - B1'!$L9 -> 13755.869 | C33: ='6 - B2'!$L9 -> 13747.937 | D33: ='6 - B3'!$L9 -> 13712.231 | E33: =AVERAGE(B33:D33) -> 13738.679 | F33: ='Clause 6'!D48 -> 165 | G33: ='6 - B1'!$M9+'6 - B2'!$M9+'6 - B3'!$M9 -> 15 | H33: =STDEVP('6 - B1'!$B9:F9,'6 - B2'!B9:F9,'6 - B3'!B9:F9)/SQRT(G33) -> 18.455828
