Workbook
Name _666.lpacal_1: AUTO!$A$1:$B$150
Name _666.lpacal_2: AUTO!$H$1:$I$144
Name LPA1.lpacal_1: AUTO!$A$1:$B$89

Sheet mtd
A1: SRM2806 2.8mg MTD / ml | H1: Interpolation Order
H2: 4 | K2: to 10 micron | M2: to 70 micron
A3: um | B3: n/ml | C3: n/mg/ml | D3: Expanded Uncertainty | F3: ln(n/mg/ml) | H3: um | I3: n/mg/ml | K3: x | L3: y | M3: x | N3: y
A4: 1 | B4: 108400 | C4: =B4/2.8 -> 38714.286 | D4: 0.274 | F4: =LN(C4) -> 10.563964 | H4: 50 | I4: =EXP(interpolate($A$4:$A$93, $F$4:$F$93, $H4,$H$2,FALSE)) -> #NAME? | K4: 1 | L4: =EXP(interpolate($A$4:$A$92, $F$4:$F$92, $K4,$H$2,TRUE)) -> #NAME? | M4: 1 | N4: =EXP(interpolate($A$4:$A$93, $F$4:$F$93, M4,$H$2,TRUE)) -> #NAME?
A5: 2 | B5: 27035 | C5: =B5/2.8 -> 9655.3571 | D5: 0.265 | F5: =LN(C5) -> 9.1752682 | K5: 1.1 | L5: =EXP(interpolate($A$4:$A$92, $F$4:$F$92, $K5,$H$2,TRUE)) -> #NAME? | M5: 2 | N5: =EXP(interpolate($A$4:$A$93, $F$4:$F$93, M5,$H$2,TRUE)) -> #NAME?
A6: 3 | B6: 11209 | C6: =B6/2.8 -> 4003.2143 | D6: 0.272 | F6: =LN(C6) -> 8.2948529 | K6: 1.2 | L6: =EXP(interpolate($A$4:$A$92, $F$4:$F$92, $K6,$H$2,TRUE)) -> #NAME? | M6: 3 | N6: =EXP(interpolate($A$4:$A$93, $F$4:$F$93, M6,$H$2,TRUE)) -> #NAME?
A7: 4 | B7: 6095 | C7: =B7/2.8 -> 2176.7857 | D7: 0.308 | F7: =LN(C7) -> 7.6856046 | K7: 1.3 | L7: =EXP(interpolate($A$4:$A$92, $F$4:$F$92, $K7,$H$2,TRUE)) -> #NAME? | M7: 4 | N7: =EXP(interpolate($A$4:$A$93, $F$4:$F$93, M7,$H$2,TRUE)) -> #NAME?
A8: 5 | B8: 3737 | C8: =B8/2.8 -> 1334.6429 | D8: 0.414 | F8: =LN(C8) -> 7.196419 | H8: n/mg/l | I8: 10000 | K8: 1.4 | L8: =EXP(interpolate($A$4:$A$92, $F$4:$F$92, $K8,$H$2,TRUE)) -> #NAME? | M8: 5 | N8: =EXP(interpolate($A$4:$A$93, $F$4:$F$93, M8,$H$2,TRUE)) -> #NAME?
A9: 6 | B9: 2395 | C9: =B9/2.8 -> 855.35714 | D9: 0.56 | F9: =LN(C9) -> 6.7515191 | H9: ln(n/mg/l) | I9: =LN(I8) -> 9.2103404 | K9: 1.5 | L9: =EXP(interpolate($A$4:$A$92, $F$4:$F$92, $K9,$H$2,TRUE)) -> #NAME? | M9: 6 | N9: =EXP(interpolate($A$4:$A$93, $F$4:$F$93, M9,$H$2,TRUE)) -> #NAME?
A10: 7 | B10: 1573 | C10: =B10/2.8 -> 561.78571 | D10: 0.542 | F10: =LN(C10) -> 6.3311205 | H10: um | I10: =interpolate($F$4:$F$93, $A$4:$A$93, $I9,$H$2,FALSE) -> #NAME? | K10: 1.6 | L10: =EXP(interpolate($A$4:$A$92, $F$4:$F$92, $K10,$H$2,TRUE)) -> #NAME? | M10: 7 | N10: =EXP(interpolate($A$4:$A$93, $F$4:$F$93, M10,$H$2,TRUE)) -> #NAME?
A11: 8 | B11: 1055 | C11: =B11/2.8 -> 376.78571 | D11: 0.499 | F11: =LN(C11) -> 5.9316766 | K11: 1.7 | L11: =EXP(interpolate($A$4:$A$92, $F$4:$F$92, $K11,$H$2,TRUE)) -> #NAME? | M11: 8 | N11: =EXP(interpolate($A$4:$A$93, $F$4:$F$93, M11,$H$2,TRUE)) -> #NAME?
A12: 9 | B12: 725.8 | C12: =B12/2.8 -> 259.21429 | D12: 0.544 | F12: =LN(C12) -> 5.5576551 | K12: 1.8 | L12: =EXP(interpolate($A$4:$A$92, $F$4:$F$92, $K12,$H$2,TRUE)) -> #NAME? | M12: 9 | N12: =EXP(interpolate($A$4:$A$93, $F$4:$F$93, M12,$H$2,TRUE)) -> #NAME?
A13: 10 | B13: 513.7 | C13: =B13/2.8 -> 183.46429 | D13: 0.643 | F13: =LN(C13) -> 5.21202 | K13: 1.9 | L13: =EXP(interpolate($A$4:$A$92, $F$4:$F$92, $K13,$H$2,TRUE)) -> #NAME? | M13: 10 | N13: =EXP(interpolate($A$4:$A$93, $F$4:$F$93, M13,$H$2,TRUE)) -> #NAME?
A14: 11 | B14: 374.6 | C14: =B14/2.8 -> 133.78571 | D14: 0.759 | F14: =LN(C14) -> 4.8962394 | H14: 2 | I14: =mtd($H$14) -> #NAME? | K14: 2 | L14: =EXP(interpolate($A$4:$A$92, $F$4:$F$92, $K14,$H$2,TRUE)) -> #NAME? | M14: 11 | N14: =EXP(interpolate($A$4:$A$93, $F$4:$F$93, M14,$H$2,TRUE)) -> #NAME?
A15: 12 | B15: 281 | C15: =B15/2.8 -> 100.35714 | D15: 0.981 | F15: =LN(C15) -> 4.6087353 | K15: 2.1 | L15: =EXP(interpolate($A$4:$A$92, $F$4:$F$92, $K15,$H$2,TRUE)) -> #NAME? | M15: 12 | N15: =EXP(interpolate($A$4:$A$93, $F$4:$F$93, M15,$H$2,TRUE)) -> #NAME?
A16: 13 | B16: 216.4 | C16: =B16/2.8 -> 77.285714 | D16: 1.273 | F16: =LN(C16) -> 4.3475091 | K16: 2.2 | L16: =EXP(interpolate($A$4:$A$92, $F$4:$F$92, $K16,$H$2,TRUE)) -> #NAME? | M16: 13 | N16: =EXP(interpolate($A$4:$A$93, $F$4:$F$93, M16,$H$2,TRUE)) -> #NAME?
A17: 14 | B17: 170.4 | C17: =B17/2.8 -> 60.857143 | D17: 1.655 | F17: =LN(C17) -> 4.1085292 | H17: =mtd(1.7575) -> #NAME? | K17: 2.3 | L17: =EXP(interpolate($A$4:$A$92, $F$4:$F$92, $K17,$H$2,TRUE)) -> #NAME? | M17: 14 | N17: =EXP(interpolate($A$4:$A$93, $F$4:$F$93, M17,$H$2,TRUE)) -> #NAME?
A18: 15 | B18: 136.8 | C18: =B18/2.8 -> 48.857143 | D18: 2.211 | F18: =LN(C18) -> 3.8889006 | K18: 2.4 | L18: =EXP(interpolate($A$4:$A$92, $F$4:$F$92, $K18,$H$2,TRUE)) -> #NAME? | M18: 15 | N18: =EXP(interpolate($A$4:$A$93, $F$4:$F$93, M18,$H$2,TRUE)) -> #NAME?
A19: 16 | B19: 111.3 | C19: =B19/2.8 -> 39.75 | D19: 2.414 | F19: =LN(C19) -> 3.6826098 | H19: (Testing area only) | K19: 2.5 | L19: =EXP(interpolate($A$4:$A$92, $F$4:$F$92, $K19,$H$2,TRUE)) -> #NAME? | M19: 16 | N19: =EXP(interpolate($A$4:$A$93, $F$4:$F$93, M19,$H$2,TRUE)) -> #NAME?
A20: 17 | B20: 91.33 | C20: =B20/2.8 -> 32.617857 | D20: 2.91 | F20: =LN(C20) -> 3.4848599 | K20: 2.6 | L20: =EXP(interpolate($A$4:$A$92, $F$4:$F$92, $K20,$H$2,TRUE)) -> #NAME? | M20: 17 | N20: =EXP(interpolate($A$4:$A$93, $F$4:$F$93, M20,$H$2,TRUE)) -> #NAME?
A21: 18 | B21: 75.29 | C21: =B21/2.8 -> 26.889286 | D21: 3.444 | F21: =LN(C21) -> 3.2917279 | K21: 2.7 | L21: =EXP(interpolate($A$4:$A$92, $F$4:$F$92, $K21,$H$2,TRUE)) -> #NAME? | M21: 18 | N21: =EXP(interpolate($A$4:$A$93, $F$4:$F$93, M21,$H$2,TRUE)) -> #NAME?
A22: 19 | B22: 62.17 | C22: =B22/2.8 -> 22.203571 | D22: 4.101 | F22: =LN(C22) -> 3.1002532 | I22: = Formulae | K22: 2.8 | L22: =EXP(interpolate($A$4:$A$92, $F$4:$F$92, $K22,$H$2,TRUE)) -> #NAME? | M22: 19 | N22: =EXP(interpolate($A$4:$A$93, $F$4:$F$93, M22,$H$2,TRUE)) -> #NAME?
A23: 20 | B23: 51.35 | C23: =B23/2.8 -> 18.339286 | D23: 5.045 | F23: =LN(C23) -> 2.9090455 | K23: 2.9 | L23: =EXP(interpolate($A$4:$A$92, $F$4:$F$92, $K23,$H$2,TRUE)) -> #NAME? | M23: 20 | N23: =EXP(interpolate($A$4:$A$93, $F$4:$F$93, M23,$H$2,TRUE)) -> #NAME?
A24: 21 | B24: 42.4 | C24: =B24/2.8 -> 15.142857 | D24: 4.976 | F24: =LN(C24) -> 2.7175289 | I24: = Reference Figures | K24: 3 | L24: =EXP(interpolate($A$4:$A$92, $F$4:$F$92, $K24,$H$2,TRUE)) -> #NAME? | M24: 21 | N24: =EXP(interpolate($A$4:$A$93, $F$4:$F$93, M24,$H$2,TRUE)) -> #NAME?
A25: 22 | B25: 35.01 | C25: =B25/2.8 -> 12.503571 | D25: 5.508 | F25: =LN(C25) -> 2.5260143 | K25: 3.1 | L25: =EXP(interpolate($A$4:$A$92, $F$4:$F$92, $K25,$H$2,TRUE)) -> #NAME? | M25: 22 | N25: =EXP(interpolate($A$4:$A$93, $F$4:$F$93, M25,$H$2,TRUE)) -> #NAME?
A26: 23 | B26: 28.95 | C26: =B26/2.8 -> 10.339286 | D26: 5.941 | F26: =LN(C26) -> 2.3359508 | I26: = Manual Input | K26: 3.2 | L26: =EXP(interpolate($A$4:$A$92, $F$4:$F$92, $K26,$H$2,TRUE)) -> #NAME? | M26: 23 | N26: =EXP(interpolate($A$4:$A$93, $F$4:$F$93, M26,$H$2,TRUE)) -> #NAME?
A27: 24 | B27: 23.99 | C27: =B27/2.8 -> 8.5678571 | D27: 6.573 | F27: =LN(C27) -> 2.1480177 | K27: 3.3 | L27: =EXP(interpolate($A$4:$A$92, $F$4:$F$92, $K27,$H$2,TRUE)) -> #NAME? | M27: 24 | N27: =EXP(interpolate($A$4:$A$93, $F$4:$F$93, M27,$H$2,TRUE)) -> #NAME?
A28: 25 | B28: 19.95 | C28: =B28/2.8 -> 7.125 | D28: 6.945 | F28: =LN(C28) -> 1.9636097 | H28: Doc. No: 200.XXX | K28: 3.4 | L28: =EXP(interpolate($A$4:$A$92, $F$4:$F$92, $K28,$H$2,TRUE)) -> #NAME? | M28: 25 | N28: =EXP(interpolate($A$4:$A$93, $F$4:$F$93, M28,$H$2,TRUE)) -> #NAME?
A29: 26 | B29: 16.66 | C29: =B29/2.8 -> 5.95 | D29: 7.261 | F29: =LN(C29) -> 1.7833912 | H29: Sheet 3 | K29: 3.5 | L29: =EXP(interpolate($A$4:$A$92, $F$4:$F$92, $K29,$H$2,TRUE)) -> #NAME? | M29: 26 | N29: =EXP(interpolate($A$4:$A$93, $F$4:$F$93, M29,$H$2,TRUE)) -> #NAME?
A30: 27 | B30: 13.98 | C30: =B30/2.8 -> 4.9928571 | D30: 8.03 | F30: =LN(C30) -> 1.6080083 | H30: DCRXXXX | K30: 3.6 | L30: =EXP(interpolate($A$4:$A$92, $F$4:$F$92, $K30,$H$2,TRUE)) -> #NAME? | M30: 27 | N30: =EXP(interpolate($A$4:$A$93, $F$4:$F$93, M30,$H$2,TRUE)) -> #NAME?
A31: 28 | B31: 11.8 | C31: =B31/2.8 -> 4.2142857 | D31: 8.369 | F31: =LN(C31) -> 1.4384801 | H31: Rev 0 | K31: 3.7 | L31: =EXP(interpolate($A$4:$A$92, $F$4:$F$92, $K31,$H$2,TRUE)) -> #NAME? | M31: 28 | N31: =EXP(interpolate($A$4:$A$93, $F$4:$F$93, M31,$H$2,TRUE)) -> #NAME?
A32: 29 | B32: 10.02 | C32: =B32/2.8 -> 3.5785714 | D32: 8.595 | F32: =LN(C32) -> 1.2749637 | K32: 3.8 | L32: =EXP(interpolate($A$4:$A$92, $F$4:$F$92, $K32,$H$2,TRUE)) -> #NAME? | M32: 29 | N32: =EXP(interpolate($A$4:$A$93, $F$4:$F$93, M32,$H$2,TRUE)) -> #NAME?
A33: 30 | B33: 8.568 | C33: =B33/2.8 -> 3.06 | D33: 9.943 | F33: =LN(C33) -> 1.1184149 | K33: 3.9 | L33: =EXP(interpolate($A$4:$A$92, $F$4:$F$92, $K33,$H$2,TRUE)) -> #NAME? | M33: 30 | N33: =EXP(interpolate($A$4:$A$93, $F$4:$F$93, M33,$H$2,TRUE)) -> #NAME?
A34: 31 | B34: 7.38 | C34: =B34/2.8 -> 2.6357143 | F34: =LN(C34) -> 0.96915422 | K34: 4 | L34: =EXP(interpolate($A$4:$A$92, $F$4:$F$92, $K34,$H$2,TRUE)) -> #NAME? | M34: 31 | N34: =EXP(interpolate($A$4:$A$93, $F$4:$F$93, M34,$H$2,TRUE)) -> #NAME?
A35: 32 | B35: 6.403 | C35: =B35/2.8 -> 2.2867857 | F35: =LN(C35) -> 0.82714721 | K35: 4.1 | L35: =EXP(interpolate($A$4:$A$92, $F$4:$F$92, $K35,$H$2,TRUE)) -> #NAME? | M35: 32 | N35: =EXP(interpolate($A$4:$A$93, $F$4:$F$93, M35,$H$2,TRUE)) -> #NAME?
A36: 33 | B36: 5.594 | C36: =B36/2.8 -> 1.9978571 | F36: =LN(C36) -> 0.69207518 | K36: 4.2 | L36: =EXP(interpolate($A$4:$A$92, $F$4:$F$92, $K36,$H$2,TRUE)) -> #NAME? | M36: 33 | N36: =EXP(interpolate($A$4:$A$93, $F$4:$F$93, M36,$H$2,TRUE)) -> #NAME?
A37: 34 | B37: 4.921 | C37: =B37/2.8 -> 1.7575 | F37: =LN(C37) -> 0.56389234 | K37: 4.3 | L37: =EXP(interpolate($A$4:$A$92, $F$4:$F$92, $K37,$H$2,TRUE)) -> #NAME? | M37: 34 | N37: =EXP(interpolate($A$4:$A$93, $F$4:$F$93, M37,$H$2,TRUE)) -> #NAME?
A38: 35 | B38: 4.356 | C38: =B38/2.8 -> 1.5557143 | F38: =LN(C38) -> 0.44193479 | K38: 4.4 | L38: =EXP(interpolate($A$4:$A$92, $F$4:$F$92, $K38,$H$2,TRUE)) -> #NAME? | M38: 35 | N38: =EXP(interpolate($A$4:$A$93, $F$4:$F$93, M38,$H$2,TRUE)) -> #NAME?
A39: 36 | B39: 3.88 | C39: =B39/2.8 -> 1.3857143 | F39: =LN(C39) -> 0.32621574 | K39: 4.5 | L39: =EXP(interpolate($A$4:$A$92, $F$4:$F$92, $K39,$H$2,TRUE)) -> #NAME? | M39: 36 | N39: =EXP(interpolate($A$4:$A$93, $F$4:$F$93, M39,$H$2,TRUE)) -> #NAME?
A40: 37 | B40: 3.476 | C40: =B40/2.8 -> 1.2414286 | F40: =LN(C40) -> 0.21626279 | K40: 4.6 | L40: =EXP(interpolate($A$4:$A$92, $F$4:$F$92, $K40,$H$2,TRUE)) -> #NAME? | M40: 37 | N40: =EXP(interpolate($A$4:$A$93, $F$4:$F$93, M40,$H$2,TRUE)) -> #NAME?
...

Sheet AUTO
A1: product | B1: LPA3 NAVAIR
A2: LPA SETTINGS
A3: model_name | B3: LPA3 NAVAIR
A4: serial_number | B4: 63010074
A5: option_bits | B5: 9264
A6: x_option_bits | B6: 0
A7: test_reference | B7: LPA3 NAVAIR
A8: threshold0 | B8: 112
A9: threshold1 | B9: 176
A10: threshold2 | B10: 714
A11: threshold3 | B11: 1314
A12: threshold4 | B12: 1794
A13: threshold5 | B13: 4348
A14: threshold6 | B14: 6298
A15: threshold7 | B15: 14290
A16: effective_slit_width | B16: 60
A17: effective_slit_height | B17: 300
A18: channel_width | B18: 750
A19: divergence_milliradians | B19: 200
... A115: threshold32_31_sz | B115: 70
A116: MEASURED PARAMETERS
A117: verification_count_1_0 | B117: 1047870
A118: verification_count_1_1 | B118: 431351
A119: verification_count_1_2 | B119: 32014
A120: verification_count_1_3 | B120: 9858
A121: verification_count_1_4 | B121: 5300
A122: verification_count_1_5 | B122: 1181
A123: verification_count_1_6 | B123: 637
A124: verification_count_1_7 | B124: 139
A125: verification_count_2_0 | B125: 1047870
A126: verification_count_2_1 | B126: 431351
A127: verification_count_2_2 | B127: 32014
A128: verification_count_2_3 | B128: 9858
... A276: reference_count32_31 | B276: 1.4
A277: Measured Counter Data
A278: pump_current_sampling | B278: 345
A279: pump_current_emptying | B279: 345
A280: led_level | B280: 10000
A281: no_noise_threshold | B281: 54
A282: CALIBRATION DOCUMENT VALUES
...

Sheet Cover Service Sheet
C1: Doc No. 202.041_04 CML4 Service and Calibration Sheet DCR 0678 | R1: -
R2: A. Brown
B3: Op No. | C3: CML4 Cover Sheet | R3: R. Eden
B4: 1 | C4: Product: | D4: SRM2806 2.8mg MTD / ml | F4: W | H4: 0 | J4: M | L4: 0 | N4: 0 | P4: 3 | Q4: SERVICE NOTES: | R4: A. Hayward
B5: =B4+1 -> 2 | C5: Serial No.: | D5: ='Auto-Calibration record'!H15 -> 63010074 | E5: =IF(D5="20","0",IF(D5="PC","00","")) | R5: J. Scarrott | S5: W | T5: P | U5: M | V5: 1 | W5: 0 | X5: 1
A6: FALSE | B6: =B5+1 -> 3 | C6: Customer: | E6: Comments | R6: A. Mustoe | S6: 0 | T6: 0 | U6: N | V6: 0 | X6: 2
A7: FALSE | B7: =B6+1 -> 4 | C7: Online booking by customer | Q7: =IF(A7=TRUE,"Customer completed online booking process","Please note: Where possible, all recalibrations should be booked online at the supplied booking site") -> Please note: Where possible, all recalibrations should be booked online at the supplied booking site | R7: Alex Buckley | T7: T | U7: S | X7: 3
A8: FALSE | B8: =B7+1 -> 5 | C8: Accessories present? | E8: NOTE: Please complete table below | Q8: =IF(A8=TRUE,"Please note: Accessories supplied with product, ensure return of all (see right)","No accessories present to return to end user") -> No accessories present to return to end user | R8: Luke Harding | X8: 4
A9: FALSE | B9: =B8+1 -> 6 | C9: COSHH SUPPLIED? | Q9: =IF(A9<>TRUE,"Relevant COSHH information provided by end user","No COSHH information supplied by end user") -> Relevant COSHH information provided by end user | R9: Scott Mosson
A10: FALSE | B10: =B9+1 -> 7 | C10: Booking Date: | R10: Jamie Soule
A11: FALSE | B11: =B10+1 -> 8 | C11: Service sheet number: | R11: Trevor Whittle
A12: FALSE | B12: =B11+1 -> 9 | C12: Warranty claim | Q12: =IF(A12=TRUE,"Item is considered warranty, requires QC control on NCR","") | R12: John Devereux
A13: FALSE | B13: =B12+1 -> 10 | C13: Date of Last Calibration (NB: CELL WILL SELF FILL) | D13: =D45-365 -> -365
A14: FALSE | B14: =B13+1 -> 11 | C14: If yes to warranty - NCR number(s)
A15: FALSE | B15: =B14+1 -> 12 | C15: SO number:
A16: FALSE | B16: =B15+1 -> 13 | C16: WO number:
A17: FALSE | B17: =B16+1 -> 14 | C17: Estimated Ship Date: | D17: =D10+5 -> 5
A18: FALSE
A19: FALSE | C19: Take this from the service tag if applicable
A20: FALSE | B20: =B17+1 -> 15 | C20: Carry bag | Q20: =IF(A20=TRUE,"Carry bag, ","")
A21: FALSE | B21: =B20+1 -> 16 | C21: Waste bottle | Q21: =IF(A21=TRUE,"Waste bottle, ","")
A22: FALSE | B22: =B21+1 -> 17 | C22: 1500mm pressure hose | Q22: =IF(A22=TRUE,"1500mm pressure hose, ","")
A23: FALSE | B23: =B22+1 -> 18 | C23: 600mm pressure hose | Q23: =IF(A23=TRUE,"600mm pressure hose, ","")
A24: FALSE | B24: =B23+1 -> 19 | C24: 2000mm waste hose | Q24: =IF(A24=TRUE,"Waste hose, ","")
A25: FALSE | B25: =B24+1 -> 20 | C25: Pouches | E25: Qty | Q25: =IF(A25=TRUE,F25&"Pouches, ","")
B26: =B25+1 -> 21 | C26: portable printer
A27: FALSE | B27: =B26+1 -> 22 | C27: USB-Serial converter | Q27: =IF(A27=TRUE,"USB converter, ","")
A28: FALSE | B28: =B27+1 -> 23 | C28: Serial cable | Q28: =IF(A28=TRUE,"serial cable, ","")
A29: FALSE | B29: =B28+1 -> 24 | C29: Power adapter | Q29: =IF(A29=TRUE,"power adapter, ","")
A30: FALSE | C30: Initial checks
A31: TRUE | B31: =B29+1 -> 25 | C31: Date initial inspection started: | E31: Status: | G31: =IF($D$31=$D$10,"ON TIME",IF($D$31>$D$10,"LATE",IF($D$31<$D$10,"EARLY"))) -> ON TIME
A32: TRUE | B32: =B31+1 -> 26 | C32: Initial checked by: | D32: -
A33: FALSE | B33: =B32+1 -> 27 | C33: Acceptible outer case condition? | Q33: =IF(A33=TRUE,"Case was returned in acceptable condition","Exterior damage to case upon receipt") -> Exterior damage to case upon receipt
A34: FALSE | B34: =B33+1 -> 28 | C34: Is there a cap on the INPUT test point? | Q34: =IF(A34=TRUE,"Cap on input test point","No cap on input test point") -> No cap on input test point
A35: FALSE | B35: =B34+1 -> 29 | C35: Is there a cap on the WASTE test point? | Q35: =IF(A35=TRUE,"Cap on waste test point","No cap on waste test point") -> No cap on waste test point
A36: FALSE | B36: =B35+1 -> 30 | C36: Remove old cal cert/paperwork and recycle
A37: FALSE | B37: =B36+1 -> 31 | C37: Check power connector is ok and functions
A38: FALSE | B38: =B37+1 -> 32 | C38: Turn unit on
A39: FALSE | B39: =B38+1 -> 33 | C39: Check screen operates | Q39: =IF(A39=TRUE,"Screen is functional upon receipt","The screen has been damaged and is not functioning correctly") -> The screen has been damaged and is not functioning correctly
A40: FALSE | B40: =B39+1 -> 34 | C40: Check all touch screen tabs operate
...

Sheet ss
A1: Service Sheet | C1: ='Cover Service Sheet'!E10 -> 0
A3: Outer Case Condition
A4: Caps on test points
A5: Software Version
A6: Serial Number
A7: Calibration due date
A8: Reference
A9: Language
A10: Open Diagnostics screen
A11: Cycle Count
A12: Battery Parameter
A13: Check Printer operation
A15: Remove faceplate screws
... A18: Replace pipework.

Sheet Sheet1
B2: Op No. | C2: LPA3 SERVICE SHEET | P2: M | Q2: M Gibson
P3: N | Q3: L Harding
B4: 16 | C4: Product: | D4: ='Cover Service Sheet'!D4&'Cover Service Sheet'!F4&'Cover Service Sheet'!H4&'Cover Service Sheet'!J4&'Cover Service Sheet'!L4&'Cover Service Sheet'!N4&'Cover Service Sheet'!P4 -> SRM2806 2.8mg MTD / mlW0M003 | O4: SERVICE NOTES: | P4: S | Q4: T Welch
B5: =B4+1 -> 17 | C5: Serial No.: | D5: ='Cover Service Sheet'!D5 -> 63010074 | E5: ='Cover Service Sheet'!E5&'Cover Service Sheet'!F5 | Q5: J Scarrott
B6: =B5+1 -> 18 | C6: Customer: | D6: 0 | Q6: S Mosson
B7: =B6+1 -> 19 | C7: Booking Date: | D7: 0 | Q7: G Salf
B8: =B7+1 -> 20 | C8: Service number: | D8: 0 | Q8: M Shurmer
A9: FALSE | B9: =B8+1 -> 21 | C9: Warranty claim | D9: =IF(A9=TRUE,"WARRANTY CLAIM","NON WARRANTY") -> NON WARRANTY | O9: =IF(A9=TRUE,"Item is considered warranty, requires QC control on NCR","") | Q9: J Odom
A10: TRUE | B10: =B9+1 -> 22 | C10: if yes to warranty - NCR number(s) | D10: 0 | E10: 0 | Q10: A Mustoe
B11: =B10+1 -> 23 | C11: SO number: | D11: 0
B12: =B11+1 -> 24 | C12: WO number: | D12: 0
B13: =B12+1 -> 25 | C13: Ship Date: | D13: =D7+14 -> 14
C14: INITIAL INSPECTION
B15: =B13+1 -> 26 | C15: Date started: | E15: Status: | G15: =IF(D15=D7,"ON TIME",IF(D15>D7,"LATE",IF(D15<D7,"EARLY"))) -> ON TIME
B16: =B15+1 -> 27 | C16: Time started:
D17: PRE-SERVICE | E17: COMMENTS
A18: FALSE | B18: =B16+1 -> 28 | D18: Are both caps on test points? | O18: =IF(A18=FALSE,"One or more hydraulic caps were missing","Test point cap and waste plug present") -> One or more hydraulic caps were missing
A19: FALSE | B19: =B18+1 -> 29 | D19: In good outer condition? | O19: =IF(A19=FALSE,"Unit was dirty or damaged outside and required extra cleanup","Outer condition good") -> Unit was dirty or damaged outside and required extra cleanup
A20: TRUE | B20: =B19+1 -> 30
A21: FALSE | B21: =B20+1 -> 31 | O21: =IF(A21=TRUE,"Case feet present and operational","quote for case feet repair required") -> quote for case feet repair required
A22: FALSE | B22: =B21+1 -> 32 | D22: Check presence & condition of case latches | O22: =IF(A22=TRUE,"Case latches present and operational","quote for case latch repair required") -> quote for case latch repair required
A23: TRUE | B23: =B22+1 -> 33 | D23: Remove old cal cert/paperwork/calibrated label
A24: FALSE | B24: =B23+1 -> 34 | D24: Remove faceplate screws and keep/store in box
A25: FALSE | B25: =B24+1 -> 35 | D25: Plug in mains and RS232 - chk charge light OK | O25: =IF(A25=TRUE,"Charge circuit checked and verified PASS","")
A26: 4.1 | B26: =B25+1 -> 36 | C26: Turn ON and note Software version: | O26: =IF(D26=A26,"Unit firmware at current release","Free of charge upgrade of unit firmware ") -> Free of charge upgrade of unit firmware
A27: FALSE | B27: =B26+1 -> 37 | D27: Log downloaded succesfully onto USB stick | O27: =IF(A27=FALSE,"Log was not present/corrupted so could not be downloaded","Log download test completed succesfully") -> Log was not present/corrupted so could not be downloaded
B28: =B27+1 -> 38 | C28: Note Test reference:
B29: =B28+1 -> 39 | C29: Open Dignostic screen
B30: =B29+1 -> 40 | C30: on diagnostic screen Note Cycle count:
B31: =B30+1 -> 41 | C31: note reporting format
A32: FALSE | B32: =B31+1 -> 42 | D32: If NOT set to ISO, switch to ISO
B33: =B32+1 -> 43 | C33: Print detailed counts
B34: =B33+1 -> 44 | C34: Print test reference
B35: =B34+1 -> 45 | C35: auto print results
A36: FALSE | B36: =B35+1 -> 46 | D36: Set auto print to OFF
B37: =B36+1 -> 47 | C37: print space for notes
B38: =B37+1 -> 48 | C38: Language
B39: =B38+1 -> 49 | C39: Test type
A40: FALSE | B40: =B39+1 -> 50 | D40: Set to continuous
B41: =B40+1 -> 51 | C41: flush time 30 secs
...

Sheet DO NOT USE post cal
A1: Post Calibration Checks
A3: Part Number | H3: ='MP Calibration Certificate'!D17 -> 5.6mg/l RM8631b
A4: Serial Number | H4: ='MP Calibration Certificate'!D18 -> 63010074
A5: Customer | H5: ='Cover Service Sheet'!D6 -> 0
A6: Sales Order | H6: ='Cover Service Sheet'!D15 -> 0
A7: Works Order | H7: ='Cover Service Sheet'!D16 -> 0
A9: Op Number
A10: 1 | B10: Print 2 Calibration Certificates
A11: =A10+1 -> 2 | B11: LPA3 Calibration sheet 202.038 updated
A12: =A11+1 -> 3 | B12: Note LPA3 Firmware
A13: =A12+1 -> 4 | B13: Check Label is fitted and details correct
B14: ON LPA VIEW
B15: User Settings
A16: =A13+1 -> 5 | B16: Test number to 1
A17: =A16+1 -> 6 | B17: Format set to ISO4406
A18: =A17+1 -> 7 | B18: If W option fitted, box is available to tick
A19: =A18+1 -> 8 | B19: W option not selected
A20: =A19+1 -> 9 | B20: Simulated test box not ticked
A21: =A20+1 -> 10 | B21: Test Type: Normal
A22: =A21+1 -> 11 | B22: Flush time: 30s
A23: =A22+1 -> 12 | B23: Sample volume: 100ml
A24: =A23+1 -> 13 | B24: Identification: LPA3 - S/N - Firmware
A25: =A24+1 -> 14 | B25: Set Current Time
A26: =A25+1 -> 15 | B26: Calibrated - current date
A27: =A26+1 -> 16 | B27: Calibration Due | H27: =H26+365 -> 365
B28: System Settings
A29: =A27+1 -> 17 | B29: Check Thresholds are programmed on unit | I29: 4 | J29: 6 | K29: 14 | L29: 21 | M29: 25 | N29: 38 | O29: 50 | P29: 70
A30: =A29+1 -> 18 | B30: Check Thresholds are noted on calibration certificate | I30: =AUTO!B3 -> LPA3 NAVAIR | J30: =AUTO!B4 -> 63010074 | K30: =AUTO!B5 -> 9264 | L30: =AUTO!B6 -> 0 | M30: =AUTO!B7 -> LPA3 NAVAIR | N30: =AUTO!B8 -> 112 | O30: =AUTO!B9 -> 176 | P30: =AUTO!B10 -> 714
B31: Sensing Volume Parameters
A32: =A30+1 -> 19 | B32: Effective Slit Width - 68
A33: =A32+1 -> 20 | B33: Effective Slit Height - 160
A34: =A33+1 -> 21 | B34: Effective Channel Dept - 400
A35: =A34+1 -> 22 | B35: Bean Divergence - 0
B36: Test Cycle Control
A37: =A35+1 -> 23 | B37: Sampling Flow Rate ml/min - 100
A38: =A37+1 -> 24 | B38: Emptying Flow Rate - 100ml
A39: =A38+1 -> 25 | B39: Sample volume - 100ml
A40: =A39+1 -> 26 | B40: Auto Flush - 30 secs
B41: Experimental
A42: =A40+1 -> 27 | B42: Bubble Mitigation not ticked
...

Sheet Auto-Calibration record
B3: Pump | C3: Units
G4: Contamination Monitoring Product Calibration Record - CML4/CML3
B5: =VLOOKUP("pump_flow_emptying_ml_min",AUTO!$A$1:$B$1051,2,FALSE) -> 150 | C5: ml/min | D5: Pump Flow Emptying
B6: =VLOOKUP("pump_target_flow_ml_min",AUTO!$A$1:$B$1051,2,FALSE) -> 30 | C6: ml/min | D6: Pump Flow Sampling
B7: =VLOOKUP("pump_current_sampling",AUTO!$A$1:$B$1051,2,FALSE) -> 345 | C7: mA | D7: Pump current when sampling (mA)
B8: =VLOOKUP("pump_current_emptying",AUTO!$A$1:$B$1051,2,FALSE) -> 345 | C8: mA | D8: Pump current when emptying (mA) | H8: = Key detail | L8: Doc. No: 200.041
L9: Sheet 1
B10: LED | C10: Units | H10: = Locked cells | L10: DCRXXXX
B11: =VLOOKUP("no_noise_threshold",AUTO!$A$1:$B$1051,2,FALSE) -> 54 | C11: - | D11: Sensor "no noise" threshold | L11: Rev XXX
B12: =VLOOKUP("sample_volume_ml",AUTO!$A$1:$B$1051,2,FALSE) -> 40 | C12: ml | D12: Sample Volume | H12: = Manual Input
B14: =VLOOKUP("led_level",AUTO!$A$1:$B$1051,2,FALSE) -> 10000 | C14: nA | D14: Photocurrent | G14: CMP type | H14: 5.6mg/l RM8631b
G15: Serial Number | H15: =VLOOKUP("serial_number_",AUTO!$A$1:$B$1051,2,FALSE) -> 63010074
G16: Date | H16: =VLOOKUP("date_",AUTO!$A$1:$B$1051,2,FALSE) -> 46147.7
G17: Cert No. | H17: =H15&" "&TEXT(H16,"ddmmyy") -> 63010074 050526
G18: RM Batch | H18: RM8631b
G19: Test Rig No. | H19: =VLOOKUP("rig_param_identifier",AUTO!$A$1:$B$1051,2,FALSE) -> 304
G21: No noise count/100ml (must not exceed 500/100ml) | H21: =VLOOKUP("rig_cleanliness_count",AUTO!$A$1:$B$1051,2,FALSE) -> 0
B22: Calibration Rig | C22: Units
B23: =VLOOKUP("meas_init_level",AUTO!A13:B1063,2,FALSE) -> 0 | C23: mm | D23: Initial Fluid Distance
B24: =VLOOKUP("calc_init_volume",AUTO!$A$1:$B$1051,2,FALSE) -> 0 | C24: L | D24: Calculated Initial Fluid Volume
B25: =VLOOKUP("desired_concentration",AUTO!$A$1:$B$1051,2,FALSE) -> 16 | C25: mg/L | D25: Desired concentration
B26: =VLOOKUP("calc_qty_add",AUTO!$A$1:$B$1051,2,FALSE) -> 0 | C26: mg | D26: Required Qty of MTD to add | G26: Calibrated by | H26: John Devereux
B27: =VLOOKUP("meas_qty_add",AUTO!$A$1:$B$1051,2,FALSE) -> 0 | C27: mg | D27: Actual qty MTD added | G27: Chkd/verified by
B28: =VLOOKUP("meas_final_level",AUTO!$A$1:$B$1051,2,FALSE) -> 0 | C28: mm | D28: Final Fluid Level
B29: =VLOOKUP("calc_volume",AUTO!$A$1:$B$1051,2,FALSE) -> 0 | C29: L | D29: Calculated Final Fluid Volume
B30: =VLOOKUP("calc_concentration",AUTO!$A$1:$B$1051,2,FALSE) -> 16 | C30: mg/L | D30: Calculated final concentration
B63: Final Recommended Threshold Settings
B64: 4 | C64: 6 | D64: 14 | E64: 21 | F64: 25 | G64: 38 | H64: 50 | I64: 70 | J64: Particle Size Required (µm)
B65: =VLOOKUP("threshold0",AUTO!$A$1:$B$1051,2,FALSE) -> 112 | C65: =VLOOKUP("threshold1",AUTO!$A$1:$B$1051,2,FALSE) -> 176 | D65: =VLOOKUP("threshold2",AUTO!$A$1:$B$1051,2,FALSE) -> 714 | E65: =VLOOKUP("threshold3",AUTO!$A$1:$B$1051,2,FALSE) -> 1314 | F65: =VLOOKUP("threshold4",AUTO!$A$1:$B$1051,2,FALSE) -> 1794 | G65: =VLOOKUP("threshold5",AUTO!$A$1:$B$1051,2,FALSE) -> 4348 | H65: =VLOOKUP("threshold6",AUTO!$A$1:$B$1051,2,FALSE) -> 6298 | I65: =VLOOKUP("threshold7",AUTO!$A$1:$B$1051,2,FALSE) -> 14290 | J65: Combined Thresholds
A67: Test result | B67: Target | C67: 1 | D67: % Deviation 1 | I67: Average value
A68: 4 | B68: =VLOOKUP("reference_count_0",AUTO!$A$1:$B$1051,2,FALSE) -> 1037710 | C68: =VLOOKUP("verification_count_1_0",AUTO!$A$1:$B$1051,2,FALSE) -> 1047870 | D68: =(C68-B68)/B68 -> 0.0097907893 | I68: =(C68) -> 1047870 | J68: =(I68-$B68)/$B68 -> 0.0097907893
A69: 6 | B69: =VLOOKUP("reference_count_1",AUTO!$A$1:$B$1051,2,FALSE) -> 432580 | C69: =VLOOKUP("verification_count_1_1",AUTO!$A$1:$B$1051,2,FALSE) -> 431351 | D69: =(C69-B69)/B69 -> -0.002841093 | I69: =(C69) -> 431351 | J69: =(I69-$B69)/$B69 -> -0.002841093
A70: 10 | B70: =VLOOKUP("reference_count32_6",AUTO!$A$1:$B$1051,2,FALSE)*100 -> 97240 | C70: =VLOOKUP("verification_count32_1_6",AUTO!$A$1:$B$1051,2,FALSE)*100 -> 96948.1 | D70: =(C70-B70)/B70 -> -0.0030018511 | I70: =(C70) -> 96948.1 | J70: =(I70-$B70)/$B70 -> -0.0030018511
A71: 14 | B71: =VLOOKUP("reference_count_2",AUTO!$A$1:$B$1051,2,FALSE) -> 31970 | C71: =VLOOKUP("verification_count_1_2",AUTO!$A$1:$B$1051,2,FALSE) -> 32014 | D71: =(C71-B71)/B71 -> 0.0013762903 | I71: =(C71) -> 32014 | J71: =(I71-$B71)/$B71 -> 0.0013762903
A72: 21 | B72: =VLOOKUP("reference_count_3",AUTO!$A$1:$B$1051,2,FALSE) -> 9870 | C72: =VLOOKUP("verification_count_1_3",AUTO!$A$1:$B$1051,2,FALSE) -> 9858 | D72: =(C72-B72)/B72 -> -0.0012158055 | I72: =(C72) -> 9858 | J72: =(I72-$B72)/$B72 -> -0.0012158055
A73: 25 | B73: =VLOOKUP("reference_count_4",AUTO!$A$1:$B$1051,2,FALSE) -> 5300 | C73: =VLOOKUP("verification_count_1_4",AUTO!$A$1:$B$1051,2,FALSE) -> 5300 | D73: =(C73-B73)/B73 -> 0 | I73: =(C73) -> 5300 | J73: =(I73-$B73)/$B73 -> 0
A74: 38 | B74: =VLOOKUP("reference_count_5",AUTO!$A$1:$B$1051,2,FALSE) -> 1180 | C74: =VLOOKUP("verification_count_1_5",AUTO!$A$1:$B$1051,2,FALSE) -> 1181 | D74: =(C74-B74)/B74 -> 0.00084745763 | I74: =(C74) -> 1181 | J74: =(I74-$B74)/$B74 -> 0.00084745763
A75: 50 | B75: =VLOOKUP("reference_count_6",AUTO!$A$1:$B$1051,2,FALSE) -> 640 | C75: =VLOOKUP("verification_count_1_6",AUTO!$A$1:$B$1051,2,FALSE) -> 637 | D75: =(C75-B75)/B75 -> -0.0046875 | I75: =(C75) -> 637 | J75: =(I75-$B75)/$B75 -> -0.0046875
A76: 70 | B76: =VLOOKUP("reference_count_7",AUTO!$A$1:$B$1051,2,FALSE) -> 140 | C76: =VLOOKUP("verification_count_1_7",AUTO!$A$1:$B$1051,2,FALSE) -> 139 | D76: =(C76-B76)/B76 -> -0.0071428571 | I76: =(C76) -> 139 | J76: =(I76-$B76)/$B76 -> -0.0071428571

Sheet MP Calibration Certificate
B2: MP Filtri UK Ltd
B3: Keep House, Conference Way, Vale Park,
B4: Evesham
B5: England
B6: WR11 1LB
B7: Tel: +44 (0) 1386 258500
B8: www.mpfiltri.co.uk
B10: CERTIFICATE OF CALIBRATION
B13: WE HEREBY CERTIFY THAT THE CONTAMINATION MONITORING PRODUCT DETAILED BELOW HAS BEEN FULLY CALIBRATED WITH ISO MEDIUM TEST DUST (MTD) BASED ON ISO 11171:2020 ON TEST EQUIPMENT CERTIFIED TO ISO 11943 BY I.F.T.S {Institut de la Filtration et des Techniques Séparatives}.
B14: We hereby confirm that the above mentioned measuring system was calibrated according to DIN ISO 9001, under the observation of a certified quality assurance system. The measuring installation used for calibration are regularly calibrated to national standards by I.F.T.S. Should no national standards exist, the measuring procedure corresponds with the technical regulations and norms valid at the time of the measurement
B17: PRODUCT TYPE | D17: ='Auto-Calibration record'!H14 -> 5.6mg/l RM8631b | K17: REFERENCE MATERIAL BATCH NUMBER | O17: ='Auto-Calibration record'!H18 -> RM8631b
B18: SERIAL NUMBER | D18: ='Auto-Calibration record'!H15 -> 63010074 | K18: DATE OF CALIBRATION | O18: ='Auto-Calibration record'!H16 -> 46147.7
B19: CERTIFICATE NUMBER | D19: ='Auto-Calibration record'!H17 -> 63010074 050526 | K19: CALIBRATION RIG NUMBER | O19: ='Auto-Calibration record'!H19 -> 304
B21: PARTICLE COUNT LIMITS AT 16mg/L CONCENTRATION
B22: (Suspension of ISO MTD in MIL-H-5606)
B23: No. particles reported per 100ml volume
D26: Particle Size | F26: Calibration Pulse Height | H26: Target Particle Count | J26: Actual Particle Count | K26: Deviation | L26: % Deviation (+/- 10%)
D27: [microns (c)] | F27: [mV] | H27: [n] | J27: [n] | K27: [n] | L27: [%]
D28: >4 | F28: ='Auto-Calibration record'!B65 -> 112 | H28: ='Auto-Calibration record'!B68 -> 1037710 | J28: ='Auto-Calibration record'!I68 -> 1047870 | K28: =J28-H28 -> 10160 | L28: =K28/H28 -> 0.0097907893
D29: >6 | F29: ='Auto-Calibration record'!C65 -> 176 | H29: ='Auto-Calibration record'!B69 -> 432580 | J29: ='Auto-Calibration record'!I69 -> 431351 | K29: =J29-H29 -> -1229 | L29: =K29/H29 -> -0.002841093
D30: >14 | F30: ='Auto-Calibration record'!D65 -> 714 | H30: ='Auto-Calibration record'!B71 -> 31970 | J30: ='Auto-Calibration record'!I71 -> 32014 | K30: =J30-H30 -> 44 | L30: =K30/H30 -> 0.0013762903
D31: >21 | F31: ='Auto-Calibration record'!E65 -> 1314 | H31: ='Auto-Calibration record'!B72 -> 9870 | J31: ='Auto-Calibration record'!I72 -> 9858 | K31: =J31-H31 -> -12 | L31: =K31/H31 -> -0.0012158055
D32: >25 | F32: ='Auto-Calibration record'!F65 -> 1794 | H32: ='Auto-Calibration record'!B73 -> 5300 | J32: ='Auto-Calibration record'!I73 -> 5300 | K32: =J32-H32 -> 0 | L32: =K32/H32 -> 0
D33: >38 | F33: ='Auto-Calibration record'!G65 -> 4348 | H33: ='Auto-Calibration record'!B74 -> 1180 | J33: ='Auto-Calibration record'!I74 -> 1181 | K33: =J33-H33 -> 1 | L33: =K33/H33 -> 0.00084745763
D34: >**50 | F34: ='Auto-Calibration record'!H65 -> 6298 | H34: ='Auto-Calibration record'!B75 -> 640 | J34: ='Auto-Calibration record'!I75 -> 637 | K34: - | L34: -
D35: >**70 | F35: ='Auto-Calibration record'!I65 -> 14290 | H35: ='Auto-Calibration record'!B76 -> 140 | J35: ='Auto-Calibration record'!I76 -> 139 | K35: - | L35: -
D36: **These particle sizes are not yet certified by NIST
D38: LS1 No Noise Threshold | E38: LS1 Threshold Sensitivity | G38: Sensitivity Threshold Ratio
D39: [mV] | E39: [mV] | G39: [-]
D40: ='Auto-Calibration record'!B11 -> 54 | E40: =F28-D40 -> 58 | G40: =F28/D40 -> 2.0740741
B72: CALIBRATION RESULT | D72: PASS | K72: PASS - VERIFIED
B74: RE-CALIBRATION DUE | D74: 1 YEAR FROM FIRST USE
B76: CALIBRATED BY | D76: ='Auto-Calibration record'!H26 -> John Devereux | K76: Position | L76: Calibration Lab Technician
B78: Newly purchased products are covered under warranty for 12 months from first use
B79: Products being returned for re-calibration are verified for accuracy for a further 12 months. This does not extend the warranty.
B80: Customers are responsible for managing the intervals between calibration's as defined within IS0 9001:2000
O83: Doc No. 200.XXX
B84: MP Filtri UK Ltd | O84: Sheet 1
B85: Bourton on the Water Industrial Park | O85: DCRXXXX
B86: Gloucestershire | O86: Rev 0
...

Sheet Packing Check List

Sheet LasPaCII (Stauff) Cal Cert
A2: Walter Stauffenberg
A3: GmbH & Co. KG
A5: Im Ehrenfeld 4 | C5: D-58791 Werdohl | E5: Telefon +49 (0) 2392 916-0
C6: CALIBRATION CERTIFICATE
B8: Carried out by: | D8: Walter Stauffenberg GmbH & Co. KG
D9: Im Ehrenfeld 4
D10: 58791 Werdohl
D11: Germany
B13: Certificate No.: | D13: 20 | E13: ='Auto-Calibration record'!J17 -> 0 | F13: ="0"&('Auto-Calibration record'!H15-200000) -> 062810074
B14: Description of probe: | D14: ='Auto-Calibration record'!H14 -> 5.6mg/l RM8631b
B15: Serial No.: | D15: 20 | E15: =F13 -> 062810074
B17: We hereby confirm that the above mentioned measuring system was calibrated according to DIN ISO 9001, under the observation of a certified quality assurance system. The measuring installation used for calibration are regularly calibrated and are based on the national standards ISO 11171:2010 and other national standards.
B18: Should no national standards exist, the measuring procedure corresponds with the technical regulations and norms valid at the time of the measurement.
B20: The documents established for this procedure are available for viewing. All the necessary measured data can be found on the following page of this calibration certificate.
B22: Special remarks
B25: Date of calibration: | D25: ='Auto-Calibration record'!H16 -> 46147.7 | G25: Processed by J Clay
G29: (Laboratory Engineer)
A30: (The LasPaCII unit is certified for 12 months after date of sale to end-customer from first use)
A32: Walter Stauffenberg
A33: GmbH & Co. KG
A35: Im Ehrenfeld 4 | C35: D-58791 Werdohl | E35: Telefon +49 (0) 2392 916-0
C36: CALIBRATION CERTIFICATE
A39: TESTING EQUIPMENT
C41: Particle Counter | E41: ='Auto-Calibration record'!H14 -> 5.6mg/l RM8631b
C42: Ser.No.: | E42: 20 | F42: =E15 -> 062810074
C43: Pressure Mode | E43: Low Pressure
C44: Noise (Laser1) | E44: ='Auto-Calibration record'!B17 -> 0
C45: Noise (Laser2) | E45: ='Auto-Calibration record'!B11 -> 54
C46: Size Range | E46: 4 - 70um(c)
C47: Flow rate | E47: 6ml/min
A49: The ISO MTD - Calibration was performaned with 16mg/l ISO MTD in MIL-H-5606 according to ISO 11171
A52: CALIBRATION PERFORMANCE
B54: Max. Deviation: ± 10%
B55: Particle Size | C55: Calibration Pulse Height | D55: Nominal | F55: Actual | G55: Deviation | H55: Deviation
B56: [um (c)] | C56: [mV] | D56: [Particle / 16ml] | F56: [Particle / 16ml] | G56: [Particle / 16ml] | H56: [%]
B57: 4 | C57: ='Auto-Calibration record'!B65 -> 112 | D57: ='Auto-Calibration record'!B68 -> 1037710 | F57: ='Auto-Calibration record'!I68 -> 1047870 | G57: =F57-D57 -> 10160 | H57: =G57/D57 -> 0.0097907893
B58: 6 | C58: ='Auto-Calibration record'!C65 -> 176 | D58: ='Auto-Calibration record'!B69 -> 432580 | F58: ='Auto-Calibration record'!I69 -> 431351 | G58: =F58-D58 -> -1229 | H58: =G58/D58 -> -0.002841093
B59: 14 | C59: ='Auto-Calibration record'!D65 -> 714 | D59: ='Auto-Calibration record'!B71 -> 31970 | F59: ='Auto-Calibration record'!I71 -> 32014 | G59: =F59-D59 -> 44 | H59: =G59/D59 -> 0.0013762903
B60: 21 | C60: ='Auto-Calibration record'!E65 -> 1314 | D60: ='Auto-Calibration record'!B72 -> 9870 | F60: ='Auto-Calibration record'!I72 -> 9858 | G60: =F60-D60 -> -12 | H60: =G60/D60 -> -0.0012158055
B61: 25 | C61: ='Auto-Calibration record'!F65 -> 1794 | D61: ='Auto-Calibration record'!B73 -> 5300 | F61: ='Auto-Calibration record'!I73 -> 5300 | G61: =F61-D61 -> 0 | H61: =G61/D61 -> 0
...

Sheet ACE Winches
B2: MP Filtri UK Ltd
B3: Bourton on the Water Industrial Park
B4: Gloucestershire
B5: England
B6: GL54 2HQ
B7: Tel: +44 (0) 1451 822522
B8: www.mpfiltri.co.uk
B10: CERTIFICATE OF CALIBRATION
B13: WE HEREBY CERTIFY THAT THE CONTAMINATION MONITORING PRODUCT DETAILED BELOW HAS BEEN FULLY CALIBRATED WITH ISO MEDIUM TEST DUST (MTD) BASED ON ISO 11171 ON TEST EQUIPMENT CERTIFIED TO ISO 11943 BY I.F.T.S {Institut de la Filtration et des Techniques Séparatives}.
B14: We hereby confirm that the above mentioned measuring system was calibrated according to DIN ISO 9001, under the observation of a certified quality assurance system. The measuring installation used for calibration are regularly calibrated to national standards by I.F.T.S. Should no national standards exist, the measuring procedure corresponds with the technical regulations and norms valid at the time of the measurement
B17: PRODUCT TYPE | D17: ='Auto-Calibration record'!H14 -> 5.6mg/l RM8631b | K17: MEDIUM TEST DUST BATCH NUMBER | O17: ='Auto-Calibration record'!H18 -> RM8631b
B18: SERIAL NUMBER | D18: ='Auto-Calibration record'!#REF!&'Auto-Calibration record'!H15 -> #REF! | K18: DATE OF CALIBRATION | O18: ='Auto-Calibration record'!H16 -> 46147.7
B19: CERTIFICATE NUMBER | D19: ='Auto-Calibration record'!H17 -> 63010074 050526 | K19: CALIBRATION RIG NUMBER | O19: ='Auto-Calibration record'!H19 -> 304
D21: ID NO. | E21: DESCRIPTION | G21: Manufacturer / Supplier | I21: Serial No.
D22: ACE 1999 | E22: PARTICLE COUNTER | G22: MP FILTRI | I22: 5226
D23: ACE 2048 | E23: PARTICLE COUNTER | G23: MP FILTRI | I23: 5306
D24: ACE 2625 | E24: PARTICLE COUNTER | G24: MP FILTRI | I24: 5326
D25: ACE 3614 | E25: PARTICLE COUNTER | G25: MP FILTRI | I25: 5529
B27: PARTICLE COUNT LIMITS AT 16mg/L CONCENTRATION
B28: (Suspension of ISO MTD in MIL-H-5606)
B29: No. particles reported per 100ml volume
D32: Particle Size | F32: Calibration Pulse Height | H32: Target Particle Count | J32: Actual Particle Count | K32: Deviation | L32: % Deviation (+/- 10%)
D33: [microns (c)] | F33: [mV] | H33: [n] | J33: [n] | K33: [n] | L33: [%]
D34: >4 | F34: ='Auto-Calibration record'!B65 -> 112 | H34: ='Auto-Calibration record'!B68 -> 1037710 | J34: ='Auto-Calibration record'!I68 -> 1047870 | K34: =J34-H34 -> 10160 | L34: =K34/H34 -> 0.0097907893
D35: >6 | F35: ='Auto-Calibration record'!C65 -> 176 | H35: ='Auto-Calibration record'!B69 -> 432580 | J35: ='Auto-Calibration record'!I69 -> 431351 | K35: =J35-H35 -> -1229 | L35: =K35/H35 -> -0.002841093
D36: >14 | F36: ='Auto-Calibration record'!D65 -> 714 | H36: ='Auto-Calibration record'!B71 -> 31970 | J36: ='Auto-Calibration record'!I71 -> 32014 | K36: =J36-H36 -> 44 | L36: =K36/H36 -> 0.0013762903
D37: >21 | F37: ='Auto-Calibration record'!E65 -> 1314 | H37: ='Auto-Calibration record'!B72 -> 9870 | J37: ='Auto-Calibration record'!I72 -> 9858 | K37: =J37-H37 -> -12 | L37: =K37/H37 -> -0.0012158055
D38: >25 | F38: ='Auto-Calibration record'!F65 -> 1794 | H38: ='Auto-Calibration record'!B73 -> 5300 | J38: ='Auto-Calibration record'!I73 -> 5300 | K38: =J38-H38 -> 0 | L38: =K38/H38 -> 0
D39: >38 | F39: ='Auto-Calibration record'!G65 -> 4348 | H39: ='Auto-Calibration record'!B74 -> 1180 | J39: ='Auto-Calibration record'!I74 -> 1181 | K39: =J39-H39 -> 1 | L39: =K39/H39 -> 0.00084745763
D40: >**50 | F40: ='Auto-Calibration record'!H65 -> 6298 | H40: ='Auto-Calibration record'!B75 -> 640 | J40: ='Auto-Calibration record'!I75 -> 637 | K40: - | L40: -
D41: >**70 | F41: ='Auto-Calibration record'!I65 -> 14290 | H41: ='Auto-Calibration record'!B76 -> 140 | J41: ='Auto-Calibration record'!I76 -> 139 | K41: - | L41: -
D42: **These particle sizes are not yet certified by NIST
D44: LS1 No Noise Threshold | E44: LS1 Threshold Sensitivity | G44: Sensitivity Threshold Ratio | J44: LS2 No Noise Threshold | K44: LS2 Threshold Sensitivity | L44: Sensitivity Threshold Ratio
D45: [mV] | E45: [mV] | G45: [-] | J45: [mV] | K45: [mV] | L45: [-]
D46: ='Auto-Calibration record'!B17 -> 0 | E46: =F34-D46 -> 112 | G46: =F34/D46 -> #DIV/0! | J46: ='Auto-Calibration record'!B11 -> 54 | K46: =F35-J46 -> 122 | L46: =F35/J46 -> 3.2592593
B78: CALIBRATION RESULT | D78: PASS | K78: PASS - VERIFIED
B80: RE-CALIBRATION DUE | D80: 1 YEAR FROM FIRST USE
B82: CALIBRATED BY | K82: Position | L82: Calibration Lab Technician
B84: Newly purchased products are covered under warranty for 12 months from first use
B85: Products being returned for re-calibration are verified for accuracy for a further 12 months. This does not extend the warranty.
...

Sheet Solge
B2: MP Filtri UK Ltd
B3: Bourton on the Water Industrial Park
B4: Gloucestershire
B5: England
B6: GL54 2HQ
B7: Tel: +44 (0) 1451 822522
B8: www.mpfiltri.co.uk
B10: CERTIFICATE OF CALIBRATION
B13: WE HEREBY CERTIFY THAT THE CONTAMINATION MONITORING PRODUCT DETAILED BELOW HAS BEEN FULLY CALIBRATED WITH ISO MEDIUM TEST DUST (MTD) BASED ON ISO 11171:2010 ON TEST EQUIPMENT CERTIFIED TO ISO 11943 BY I.F.T.S {Institut de la Filtration et des Techniques Séparatives}.
B14: We hereby confirm that the above mentioned measuring system was calibrated according to DIN ISO 9001, under the observation of a certified quality assurance system. The measuring installation used for calibration are regularly calibrated to national standards by I.F.T.S. Should no national standards exist, the measuring procedure corresponds with the technical regulations and norms valid at the time of the measurement
B17: PRODUCT TYPE | D17: ='Auto-Calibration record'!H14 -> 5.6mg/l RM8631b | K17: MEDIUM TEST DUST BATCH NUMBER | O17: ='Auto-Calibration record'!H18 -> RM8631b
B18: SERIAL NUMBER | D18: ='Auto-Calibration record'!#REF!&'Auto-Calibration record'!H15 -> #REF! | K18: DATE OF CALIBRATION | O18: ='Auto-Calibration record'!H16 -> 46147.7
B19: CERTIFICATE NUMBER | D19: ='Auto-Calibration record'!H17 -> 63010074 050526 | K19: CALIBRATION RIG NUMBER | O19: ='Auto-Calibration record'!H19 -> 304
B21: PARTICLE COUNT LIMITS AT 16mg/L CONCENTRATION
B22: (Suspension of ISO MTD in MIL-H-5606)
B23: No. particles reported per 100ml volume
D26: Particle Size | F26: Calibration Pulse Height | H26: Target Particle Count | J26: Actual Particle Count | K26: Deviation | L26: % Deviation (+/- 10%)
D27: [microns (c)] | F27: [mV] | H27: [n] | J27: [n] | K27: [n] | L27: [%]
D28: >4 | F28: ='Auto-Calibration record'!B65 -> 112 | H28: ='Auto-Calibration record'!B68 -> 1037710 | J28: ='Auto-Calibration record'!I68 -> 1047870 | K28: =J28-H28 -> 10160 | L28: =K28/H28 -> 0.0097907893
D29: >6 | F29: ='Auto-Calibration record'!C65 -> 176 | H29: ='Auto-Calibration record'!B69 -> 432580 | J29: ='Auto-Calibration record'!I69 -> 431351 | K29: =J29-H29 -> -1229 | L29: =K29/H29 -> -0.002841093
D30: >14 | F30: ='Auto-Calibration record'!D65 -> 714 | H30: ='Auto-Calibration record'!B71 -> 31970 | J30: ='Auto-Calibration record'!I71 -> 32014 | K30: =J30-H30 -> 44 | L30: =K30/H30 -> 0.0013762903
D31: >21 | F31: ='Auto-Calibration record'!E65 -> 1314 | H31: ='Auto-Calibration record'!B72 -> 9870 | J31: ='Auto-Calibration record'!I72 -> 9858 | K31: =J31-H31 -> -12 | L31: =K31/H31 -> -0.0012158055
D32: >25 | F32: ='Auto-Calibration record'!F65 -> 1794 | H32: ='Auto-Calibration record'!B73 -> 5300 | J32: ='Auto-Calibration record'!I73 -> 5300 | K32: =J32-H32 -> 0 | L32: =K32/H32 -> 0
D33: >38 | F33: ='Auto-Calibration record'!G65 -> 4348 | H33: ='Auto-Calibration record'!B74 -> 1180 | J33: ='Auto-Calibration record'!I74 -> 1181 | K33: =J33-H33 -> 1 | L33: =K33/H33 -> 0.00084745763
D34: >**50 | F34: ='Auto-Calibration record'!H65 -> 6298 | H34: ='Auto-Calibration record'!B75 -> 640 | J34: ='Auto-Calibration record'!I75 -> 637 | K34: - | L34: -
D35: >**70 | F35: ='Auto-Calibration record'!I65 -> 14290 | H35: ='Auto-Calibration record'!B76 -> 140 | J35: ='Auto-Calibration record'!I76 -> 139 | K35: - | L35: -
D36: **These particle sizes are not yet certified by NIST
D38: LS1 No Noise Threshold | E38: LS1 Threshold Sensitivity | G38: Sensitivity Threshold Ratio | J38: LS2 No Noise Threshold | K38: LS2 Threshold Sensitivity | L38: Sensitivity Threshold Ratio
D39: [mV] | E39: [mV] | G39: [-] | J39: [mV] | K39: [mV] | L39: [-]
D40: ='Auto-Calibration record'!B17 -> 0 | E40: =F28-D40 -> 112 | G40: =F28/D40 -> #DIV/0! | J40: ='Auto-Calibration record'!B11 -> 54 | K40: =F29-J40 -> 122 | L40: =F29/J40 -> 3.2592593
B72: CALIBRATION RESULT | D72: PASS | K72: PASS - VERIFIED
B74: RE-CALIBRATION DUE | D74: 1 YEAR FROM FIRST USE
B76: CALIBRATED BY | K76: Position | L76: Calibration Lab Technician
B78: Newly purchased products are covered under warranty for 12 months from first use
B79: Products being returned for re-calibration are verified for accuracy for a further 12 months. This does not extend the warranty.
B80: Customers are responsible for managing the intervals between calibration's as defined within IS0 9001:2000
O83: Doc No. 200.XXX
O84: Sheet 1
O85: DCRXXXX
B86: Page 1 of 1 | O86: Rev 0

Sheet PLPC (RMF) Cal Cert
B10: CERTIFICATE OF CALIBRATION
B13: WE HEREBY CERTIFY THAT THE CONTAMINATION MONITORING PRODUCT DETAILED BELOW HAS BEEN FULLY CALIBRATED WITH ISO MEDIUM TEST DUST (MTD) BASED ON ISO 11171:2010 ON TEST EQUIPMENT CERTIFIED TO ISO 11943 BY I.F.T.S {Institut de la Filtration et des Techniques Séparatives}.
B14: We hereby confirm that the above mentioned measuring system was calibrated according to DIN ISO 9001, under the observation of a certified quality assurance system. The measuring installation used for calibration are regularly calibrated to national standards by I.F.T.S. Should no national standards exist, the measuring procedure corresponds with the technical regulations and norms valid at the time of the measurement
B17: PRODUCT TYPE | D17: ='Auto-Calibration record'!H14 -> 5.6mg/l RM8631b | K17: MEDIUM TEST DUST BATCH NUMBER | O17: ='Auto-Calibration record'!H18 -> RM8631b
B18: SERIAL NUMBER | D18: ='Auto-Calibration record'!#REF!&'Auto-Calibration record'!H15 -> #REF! | K18: DATE OF CALIBRATION | O18: ='Auto-Calibration record'!H16 -> 46147.7
B19: CERTIFICATE NUMBER | D19: ='Auto-Calibration record'!H17 -> 63010074 050526 | K19: CALIBRATION RIG NUMBER | O19: ='Auto-Calibration record'!H19 -> 304
B21: PARTICLE COUNT LIMITS AT 16mg/L CONCENTRATION
B22: (Suspension of ISO MTD in MIL-H-5606)
B23: No. particles reported per 100ml volume
D26: Particle Size | F26: Calibration Pulse Height | H26: Target Particle Count | J26: Actual Particle Count | K26: Deviation | L26: % Deviation (+/- 10%)
D27: [microns (c)] | F27: [mV] | H27: [n] | J27: [n] | K27: [n] | L27: [%]
D28: >4 | F28: ='Auto-Calibration record'!B65 -> 112 | H28: ='Auto-Calibration record'!B68 -> 1037710 | J28: ='Auto-Calibration record'!I68 -> 1047870 | K28: =J28-H28 -> 10160 | L28: =K28/H28 -> 0.0097907893
D29: >6 | F29: ='Auto-Calibration record'!C65 -> 176 | H29: ='Auto-Calibration record'!B69 -> 432580 | J29: ='Auto-Calibration record'!I69 -> 431351 | K29: =J29-H29 -> -1229 | L29: =K29/H29 -> -0.002841093
D30: >14 | F30: ='Auto-Calibration record'!D65 -> 714 | H30: ='Auto-Calibration record'!B71 -> 31970 | J30: ='Auto-Calibration record'!I71 -> 32014 | K30: =J30-H30 -> 44 | L30: =K30/H30 -> 0.0013762903
D31: >21 | F31: ='Auto-Calibration record'!E65 -> 1314 | H31: ='Auto-Calibration record'!B72 -> 9870 | J31: ='Auto-Calibration record'!I72 -> 9858 | K31: =J31-H31 -> -12 | L31: =K31/H31 -> -0.0012158055
D32: >25 | F32: ='Auto-Calibration record'!F65 -> 1794 | H32: ='Auto-Calibration record'!B73 -> 5300 | J32: ='Auto-Calibration record'!I73 -> 5300 | K32: =J32-H32 -> 0 | L32: =K32/H32 -> 0
D33: >38 | F33: ='Auto-Calibration record'!G65 -> 4348 | H33: ='Auto-Calibration record'!B74 -> 1180 | J33: ='Auto-Calibration record'!I74 -> 1181 | K33: =J33-H33 -> 1 | L33: =K33/H33 -> 0.00084745763
D34: >**50 | F34: ='Auto-Calibration record'!H65 -> 6298 | H34: ='Auto-Calibration record'!B75 -> 640 | J34: ='Auto-Calibration record'!I75 -> 637 | K34: - | L34: -
D35: >**70 | F35: ='Auto-Calibration record'!I65 -> 14290 | H35: ='Auto-Calibration record'!B76 -> 140 | J35: ='Auto-Calibration record'!I76 -> 139 | K35: - | L35: -
D36: **These particle sizes are not yet certified by NIST
D38: LS1 No Noise Threshold | E38: LS1 Threshold Sensitivity | G38: Sensitivity Threshold Ratio | J38: LS2 No Noise Threshold | K38: LS2 Threshold Sensitivity | L38: Sensitivity Threshold Ratio
D39: [mV] | E39: [mV] | G39: [-] | J39: [mV] | K39: [mV] | L39: [-]
D40: ='Auto-Calibration record'!B17 -> 0 | E40: =F28-D40 -> 112 | G40: =F28/D40 -> #DIV/0! | J40: ='Auto-Calibration record'!B11 -> 54 | K40: =F29-J40 -> 122 | L40: =F29/J40 -> 3.2592593
B72: CALIBRATION RESULT | D72: PASS | K72: PASS - VERIFIED
B74: RE-CALIBRATION DUE | D74: 1 YEAR FROM FIRST USE
B76: CALIBRATED BY | K76: Position | L76: Calibration Lab Technician
B78: Newly purchased products are covered under warranty for 12 months from first use
B79: Products being returned for re-calibration are verified for accuracy for a further 12 months. This does not extend the warranty.
B80: Customers are responsible for managing the intervals between calibration's as defined within IS0 9001:2000
O83: Doc No. 200.XXX
O84: Sheet 1
O85: DCRXXXX
B86: Page 1 of 1 | O86: Rev 0

Sheet Dutch Holding Cal Cert
B2: MP Filtri UK Ltd
B3: Bourton on the Water Industrial Park
B4: Gloucestershire
B5: England
B6: GL54 2HQ
B7: Tel: +44 (0) 1451 822522
B8: www.mpfiltri.co.uk
B10: CERTIFICATE OF CALIBRATION
B13: WE HEREBY CERTIFY THAT THE CONTAMINATION MONITORING PRODUCT DETAILED BELOW HAS BEEN FULLY CALIBRATED WITH ISO MEDIUM TEST DUST (MTD) BASED ON ISO 11171 ON TEST EQUIPMENT CERTIFIED TO ISO 11943 BY I.F.T.S {Institut de la Filtration et des Techniques Séparatives}.
B14: We hereby confirm that the above mentioned measuring system was calibrated according to DIN ISO 9001, under the observation of a certified quality assurance system. The measuring installation used for calibration are regularly calibrated to national standards by I.F.T.S. Should no national standards exist, the measuring procedure corresponds with the technical regulations and norms valid at the time of the measurement
B17: PRODUCT TYPE | D17: ='Auto-Calibration record'!H14 -> 5.6mg/l RM8631b | K17: MEDIUM TEST DUST BATCH NUMBER | O17: ='Auto-Calibration record'!H18 -> RM8631b
B18: SERIAL NUMBER | D18: ='Auto-Calibration record'!#REF!&'Auto-Calibration record'!H15 -> #REF! | K18: DATE OF CALIBRATION | O18: ='Auto-Calibration record'!H16 -> 46147.7
B19: CERTIFICATE NUMBER | D19: ='Auto-Calibration record'!H17 -> 63010074 050526 | K19: CALIBRATION RIG NUMBER | O19: ='Auto-Calibration record'!H19 -> 304
B21: PARTICLE COUNT LIMITS AT 16mg/L CONCENTRATION
B22: (Suspension of ISO MTD in MIL-H-5606)
B23: No. particles reported per 100ml volume
D26: Particle Size | F26: Calibration Pulse Height | H26: Target Particle Count | J26: Actual Particle Count | K26: Deviation | L26: % Deviation (+/- 10%)
D27: [microns (c)] | F27: [mV] | H27: [n] | J27: [n] | K27: [n] | L27: [%]
D28: >4 | F28: ='Auto-Calibration record'!B65 -> 112 | H28: ='Auto-Calibration record'!B68 -> 1037710 | J28: ='Auto-Calibration record'!I68 -> 1047870 | K28: =J28-H28 -> 10160 | L28: =K28/H28 -> 0.0097907893
D29: >6 | F29: ='Auto-Calibration record'!C65 -> 176 | H29: ='Auto-Calibration record'!B69 -> 432580 | J29: ='Auto-Calibration record'!I69 -> 431351 | K29: =J29-H29 -> -1229 | L29: =K29/H29 -> -0.002841093
D30: >14 | F30: ='Auto-Calibration record'!D65 -> 714 | H30: ='Auto-Calibration record'!B71 -> 31970 | J30: ='Auto-Calibration record'!I71 -> 32014 | K30: =J30-H30 -> 44 | L30: =K30/H30 -> 0.0013762903
D31: >21 | F31: ='Auto-Calibration record'!E65 -> 1314 | H31: ='Auto-Calibration record'!B72 -> 9870 | J31: ='Auto-Calibration record'!I72 -> 9858 | K31: =J31-H31 -> -12 | L31: =K31/H31 -> -0.0012158055
D32: >25 | F32: ='Auto-Calibration record'!F65 -> 1794 | H32: ='Auto-Calibration record'!B73 -> 5300 | J32: ='Auto-Calibration record'!I73 -> 5300 | K32: =J32-H32 -> 0 | L32: =K32/H32 -> 0
D33: >38 | F33: ='Auto-Calibration record'!G65 -> 4348 | H33: ='Auto-Calibration record'!B74 -> 1180 | J33: ='Auto-Calibration record'!I74 -> 1181 | K33: =J33-H33 -> 1 | L33: =K33/H33 -> 0.00084745763
D34: >**50 | F34: ='Auto-Calibration record'!H65 -> 6298 | H34: ='Auto-Calibration record'!B75 -> 640 | J34: ='Auto-Calibration record'!I75 -> 637 | K34: - | L34: -
D35: >**70 | F35: ='Auto-Calibration record'!I65 -> 14290 | H35: ='Auto-Calibration record'!B76 -> 140 | J35: ='Auto-Calibration record'!I76 -> 139 | K35: - | L35: -
D36: **These particle sizes are not yet certified by NIST
D38: LS1 No Noise Threshold | E38: LS1 Threshold Sensitivity | G38: Sensitivity Threshold Ratio | J38: LS2 No Noise Threshold | K38: LS2 Threshold Sensitivity | L38: Sensitivity Threshold Ratio
D39: [mV] | E39: [mV] | G39: [-] | J39: [mV] | K39: [mV] | L39: [-]
D40: ='Auto-Calibration record'!B17 -> 0 | E40: =F28-D40 -> 112 | G40: =F28/D40 -> #DIV/0! | J40: ='Auto-Calibration record'!B11 -> 54 | K40: =F29-J40 -> 122 | L40: =F29/J40 -> 3.2592593
B72: CALIBRATION RESULT | D72: PASS | K72: PASS - VERIFIED
B74: RE-CALIBRATION DUE | D74: 1 YEAR FROM FIRST USE
B76: CALIBRATED BY | K76: Position | L76: Calibration Lab Technician
B78: Newly purchased products are covered under warranty for 12 months from first use | J78: MP Filtri Distributor: Dutch Holding | M78: Asesorias Y Tecnologia Industrial S.A
B79: Products being returned for re-calibration are verified for accuracy for a further 12 months. This does not extend the warranty. | M79: VDA Del Parque 4680A OF.401
B80: Customers are responsible for managing the intervals between calibration's as defined within IS0 9001:2000 | M80: Ciudad Empresarial Huechuraba
M81: Santiago - Chile
O83: Doc No. 200.XXX
O84: Sheet 1
O85: DCRXXXX
...

Sheet Blank Cal Cert (EatonWearcheck)
B10: CERTIFICATE OF CALIBRATION
B13: WE HEREBY CERTIFY THAT THE CONTAMINATION MONITORING PRODUCT DETAILED BELOW HAS BEEN FULLY CALIBRATED WITH ISO MEDIUM TEST DUST (MTD) BASED ON ISO 11171:2010 ON TEST EQUIPMENT CERTIFIED TO ISO 11943 BY I.F.T.S {Institut de la Filtration et des Techniques Séparatives}.
B14: We hereby confirm that the above mentioned measuring system was calibrated according to DIN ISO 9001, under the observation of a certified quality assurance system. The measuring installation used for calibration are regularly calibrated to national standards by I.F.T.S. Should no national standards exist, the measuring procedure corresponds with the technical regulations and norms valid at the time of the measurement
B17: PRODUCT TYPE | D17: ='Auto-Calibration record'!H14 -> 5.6mg/l RM8631b | K17: MEDIUM TEST DUST BATCH NUMBER | O17: ='Auto-Calibration record'!H18 -> RM8631b
B18: SERIAL NUMBER | D18: ='Auto-Calibration record'!#REF!&'Auto-Calibration record'!H15 -> #REF! | K18: DATE OF CALIBRATION | O18: ='Auto-Calibration record'!H16 -> 46147.7
B19: CERTIFICATE NUMBER | D19: ='Auto-Calibration record'!H17 -> 63010074 050526 | K19: CALIBRATION RIG NUMBER | O19: ='Auto-Calibration record'!H19 -> 304
B21: PARTICLE COUNT LIMITS AT 16mg/L CONCENTRATION
B22: (Suspension of ISO MTD in MIL-H-5606)
B23: No. particles reported per 100ml volume
D26: Particle Size | F26: Calibration Pulse Height | H26: Target Particle Count | J26: Actual Particle Count | K26: Deviation | L26: % Deviation (+/- 10%)
D27: [microns (c)] | F27: [mV] | H27: [n] | J27: [n] | K27: [n] | L27: [%]
D28: >4 | F28: ='Auto-Calibration record'!B65 -> 112 | H28: ='Auto-Calibration record'!B68 -> 1037710 | J28: ='MP Calibration Certificate'!J28 -> 1047870 | K28: =J28-H28 -> 10160 | L28: =K28/H28 -> 0.0097907893
D29: >6 | F29: ='Auto-Calibration record'!C65 -> 176 | H29: ='Auto-Calibration record'!B69 -> 432580 | J29: ='MP Calibration Certificate'!J29 -> 431351 | K29: =J29-H29 -> -1229 | L29: =K29/H29 -> -0.002841093
D30: >14 | F30: ='Auto-Calibration record'!D65 -> 714 | H30: ='Auto-Calibration record'!B71 -> 31970 | J30: ='MP Calibration Certificate'!J30 -> 32014 | K30: =J30-H30 -> 44 | L30: =K30/H30 -> 0.0013762903
D31: >21 | F31: ='Auto-Calibration record'!E65 -> 1314 | H31: ='Auto-Calibration record'!B72 -> 9870 | J31: ='MP Calibration Certificate'!J31 -> 9858 | K31: =J31-H31 -> -12 | L31: =K31/H31 -> -0.0012158055
D32: >25 | F32: ='Auto-Calibration record'!F65 -> 1794 | H32: ='Auto-Calibration record'!B73 -> 5300 | J32: ='MP Calibration Certificate'!J32 -> 5300 | K32: =J32-H32 -> 0 | L32: =K32/H32 -> 0
D33: >38 | F33: ='Auto-Calibration record'!G65 -> 4348 | H33: ='Auto-Calibration record'!B74 -> 1180 | J33: ='MP Calibration Certificate'!J33 -> 1181 | K33: =J33-H33 -> 1 | L33: =K33/H33 -> 0.00084745763
D34: >**50 | F34: ='Auto-Calibration record'!H65 -> 6298 | H34: ='Auto-Calibration record'!B75 -> 640 | J34: ='MP Calibration Certificate'!J34 -> 637 | K34: - | L34: -
D35: >**70 | F35: ='Auto-Calibration record'!I65 -> 14290 | H35: ='Auto-Calibration record'!B76 -> 140 | J35: ='MP Calibration Certificate'!J35 -> 139 | K35: - | L35: -
D36: **These particle sizes are not yet certified by NIST
D38: LS1 No Noise Threshold | E38: LS1 Threshold Sensitivity | G38: Sensitivity Threshold Ratio | J38: LS2 No Noise Threshold | K38: LS2 Threshold Sensitivity | L38: Sensitivity Threshold Ratio
D39: [mV] | E39: [mV] | G39: [-] | J39: [mV] | K39: [mV] | L39: [-]
D40: ='Auto-Calibration record'!B17 -> 0 | E40: =F28-D40 -> 112 | G40: =F28/D40 -> #DIV/0! | J40: ='Auto-Calibration record'!B11 -> 54 | K40: =F29-J40 -> 122 | L40: =F29/J40 -> 3.2592593
B72: CALIBRATION RESULT | D72: PASS | K72: PASS - VERIFIED
B74: RE-CALIBRATION DUE | D74: 1 YEAR FROM FIRST USE
B76: CALIBRATED BY | K76: Position | L76: Calibration Lab Technician
B78: Newly purchased products are covered under warranty for 12 months from first use
B79: Products being returned for re-calibration are verified for accuracy for a further 12 months. This does not extend the warranty.
B80: Customers are responsible for managing the intervals between calibration's as defined within IS0 9001:2000
O83: Doc No. 200.XXX
O84: Sheet 1
O85: DCRXXXX
B86: Page 1 of 1 | O86: Rev 0

Sheet Trescal Cal Cert
B2: MP Filtri UK Ltd
B3: Bourton on the Water Industrial Park
B4: Gloucestershire
B5: England
B6: GL54 2HQ
B7: Tel: +44 (0) 1451 822522
B8: www.mpfiltri.co.uk
B10: CERTIFICATE OF CALIBRATION
B13: WE HEREBY CERTIFY THAT THE CONTAMINATION MONITORING PRODUCT DETAILED BELOW HAS BEEN FULLY CALIBRATED WITH ISO MEDIUM TEST DUST (MTD) BASED ON ISO 11171 ON TEST EQUIPMENT CERTIFIED TO ISO 11943 BY I.F.T.S {Institut de la Filtration et des Techniques Séparatives}.
B14: We hereby confirm that the above mentioned measuring system was calibrated according to DIN ISO 9001, under the observation of a certified quality assurance system. The measuring installation used for calibration are regularly calibrated to national standards by I.F.T.S. Should no national standards exist, the measuring procedure corresponds with the technical regulations and norms valid at the time of the measurement
B17: PRODUCT TYPE | D17: ='Auto-Calibration record'!H14 -> 5.6mg/l RM8631b | K17: MEDIUM TEST DUST BATCH NUMBER | O17: ='Auto-Calibration record'!H18 -> RM8631b
B18: SERIAL NUMBER | D18: ='Auto-Calibration record'!#REF!&'Auto-Calibration record'!H15 -> #REF! | K18: DATE OF CALIBRATION | O18: ='Auto-Calibration record'!H16 -> 46147.7
B19: CERTIFICATE NUMBER | D19: ='Auto-Calibration record'!H17 -> 63010074 050526 | K19: CALIBRATION RIG NUMBER | O19: ='Auto-Calibration record'!H19 -> 304
B21: PARTICLE COUNT LIMITS AT 16mg/L CONCENTRATION
B22: (Suspension of ISO MTD in MIL-H-5606)
B23: No. particles reported per 100ml volume
D26: Particle Size | F26: Calibration Pulse Height | H26: Target Particle Count | J26: Actual Particle Count | K26: Deviation | L26: % Deviation (+/- 10%)
D27: [microns (c)] | F27: [mV] | H27: [n] | J27: [n] | K27: [n] | L27: [%]
D28: >4 | F28: ='Auto-Calibration record'!B65 -> 112 | H28: ='Auto-Calibration record'!B68 -> 1037710 | J28: ='Auto-Calibration record'!I68 -> 1047870 | K28: =J28-H28 -> 10160 | L28: =K28/H28 -> 0.0097907893
